[I 2022-06-13 10:05:41.802 ServerApp] jupyterlab | extension was successfully linked.
[I 2022-06-13 10:05:41.825 ServerApp] nbclassic | extension was successfully linked.
[I 2022-06-13 10:05:45.203 ServerApp] notebook_shim | extension was successfully linked.
[I 2022-06-13 10:05:45.203 ServerApp] panel.io.jupyter_server_extension | extension was successfully linked.
[I 2022-06-13 10:05:45.603 ServerApp] notebook_shim | extension was successfully loaded.
[I 2022-06-13 10:05:45.605 LabApp] JupyterLab extension loaded from /home/k/kimpson/bin/conda/envs/workhorse/lib/python3.7/site-packages/jupyterlab
[I 2022-06-13 10:05:45.606 LabApp] JupyterLab application directory is /home/k/kimpson/bin/conda/envs/workhorse/share/jupyter/lab
[I 2022-06-13 10:05:45.618 ServerApp] jupyterlab | extension was successfully loaded.
[I 2022-06-13 10:05:45.732 ServerApp] nbclassic | extension was successfully loaded.
[I 2022-06-13 10:05:45.737 ServerApp] panel.io.jupyter_server_extension | extension was successfully loaded.
[I 2022-06-13 10:05:45.738 ServerApp] Serving notebooks from local directory: /network/aopp/chaos/pred/kimpson/speedy-1
[I 2022-06-13 10:05:45.738 ServerApp] Jupyter Server 1.15.6 is running at:
[I 2022-06-13 10:05:45.738 ServerApp] http://localhost:9168/lab
[I 2022-06-13 10:05:45.738 ServerApp]  or http://127.0.0.1:9168/lab
[I 2022-06-13 10:05:45.738 ServerApp] Use Control-C to stop this server and shut down all kernels (twice to skip confirmation).
[I 2022-06-13 10:08:47.967 ServerApp] 302 GET / (::1) 1.20ms
[I 2022-06-13 10:08:55.780 LabApp] Build is up to date
[I 2022-06-13 10:09:04.569 ServerApp] Kernel started: 665e95e9-9a00-43a2-ad8b-3b97e2ba91c1
[I 2022-06-13 10:09:04.572 ServerApp] Kernel started: cc1ddbf6-3111-45d3-ab13-316529459577
[I 2022-06-13 10:09:04.572 ServerApp] Kernel started: 9348b8a3-e482-424f-9f0c-735584fde370
[I 2022-06-13 10:09:04.576 ServerApp] Kernel started: d78a54fc-b9cc-4a8b-b05c-0548884240c5
[I 2022-06-13 10:09:07.198 ServerApp] Starting buffering for d78a54fc-b9cc-4a8b-b05c-0548884240c5:3c132a31-7581-4bec-a816-bafe45da110f
[I 2022-06-13 10:11:07.728 ServerApp] Saving file at /jupyter_notebooks/1.Timeseries_individual_precipitation.ipynb
[I 2022-06-13 10:13:54.083 ServerApp] Copying jupyter_notebooks/1.Timeseries_ensemble-wm8.ipynb to /jupyter_notebooks
[I 2022-06-13 10:14:08.499 ServerApp] Kernel started: da1c0797-3347-440e-8eb1-90131b7d1d77
[I 2022-06-13 10:15:08.916 ServerApp] Starting buffering for 9348b8a3-e482-424f-9f0c-735584fde370:aedc45e7-9025-4c53-aeeb-520737e39002
[I 2022-06-13 10:16:08.352 ServerApp] Saving file at /jupyter_notebooks/1.Timeseries_ensemble-precip.ipynb
[I 2022-06-13 10:18:09.140 ServerApp] Saving file at /jupyter_notebooks/1.Timeseries_ensemble-precip.ipynb
[I 2022-06-13 10:20:10.003 ServerApp] Saving file at /jupyter_notebooks/1.Timeseries_ensemble-precip.ipynb
[I 2022-06-13 10:20:16.828 ServerApp] Saving file at /jupyter_notebooks/1.Timeseries_ensemble-precip.ipynb
[I 2022-06-13 10:20:23.196 ServerApp] Saving file at /jupyter_notebooks/1.Timeseries_ensemble-precip.ipynb
[I 2022-06-13 10:20:24.275 ServerApp] Saving file at /jupyter_notebooks/1.Timeseries_ensemble-precip.ipynb
[I 2022-06-13 10:21:05.487 ServerApp] Saving file at /jupyter_notebooks/1.Timeseries_ensemble-precip.ipynb
[I 2022-06-13 10:23:06.912 ServerApp] Saving file at /jupyter_notebooks/1.Timeseries_ensemble-precip.ipynb
[I 2022-06-13 10:27:11.560 ServerApp] Saving file at /jupyter_notebooks/1.Timeseries_individual_precipitation.ipynb
[I 2022-06-13 10:29:14.433 ServerApp] Saving file at /jupyter_notebooks/1.Timeseries_individual_precipitation.ipynb
[I 2022-06-13 10:31:17.490 ServerApp] Saving file at /jupyter_notebooks/1.Timeseries_individual_precipitation.ipynb
[I 2022-06-13 10:33:20.534 ServerApp] Saving file at /jupyter_notebooks/1.Timeseries_individual_precipitation.ipynb
[I 2022-06-13 10:35:03.702 ServerApp] Saving file at /jupyter_notebooks/1.Timeseries_ensemble-wm8.ipynb
[I 2022-06-13 10:35:23.850 ServerApp] Saving file at /jupyter_notebooks/1.Timeseries_individual_precipitation.ipynb
[I 2022-06-13 10:37:05.995 ServerApp] Saving file at /jupyter_notebooks/1.Timeseries_ensemble-wm8.ipynb
[I 2022-06-13 10:37:26.891 ServerApp] Saving file at /jupyter_notebooks/1.Timeseries_individual_precipitation.ipynb
[I 2022-06-13 10:39:29.783 ServerApp] Saving file at /jupyter_notebooks/1.Timeseries_individual_precipitation.ipynb
[I 2022-06-13 10:41:32.731 ServerApp] Saving file at /jupyter_notebooks/1.Timeseries_individual_precipitation.ipynb
[I 2022-06-13 10:43:36.399 ServerApp] Saving file at /jupyter_notebooks/1.Timeseries_individual_precipitation.ipynb
[I 2022-06-13 10:45:40.088 ServerApp] Saving file at /jupyter_notebooks/1.Timeseries_individual_precipitation.ipynb
[I 2022-06-13 10:47:43.595 ServerApp] Saving file at /jupyter_notebooks/1.Timeseries_individual_precipitation.ipynb
[I 2022-06-13 10:49:46.916 ServerApp] Saving file at /jupyter_notebooks/1.Timeseries_individual_precipitation.ipynb
[I 2022-06-13 10:51:50.356 ServerApp] Saving file at /jupyter_notebooks/1.Timeseries_individual_precipitation.ipynb
[I 2022-06-13 10:53:53.737 ServerApp] Saving file at /jupyter_notebooks/1.Timeseries_individual_precipitation.ipynb
[I 2022-06-13 10:55:57.126 ServerApp] Saving file at /jupyter_notebooks/1.Timeseries_individual_precipitation.ipynb
[I 2022-06-13 10:58:00.859 ServerApp] Saving file at /jupyter_notebooks/1.Timeseries_individual_precipitation.ipynb
[I 2022-06-13 11:00:04.555 ServerApp] Saving file at /jupyter_notebooks/1.Timeseries_individual_precipitation.ipynb
[I 2022-06-13 11:02:08.011 ServerApp] Saving file at /jupyter_notebooks/1.Timeseries_individual_precipitation.ipynb
[I 2022-06-13 11:04:11.479 ServerApp] Saving file at /jupyter_notebooks/1.Timeseries_individual_precipitation.ipynb
[I 2022-06-13 11:06:15.064 ServerApp] Saving file at /jupyter_notebooks/1.Timeseries_individual_precipitation.ipynb
[I 2022-06-13 11:08:18.424 ServerApp] Saving file at /jupyter_notebooks/1.Timeseries_individual_precipitation.ipynb
[I 2022-06-13 11:10:22.845 ServerApp] Saving file at /jupyter_notebooks/1.Timeseries_individual_precipitation.ipynb
[I 2022-06-13 11:11:10.792 ServerApp] Saving file at /jupyter_notebooks/1.Timeseries_ensemble-precip.ipynb
[I 2022-06-13 11:11:55.963 ServerApp] Kernel started: 0a408c42-0719-4783-8c0f-a69cffa4bca1
[I 2022-06-13 11:14:26.840 ServerApp] Saving file at /jupyter_notebooks/1.Timeseries_individual_precipitation.ipynb
[I 2022-06-13 11:16:31.942 ServerApp] Saving file at /jupyter_notebooks/1.Timeseries_individual_precipitation.ipynb
[I 2022-06-13 11:18:35.486 ServerApp] Saving file at /jupyter_notebooks/1.Timeseries_individual_precipitation.ipynb
[I 2022-06-13 11:20:40.255 ServerApp] Saving file at /jupyter_notebooks/1.Timeseries_individual_precipitation.ipynb
[I 2022-06-13 11:22:44.545 ServerApp] Saving file at /jupyter_notebooks/1.Timeseries_individual_precipitation.ipynb
[I 2022-06-13 11:24:48.934 ServerApp] Saving file at /jupyter_notebooks/1.Timeseries_individual_precipitation.ipynb
[I 2022-06-13 11:26:52.571 ServerApp] Saving file at /jupyter_notebooks/1.Timeseries_individual_precipitation.ipynb
[I 2022-06-13 11:28:56.298 ServerApp] Saving file at /jupyter_notebooks/1.Timeseries_individual_precipitation.ipynb
[I 2022-06-13 11:31:03.372 ServerApp] Saving file at /jupyter_notebooks/1.Timeseries_individual_precipitation.ipynb
[I 2022-06-13 11:33:10.031 ServerApp] Saving file at /jupyter_notebooks/1.Timeseries_individual_precipitation.ipynb
[I 2022-06-13 11:35:14.501 ServerApp] Saving file at /jupyter_notebooks/1.Timeseries_individual_precipitation.ipynb
[I 2022-06-13 12:16:11.386 ServerApp] Starting buffering for da1c0797-3347-440e-8eb1-90131b7d1d77:64de33ac-15b6-46c0-a48e-b095063ed6e5
[I 2022-06-13 12:16:11.389 ServerApp] Starting buffering for cc1ddbf6-3111-45d3-ab13-316529459577:7c619350-2cd8-4915-8bea-4b9c1fbc2874
[I 2022-06-13 12:16:11.390 ServerApp] Starting buffering for 665e95e9-9a00-43a2-ad8b-3b97e2ba91c1:82f6eed2-cdbf-469c-8061-942de9dcd7fc
[I 2022-06-13 12:16:11.391 ServerApp] Starting buffering for 0a408c42-0719-4783-8c0f-a69cffa4bca1:39d947d5-d53b-4cf2-8f9f-3195948696dc
[I 2022-06-13 12:16:11.392 ServerApp] Starting buffering for d78a54fc-b9cc-4a8b-b05c-0548884240c5:1e508ba3-9216-426c-8c94-3911f99ab9e4
[I 2022-06-13 12:16:11.507 ServerApp] Restoring connection for da1c0797-3347-440e-8eb1-90131b7d1d77:64de33ac-15b6-46c0-a48e-b095063ed6e5
[I 2022-06-13 12:16:11.563 ServerApp] Restoring connection for d78a54fc-b9cc-4a8b-b05c-0548884240c5:1e508ba3-9216-426c-8c94-3911f99ab9e4
[I 2022-06-13 12:16:11.732 ServerApp] Restoring connection for 0a408c42-0719-4783-8c0f-a69cffa4bca1:39d947d5-d53b-4cf2-8f9f-3195948696dc
[I 2022-06-13 12:16:11.812 ServerApp] Restoring connection for cc1ddbf6-3111-45d3-ab13-316529459577:7c619350-2cd8-4915-8bea-4b9c1fbc2874
[I 2022-06-13 12:16:11.814 ServerApp] Restoring connection for 665e95e9-9a00-43a2-ad8b-3b97e2ba91c1:82f6eed2-cdbf-469c-8061-942de9dcd7fc
[W 2022-06-13 12:17:41.508 ServerApp] WebSocket ping timeout after 90001 ms.
[W 2022-06-13 12:17:41.564 ServerApp] WebSocket ping timeout after 90001 ms.
[W 2022-06-13 12:17:41.733 ServerApp] WebSocket ping timeout after 90000 ms.
[W 2022-06-13 12:17:41.738 ServerApp] WebSocket ping timeout after 90001 ms.
[W 2022-06-13 12:17:41.814 ServerApp] WebSocket ping timeout after 90001 ms.
[W 2022-06-13 12:17:41.814 ServerApp] WebSocket ping timeout after 90000 ms.
[I 2022-06-13 12:17:46.511 ServerApp] Starting buffering for da1c0797-3347-440e-8eb1-90131b7d1d77:64de33ac-15b6-46c0-a48e-b095063ed6e5
[I 2022-06-13 12:17:46.734 ServerApp] Starting buffering for 0a408c42-0719-4783-8c0f-a69cffa4bca1:39d947d5-d53b-4cf2-8f9f-3195948696dc
[I 2022-06-13 12:17:46.740 ServerApp] Starting buffering for d78a54fc-b9cc-4a8b-b05c-0548884240c5:e4f0d362-763e-428d-b79b-7989ceb2c353
[I 2022-06-13 12:17:46.815 ServerApp] Starting buffering for cc1ddbf6-3111-45d3-ab13-316529459577:7c619350-2cd8-4915-8bea-4b9c1fbc2874
[I 2022-06-13 12:17:46.815 ServerApp] Starting buffering for 665e95e9-9a00-43a2-ad8b-3b97e2ba91c1:82f6eed2-cdbf-469c-8061-942de9dcd7fc
[I 2022-06-13 12:53:52.937 ServerApp] Restoring connection for d78a54fc-b9cc-4a8b-b05c-0548884240c5:e4f0d362-763e-428d-b79b-7989ceb2c353
[I 2022-06-13 12:53:53.960 ServerApp] Starting buffering for d78a54fc-b9cc-4a8b-b05c-0548884240c5:e4f0d362-763e-428d-b79b-7989ceb2c353
[I 2022-06-13 12:54:03.672 LabApp] Build is up to date
[I 2022-06-13 12:56:08.208 ServerApp] Saving file at /jupyter_notebooks/1.Timeseries_individual_precipitation.ipynb
[I 2022-06-13 12:58:11.693 ServerApp] Saving file at /jupyter_notebooks/1.Timeseries_individual_precipitation.ipynb
[I 2022-06-13 13:00:15.430 ServerApp] Saving file at /jupyter_notebooks/1.Timeseries_individual_precipitation.ipynb
[I 2022-06-13 13:02:19.166 ServerApp] Saving file at /jupyter_notebooks/1.Timeseries_individual_precipitation.ipynb
[I 2022-06-13 13:04:22.896 ServerApp] Saving file at /jupyter_notebooks/1.Timeseries_individual_precipitation.ipynb
[I 2022-06-13 13:06:26.639 ServerApp] Saving file at /jupyter_notebooks/1.Timeseries_individual_precipitation.ipynb
[I 2022-06-13 13:08:30.326 ServerApp] Saving file at /jupyter_notebooks/1.Timeseries_individual_precipitation.ipynb
[I 2022-06-13 13:10:34.122 ServerApp] Saving file at /jupyter_notebooks/1.Timeseries_individual_precipitation.ipynb
[I 2022-06-13 13:12:37.847 ServerApp] Saving file at /jupyter_notebooks/1.Timeseries_individual_precipitation.ipynb
[I 2022-06-13 13:14:42.286 ServerApp] Saving file at /jupyter_notebooks/1.Timeseries_individual_precipitation.ipynb
[I 2022-06-13 13:16:45.931 ServerApp] Saving file at /jupyter_notebooks/1.Timeseries_individual_precipitation.ipynb
[I 2022-06-13 13:18:49.521 ServerApp] Saving file at /jupyter_notebooks/1.Timeseries_individual_precipitation.ipynb
[I 2022-06-13 13:20:53.987 ServerApp] Saving file at /jupyter_notebooks/1.Timeseries_individual_precipitation.ipynb
[I 2022-06-13 13:22:57.824 ServerApp] Saving file at /jupyter_notebooks/1.Timeseries_individual_precipitation.ipynb
[I 2022-06-13 13:25:01.478 ServerApp] Saving file at /jupyter_notebooks/1.Timeseries_individual_precipitation.ipynb
[I 2022-06-13 13:26:04.322 ServerApp] Saving file at /jupyter_notebooks/1.Timeseries_ensemble-precip.ipynb
[I 2022-06-13 13:27:05.726 ServerApp] Saving file at /jupyter_notebooks/1.Timeseries_individual_precipitation.ipynb
[I 2022-06-13 13:28:05.386 ServerApp] Saving file at /jupyter_notebooks/1.Timeseries_ensemble-precip.ipynb
[I 2022-06-13 13:29:09.367 ServerApp] Saving file at /jupyter_notebooks/1.Timeseries_individual_precipitation.ipynb
[I 2022-06-13 13:30:06.722 ServerApp] Saving file at /jupyter_notebooks/1.Timeseries_ensemble-precip.ipynb
[I 2022-06-13 13:31:13.737 ServerApp] Saving file at /jupyter_notebooks/1.Timeseries_individual_precipitation.ipynb
[I 2022-06-13 13:33:18.309 ServerApp] Saving file at /jupyter_notebooks/1.Timeseries_individual_precipitation.ipynb
[I 2022-06-13 13:35:23.009 ServerApp] Saving file at /jupyter_notebooks/1.Timeseries_individual_precipitation.ipynb
[I 2022-06-13 13:37:27.540 ServerApp] Saving file at /jupyter_notebooks/1.Timeseries_individual_precipitation.ipynb
[I 2022-06-13 13:39:32.731 ServerApp] Saving file at /jupyter_notebooks/1.Timeseries_individual_precipitation.ipynb
[I 2022-06-13 13:41:36.549 ServerApp] Saving file at /jupyter_notebooks/1.Timeseries_individual_precipitation.ipynb
[I 2022-06-13 13:43:41.248 ServerApp] Saving file at /jupyter_notebooks/1.Timeseries_individual_precipitation.ipynb
[I 2022-06-13 13:45:45.148 ServerApp] Saving file at /jupyter_notebooks/1.Timeseries_individual_precipitation.ipynb
[I 2022-06-13 13:47:48.933 ServerApp] Saving file at /jupyter_notebooks/1.Timeseries_individual_precipitation.ipynb
[I 2022-06-13 13:49:52.686 ServerApp] Saving file at /jupyter_notebooks/1.Timeseries_individual_precipitation.ipynb
[I 2022-06-13 13:51:56.551 ServerApp] Saving file at /jupyter_notebooks/1.Timeseries_individual_precipitation.ipynb
[I 2022-06-13 13:54:00.400 ServerApp] Saving file at /jupyter_notebooks/1.Timeseries_individual_precipitation.ipynb
[I 2022-06-13 13:56:07.602 ServerApp] Saving file at /jupyter_notebooks/1.Timeseries_ensemble-precip.ipynb
[I 2022-06-13 13:57:41.704 ServerApp] Starting buffering for 0a408c42-0719-4783-8c0f-a69cffa4bca1:9566231a-d0e9-4117-85df-28e098a6fb43
[I 2022-06-13 13:58:08.518 ServerApp] Saving file at /jupyter_notebooks/1.Timeseries_ensemble-precip.ipynb
[I 2022-06-13 13:59:09.179 ServerApp] Saving file at /jupyter_notebooks/1.Timeseries_ensemble-precip.ipynb
[I 2022-06-13 14:01:10.084 ServerApp] Saving file at /jupyter_notebooks/1.Timeseries_ensemble-precip.ipynb
[I 2022-06-13 14:02:02.538 ServerApp] Saving file at /jupyter_notebooks/1.Timeseries_individual_precipitation.ipynb
[I 2022-06-13 14:02:54.495 ServerApp] Saving file at /jupyter_notebooks/1.Timeseries_individual_precipitation.ipynb
[I 2022-06-13 14:04:05.810 ServerApp] Kernel interrupted: d78a54fc-b9cc-4a8b-b05c-0548884240c5
[I 2022-06-13 14:04:05.990 ServerApp] Kernel interrupted: d78a54fc-b9cc-4a8b-b05c-0548884240c5
[I 2022-06-13 14:04:06.144 ServerApp] Kernel interrupted: d78a54fc-b9cc-4a8b-b05c-0548884240c5
[I 2022-06-13 14:04:06.309 ServerApp] Kernel interrupted: d78a54fc-b9cc-4a8b-b05c-0548884240c5
[I 2022-06-13 14:04:19.637 ServerApp] Saving file at /jupyter_notebooks/1.Timeseries_individual_precipitation.ipynb
[I 2022-06-13 14:04:28.031 ServerApp] Kernel interrupted: d78a54fc-b9cc-4a8b-b05c-0548884240c5
[I 2022-06-13 14:04:28.411 ServerApp] Kernel interrupted: d78a54fc-b9cc-4a8b-b05c-0548884240c5
[I 2022-06-13 14:04:28.818 ServerApp] Kernel interrupted: d78a54fc-b9cc-4a8b-b05c-0548884240c5
[I 2022-06-13 14:04:28.834 ServerApp] Kernel interrupted: d78a54fc-b9cc-4a8b-b05c-0548884240c5
[I 2022-06-13 14:06:22.141 ServerApp] Saving file at /jupyter_notebooks/1.Timeseries_individual_precipitation.ipynb
[I 2022-06-13 14:18:23.165 ServerApp] Saving file at /jupyter_notebooks/1.Timeseries_individual_precipitation.ipynb
[I 2022-06-13 14:18:48.656 ServerApp] Saving file at /jupyter_notebooks/1.Timeseries_individual_precipitation.ipynb
[I 2022-06-13 14:20:51.140 ServerApp] Saving file at /jupyter_notebooks/1.Timeseries_individual_precipitation.ipynb
[I 2022-06-13 14:22:54.431 ServerApp] Saving file at /jupyter_notebooks/1.Timeseries_individual_precipitation.ipynb
[I 2022-06-13 14:23:10.873 ServerApp] Saving file at /jupyter_notebooks/1.Timeseries_ensemble-precip.ipynb
[I 2022-06-13 14:24:56.925 ServerApp] Saving file at /jupyter_notebooks/1.Timeseries_individual_precipitation.ipynb
[I 2022-06-13 14:25:11.602 ServerApp] Saving file at /jupyter_notebooks/1.Timeseries_ensemble-precip.ipynb
[I 2022-06-13 14:26:59.654 ServerApp] Saving file at /jupyter_notebooks/1.Timeseries_individual_precipitation.ipynb
[I 2022-06-13 14:29:02.694 ServerApp] Saving file at /jupyter_notebooks/1.Timeseries_individual_precipitation.ipynb
[I 2022-06-13 14:31:06.045 ServerApp] Saving file at /jupyter_notebooks/1.Timeseries_individual_precipitation.ipynb
[I 2022-06-13 14:33:08.757 ServerApp] Saving file at /jupyter_notebooks/1.Timeseries_individual_precipitation.ipynb
[I 2022-06-13 14:35:11.437 ServerApp] Saving file at /jupyter_notebooks/1.Timeseries_individual_precipitation.ipynb
[I 2022-06-13 14:37:14.131 ServerApp] Saving file at /jupyter_notebooks/1.Timeseries_individual_precipitation.ipynb
[I 2022-06-13 14:39:16.831 ServerApp] Saving file at /jupyter_notebooks/1.Timeseries_individual_precipitation.ipynb
[I 2022-06-13 14:41:19.521 ServerApp] Saving file at /jupyter_notebooks/1.Timeseries_individual_precipitation.ipynb
[I 2022-06-13 14:43:22.191 ServerApp] Saving file at /jupyter_notebooks/1.Timeseries_individual_precipitation.ipynb
[I 2022-06-13 14:45:24.891 ServerApp] Saving file at /jupyter_notebooks/1.Timeseries_individual_precipitation.ipynb
[I 2022-06-13 14:47:27.565 ServerApp] Saving file at /jupyter_notebooks/1.Timeseries_individual_precipitation.ipynb
[I 2022-06-13 14:49:30.286 ServerApp] Saving file at /jupyter_notebooks/1.Timeseries_individual_precipitation.ipynb
[I 2022-06-13 14:51:32.960 ServerApp] Saving file at /jupyter_notebooks/1.Timeseries_individual_precipitation.ipynb
[I 2022-06-13 14:55:35.376 ServerApp] Saving file at /jupyter_notebooks/1.Timeseries_individual_precipitation.ipynb
[I 2022-06-13 14:56:55.019 ServerApp] Kernel started: 866ff731-88f0-4d5c-b354-d1cf987557d3
[I 2022-06-13 14:57:39.476 ServerApp] Saving file at /jupyter_notebooks/1.Timeseries_individual_precipitation.ipynb
[I 2022-06-13 15:00:56.343 ServerApp] Saving file at /jupyter_notebooks/2.GlobalMapPrecip.ipynb
[I 2022-06-13 15:05:29.884 ServerApp] Kernel interrupted: 866ff731-88f0-4d5c-b354-d1cf987557d3
[I 2022-06-13 15:05:30.196 ServerApp] Kernel interrupted: 866ff731-88f0-4d5c-b354-d1cf987557d3
[I 2022-06-13 15:05:30.476 ServerApp] Kernel interrupted: 866ff731-88f0-4d5c-b354-d1cf987557d3
[I 2022-06-13 15:05:30.550 ServerApp] Kernel interrupted: 866ff731-88f0-4d5c-b354-d1cf987557d3
[IPKernelApp] ERROR | Exception in message handler:
Traceback (most recent call last):
  File "/home/k/kimpson/bin/conda/envs/workhorse/lib/python3.7/site-packages/IPython/core/interactiveshell.py", line 3457, in run_code
    exec(code_obj, self.user_global_ns, self.user_ns)
  File "/tmp/ipykernel_53445/762145844.py", line 99, in <module>
    df_control = global_average(sorted(glob.glob(control_files)),                          'small_data/control_map_precip_weighted.pkl')
  File "/tmp/ipykernel_53445/762145844.py", line 70, in global_average
    df,use = process_nc_file(f,true_latitude,counter) #this is a df of the surface temperature for that file, averaged over time
  File "/tmp/ipykernel_53445/762145844.py", line 23, in process_nc_file
    ds = xr.open_dataset(f)
  File "/home/k/kimpson/bin/conda/envs/workhorse/lib/python3.7/site-packages/xarray/backends/api.py", line 479, in open_dataset
    engine = plugins.guess_engine(filename_or_obj)
  File "/home/k/kimpson/bin/conda/envs/workhorse/lib/python3.7/site-packages/xarray/backends/plugins.py", line 114, in guess_engine
    if backend.guess_can_open(store_spec):
  File "/home/k/kimpson/bin/conda/envs/workhorse/lib/python3.7/site-packages/xarray/backends/scipy_.py", line 245, in guess_can_open
    magic_number = try_read_magic_number_from_file_or_path(filename_or_obj)
  File "/home/k/kimpson/bin/conda/envs/workhorse/lib/python3.7/site-packages/xarray/core/utils.py", line 676, in try_read_magic_number_from_file_or_path
    magic_number = try_read_magic_number_from_path(filename_or_obj, count)
  File "/home/k/kimpson/bin/conda/envs/workhorse/lib/python3.7/site-packages/xarray/core/utils.py", line 667, in try_read_magic_number_from_path
    return read_magic_number_from_file(f, count)
  File "/home/k/kimpson/bin/conda/envs/workhorse/lib/python3.7/site-packages/xarray/core/utils.py", line 655, in read_magic_number_from_file
    magic_number = filename_or_obj.read(count)  # type: ignore
KeyboardInterrupt

During handling of the above exception, another exception occurred:

Traceback (most recent call last):
  File "/home/k/kimpson/bin/conda/envs/workhorse/lib/python3.7/site-packages/IPython/core/interactiveshell.py", line 2077, in showtraceback
    stb = value._render_traceback_()
AttributeError: 'KeyboardInterrupt' object has no attribute '_render_traceback_'

During handling of the above exception, another exception occurred:

Traceback (most recent call last):
  File "/home/k/kimpson/bin/conda/envs/workhorse/lib/python3.7/site-packages/IPython/core/interactiveshell.py", line 3377, in run_ast_nodes
    if (await self.run_code(code, result,  async_=asy)):
  File "/home/k/kimpson/bin/conda/envs/workhorse/lib/python3.7/site-packages/IPython/core/interactiveshell.py", line 3474, in run_code
    self.showtraceback(running_compiled_code=True)
  File "/home/k/kimpson/bin/conda/envs/workhorse/lib/python3.7/site-packages/IPython/core/interactiveshell.py", line 2080, in showtraceback
    value, tb, tb_offset=tb_offset)
  File "/home/k/kimpson/bin/conda/envs/workhorse/lib/python3.7/site-packages/IPython/core/ultratb.py", line 1368, in structured_traceback
    self, etype, value, tb, tb_offset, number_of_lines_of_context)
  File "/home/k/kimpson/bin/conda/envs/workhorse/lib/python3.7/site-packages/IPython/core/ultratb.py", line 1268, in structured_traceback
    self, etype, value, tb, tb_offset, number_of_lines_of_context
  File "/home/k/kimpson/bin/conda/envs/workhorse/lib/python3.7/site-packages/IPython/core/ultratb.py", line 1125, in structured_traceback
    tb_offset)
  File "/home/k/kimpson/bin/conda/envs/workhorse/lib/python3.7/site-packages/IPython/core/ultratb.py", line 1082, in format_exception_as_a_whole
    last_unique, recursion_repeat = find_recursion(orig_etype, evalue, records)
  File "/home/k/kimpson/bin/conda/envs/workhorse/lib/python3.7/site-packages/IPython/core/ultratb.py", line 382, in find_recursion
    return len(records), 0
TypeError: object of type 'NoneType' has no len()

During handling of the above exception, another exception occurred:

Traceback (most recent call last):
  File "/home/k/kimpson/bin/conda/envs/workhorse/lib/python3.7/site-packages/IPython/core/interactiveshell.py", line 2077, in showtraceback
    stb = value._render_traceback_()
AttributeError: 'TypeError' object has no attribute '_render_traceback_'

During handling of the above exception, another exception occurred:

Traceback (most recent call last):
  File "/home/k/kimpson/bin/conda/envs/workhorse/lib/python3.7/site-packages/IPython/core/interactiveshell.py", line 2960, in _run_cell
    return runner(coro)
  File "/home/k/kimpson/bin/conda/envs/workhorse/lib/python3.7/site-packages/IPython/core/async_helpers.py", line 78, in _pseudo_sync_runner
    coro.send(None)
  File "/home/k/kimpson/bin/conda/envs/workhorse/lib/python3.7/site-packages/IPython/core/interactiveshell.py", line 3186, in run_cell_async
    interactivity=interactivity, compiler=compiler, result=result)
  File "/home/k/kimpson/bin/conda/envs/workhorse/lib/python3.7/site-packages/IPython/core/interactiveshell.py", line 3396, in run_ast_nodes
    self.showtraceback()
  File "/home/k/kimpson/bin/conda/envs/workhorse/lib/python3.7/site-packages/IPython/core/interactiveshell.py", line 2080, in showtraceback
    value, tb, tb_offset=tb_offset)
  File "/home/k/kimpson/bin/conda/envs/workhorse/lib/python3.7/site-packages/IPython/core/ultratb.py", line 1368, in structured_traceback
    self, etype, value, tb, tb_offset, number_of_lines_of_context)
  File "/home/k/kimpson/bin/conda/envs/workhorse/lib/python3.7/site-packages/IPython/core/ultratb.py", line 1268, in structured_traceback
    self, etype, value, tb, tb_offset, number_of_lines_of_context
  File "/home/k/kimpson/bin/conda/envs/workhorse/lib/python3.7/site-packages/IPython/core/ultratb.py", line 1143, in structured_traceback
    chained_exceptions_tb_offset)
  File "/home/k/kimpson/bin/conda/envs/workhorse/lib/python3.7/site-packages/IPython/core/ultratb.py", line 1082, in format_exception_as_a_whole
    last_unique, recursion_repeat = find_recursion(orig_etype, evalue, records)
  File "/home/k/kimpson/bin/conda/envs/workhorse/lib/python3.7/site-packages/IPython/core/ultratb.py", line 382, in find_recursion
    return len(records), 0
TypeError: object of type 'NoneType' has no len()

During handling of the above exception, another exception occurred:

Traceback (most recent call last):
  File "/home/k/kimpson/bin/conda/envs/workhorse/lib/python3.7/site-packages/IPython/core/interactiveshell.py", line 2077, in showtraceback
    stb = value._render_traceback_()
AttributeError: 'TypeError' object has no attribute '_render_traceback_'

During handling of the above exception, another exception occurred:

Traceback (most recent call last):
  File "/home/k/kimpson/bin/conda/envs/workhorse/lib/python3.7/site-packages/ipykernel/kernelbase.py", line 367, in dispatch_shell
    await result
  File "/home/k/kimpson/bin/conda/envs/workhorse/lib/python3.7/site-packages/ipykernel/kernelbase.py", line 662, in execute_request
    reply_content = await reply_content
  File "/home/k/kimpson/bin/conda/envs/workhorse/lib/python3.7/site-packages/ipykernel/ipkernel.py", line 360, in do_execute
    res = shell.run_cell(code, store_history=store_history, silent=silent)
  File "/home/k/kimpson/bin/conda/envs/workhorse/lib/python3.7/site-packages/ipykernel/zmqshell.py", line 532, in run_cell
    return super().run_cell(*args, **kwargs)
  File "/home/k/kimpson/bin/conda/envs/workhorse/lib/python3.7/site-packages/IPython/core/interactiveshell.py", line 2915, in run_cell
    raw_cell, store_history, silent, shell_futures)
  File "/home/k/kimpson/bin/conda/envs/workhorse/lib/python3.7/site-packages/IPython/core/interactiveshell.py", line 2965, in _run_cell
    self.showtraceback(running_compiled_code=True)
  File "/home/k/kimpson/bin/conda/envs/workhorse/lib/python3.7/site-packages/IPython/core/interactiveshell.py", line 2080, in showtraceback
    value, tb, tb_offset=tb_offset)
  File "/home/k/kimpson/bin/conda/envs/workhorse/lib/python3.7/site-packages/IPython/core/ultratb.py", line 1368, in structured_traceback
    self, etype, value, tb, tb_offset, number_of_lines_of_context)
  File "/home/k/kimpson/bin/conda/envs/workhorse/lib/python3.7/site-packages/IPython/core/ultratb.py", line 1268, in structured_traceback
    self, etype, value, tb, tb_offset, number_of_lines_of_context
  File "/home/k/kimpson/bin/conda/envs/workhorse/lib/python3.7/site-packages/IPython/core/ultratb.py", line 1125, in structured_traceback
    tb_offset)
  File "/home/k/kimpson/bin/conda/envs/workhorse/lib/python3.7/site-packages/IPython/core/ultratb.py", line 1082, in format_exception_as_a_whole
    last_unique, recursion_repeat = find_recursion(orig_etype, evalue, records)
  File "/home/k/kimpson/bin/conda/envs/workhorse/lib/python3.7/site-packages/IPython/core/ultratb.py", line 382, in find_recursion
    return len(records), 0
TypeError: object of type 'NoneType' has no len()
[I 2022-06-13 15:07:00.408 ServerApp] Saving file at /jupyter_notebooks/2.GlobalMapPrecip.ipynb
[I 2022-06-13 15:07:04.461 ServerApp] Creating new directory in /jupyter_notebooks
[I 2022-06-13 15:07:26.194 ServerApp] Copying jupyter_notebooks/1.Timeseries_ensemble-precip.ipynb to /jupyter_notebooks
[I 2022-06-13 15:07:46.885 ServerApp] Kernel started: aa43cd0c-abf8-4204-a364-b72d795cd894
[I 2022-06-13 15:07:46.923 ServerApp] Starting buffering for 665e95e9-9a00-43a2-ad8b-3b97e2ba91c1:d5eaf33b-ab56-44b2-81c0-bef1c3e2bebc
[I 2022-06-13 15:07:47.819 ServerApp] Starting buffering for cc1ddbf6-3111-45d3-ab13-316529459577:fdab755b-aa0f-4e03-b455-354844b2b459
[I 2022-06-13 15:07:48.064 ServerApp] Starting buffering for da1c0797-3347-440e-8eb1-90131b7d1d77:2bbac522-35e9-48f9-b051-e23236079282
[I 2022-06-13 15:07:49.300 ServerApp] Starting buffering for d78a54fc-b9cc-4a8b-b05c-0548884240c5:b7c50aaa-a83e-43fc-a187-5aea529fd4ab
[I 2022-06-13 15:09:46.931 ServerApp] Saving file at /jupyter_notebooks/paper/1.Precipitation_timeseries.ipynb
[I 2022-06-13 15:12:51.460 ServerApp] Saving file at /jupyter_notebooks/1.Timeseries_individual_precipitation.ipynb
[I 2022-06-13 15:14:55.909 ServerApp] Saving file at /jupyter_notebooks/1.Timeseries_individual_precipitation.ipynb
[I 2022-06-13 15:15:47.682 ServerApp] Saving file at /jupyter_notebooks/paper/1.Precipitation_timeseries.ipynb
[I 2022-06-13 15:17:00.054 ServerApp] Saving file at /jupyter_notebooks/1.Timeseries_individual_precipitation.ipynb
[I 2022-06-13 15:17:31.754 ServerApp] Saving file at /jupyter_notebooks/paper/1.Precipitation_timeseries.ipynb
[I 2022-06-13 15:18:48.879 ServerApp] Saving file at /jupyter_notebooks/paper/1.Precipitation_timeseries.ipynb
[I 2022-06-13 15:19:04.402 ServerApp] Saving file at /jupyter_notebooks/1.Timeseries_individual_precipitation.ipynb
[I 2022-06-13 15:20:49.675 ServerApp] Saving file at /jupyter_notebooks/paper/1.Precipitation_timeseries.ipynb
[I 2022-06-13 15:21:08.581 ServerApp] Saving file at /jupyter_notebooks/1.Timeseries_individual_precipitation.ipynb
[I 2022-06-13 15:22:50.485 ServerApp] Saving file at /jupyter_notebooks/paper/1.Precipitation_timeseries.ipynb
[I 2022-06-13 15:22:55.376 ServerApp] Saving file at /jupyter_notebooks/paper/1.Precipitation_timeseries.ipynb
[I 2022-06-13 15:23:12.902 ServerApp] Saving file at /jupyter_notebooks/1.Timeseries_individual_precipitation.ipynb
[I 2022-06-13 15:24:28.318 ServerApp] Saving file at /jupyter_notebooks/paper/1.Precipitation_timeseries.ipynb
[I 2022-06-13 15:24:32.058 ServerApp] Saving file at /jupyter_notebooks/paper/1.Precipitation_timeseries.ipynb
[I 2022-06-13 15:24:35.768 ServerApp] Saving file at /jupyter_notebooks/paper/1.Precipitation_timeseries.ipynb
[I 2022-06-13 15:25:17.090 ServerApp] Saving file at /jupyter_notebooks/1.Timeseries_individual_precipitation.ipynb
[I 2022-06-13 15:26:36.243 ServerApp] Saving file at /jupyter_notebooks/paper/1.Precipitation_timeseries.ipynb
[I 2022-06-13 15:26:36.975 ServerApp] Saving file at /jupyter_notebooks/paper/1.Precipitation_timeseries.ipynb
[I 2022-06-13 15:27:21.432 ServerApp] Saving file at /jupyter_notebooks/1.Timeseries_individual_precipitation.ipynb
[I 2022-06-13 15:27:21.991 ServerApp] Saving file at /jupyter_notebooks/paper/1.Precipitation_timeseries.ipynb
[I 2022-06-13 15:27:48.471 ServerApp] Saving file at /jupyter_notebooks/paper/1.Precipitation_timeseries.ipynb
[I 2022-06-13 15:29:25.623 ServerApp] Saving file at /jupyter_notebooks/1.Timeseries_individual_precipitation.ipynb
[I 2022-06-13 15:29:49.231 ServerApp] Saving file at /jupyter_notebooks/paper/1.Precipitation_timeseries.ipynb
[I 2022-06-13 15:31:29.948 ServerApp] Saving file at /jupyter_notebooks/1.Timeseries_individual_precipitation.ipynb
[I 2022-06-13 15:31:50.204 ServerApp] Saving file at /jupyter_notebooks/paper/1.Precipitation_timeseries.ipynb
[I 2022-06-13 15:33:34.210 ServerApp] Saving file at /jupyter_notebooks/1.Timeseries_individual_precipitation.ipynb
[I 2022-06-13 15:33:50.963 ServerApp] Saving file at /jupyter_notebooks/paper/1.Precipitation_timeseries.ipynb
[I 2022-06-13 15:35:36.544 ServerApp] Saving file at /jupyter_notebooks/1.Timeseries_individual_precipitation.ipynb
[I 2022-06-13 15:35:51.913 ServerApp] Saving file at /jupyter_notebooks/paper/1.Precipitation_timeseries.ipynb
[I 2022-06-13 15:37:10.754 ServerApp] Saving file at /jupyter_notebooks/paper/1.Precipitation_timeseries.ipynb
[I 2022-06-13 15:37:13.708 ServerApp] Saving file at /jupyter_notebooks/paper/1.Precipitation_timeseries.ipynb
[I 2022-06-13 15:37:38.636 ServerApp] Saving file at /jupyter_notebooks/1.Timeseries_individual_precipitation.ipynb
[I 2022-06-13 15:39:14.581 ServerApp] Saving file at /jupyter_notebooks/paper/1.Precipitation_timeseries.ipynb
[I 2022-06-13 15:39:40.665 ServerApp] Saving file at /jupyter_notebooks/1.Timeseries_individual_precipitation.ipynb
[I 2022-06-13 15:40:52.338 ServerApp] Saving file at /jupyter_notebooks/paper/1.Precipitation_timeseries.ipynb
[I 2022-06-13 15:41:42.938 ServerApp] Saving file at /jupyter_notebooks/1.Timeseries_individual_precipitation.ipynb
[I 2022-06-13 15:42:44.992 ServerApp] Kernel interrupted: aa43cd0c-abf8-4204-a364-b72d795cd894
[I 2022-06-13 15:42:45.379 ServerApp] Kernel interrupted: aa43cd0c-abf8-4204-a364-b72d795cd894
[I 2022-06-13 15:42:45.483 ServerApp] Kernel interrupted: aa43cd0c-abf8-4204-a364-b72d795cd894
[I 2022-06-13 15:42:45.600 ServerApp] Kernel interrupted: aa43cd0c-abf8-4204-a364-b72d795cd894
[I 2022-06-13 15:42:45.744 ServerApp] Kernel interrupted: aa43cd0c-abf8-4204-a364-b72d795cd894
[I 2022-06-13 15:42:46.037 ServerApp] Kernel interrupted: aa43cd0c-abf8-4204-a364-b72d795cd894
[I 2022-06-13 15:42:46.053 ServerApp] Kernel interrupted: aa43cd0c-abf8-4204-a364-b72d795cd894
[I 2022-06-13 15:42:53.149 ServerApp] Saving file at /jupyter_notebooks/paper/1.Precipitation_timeseries.ipynb
[I 2022-06-13 15:42:56.525 ServerApp] Kernel interrupted: aa43cd0c-abf8-4204-a364-b72d795cd894
[I 2022-06-13 15:42:56.630 ServerApp] Kernel interrupted: aa43cd0c-abf8-4204-a364-b72d795cd894
[I 2022-06-13 15:42:56.919 ServerApp] Kernel interrupted: aa43cd0c-abf8-4204-a364-b72d795cd894
[I 2022-06-13 15:43:45.199 ServerApp] Saving file at /jupyter_notebooks/1.Timeseries_individual_precipitation.ipynb
[I 2022-06-13 15:44:39.734 ServerApp] Saving file at /jupyter_notebooks/paper/1.Precipitation_timeseries.ipynb
[I 2022-06-13 15:45:49.902 ServerApp] Saving file at /jupyter_notebooks/1.Timeseries_individual_precipitation.ipynb
[I 2022-06-13 15:45:51.755 ServerApp] Creating new directory in /jupyter_notebooks/paper
[I 2022-06-13 15:46:40.500 ServerApp] Saving file at /jupyter_notebooks/paper/1.Precipitation_timeseries.ipynb
[I 2022-06-13 15:47:52.239 ServerApp] Saving file at /jupyter_notebooks/paper/1.Precipitation_timeseries.ipynb
[I 2022-06-13 15:48:21.009 ServerApp] Saving file at /jupyter_notebooks/paper/1.Precipitation_timeseries.ipynb
[I 2022-06-13 15:50:21.745 ServerApp] Saving file at /jupyter_notebooks/paper/1.Precipitation_timeseries.ipynb
[W 2022-06-13 15:52:10.189 ServerApp] 400 GET /api/contents/jupyter_notebooks/paper/data/m5_precip_timeseries_unweighted.pkl?type=file&content=1&format=text&1655131930083 (::1): /network/aopp/chaos/pred/kimpson/speedy-1/jupyter_notebooks/paper/data/m5_precip_timeseries_unweighted.pkl is not UTF-8 encoded
[W 2022-06-13 15:52:10.189 ServerApp] /network/aopp/chaos/pred/kimpson/speedy-1/jupyter_notebooks/paper/data/m5_precip_timeseries_unweighted.pkl is not UTF-8 encoded
[W 2022-06-13 15:52:10.190 ServerApp] 400 GET /api/contents/jupyter_notebooks/paper/data/m5_precip_timeseries_unweighted.pkl?type=file&content=1&format=text&1655131930083 (::1) 4.38ms referer=http://localhost:8885/lab/tree/jupyter_notebooks/paper/1.Precipitation_timeseries.ipynb
[W 2022-06-13 15:52:14.386 ServerApp] 400 GET /api/contents/jupyter_notebooks/paper/data/m5_precip_timeseries_unweighted.pkl?type=file&content=1&format=text&1655131934267 (::1): /network/aopp/chaos/pred/kimpson/speedy-1/jupyter_notebooks/paper/data/m5_precip_timeseries_unweighted.pkl is not UTF-8 encoded
[W 2022-06-13 15:52:14.387 ServerApp] /network/aopp/chaos/pred/kimpson/speedy-1/jupyter_notebooks/paper/data/m5_precip_timeseries_unweighted.pkl is not UTF-8 encoded
[W 2022-06-13 15:52:14.387 ServerApp] 400 GET /api/contents/jupyter_notebooks/paper/data/m5_precip_timeseries_unweighted.pkl?type=file&content=1&format=text&1655131934267 (::1) 3.97ms referer=http://localhost:8885/lab/tree/jupyter_notebooks/paper/1.Precipitation_timeseries.ipynb
[I 2022-06-13 15:52:22.479 ServerApp] Saving file at /jupyter_notebooks/paper/1.Precipitation_timeseries.ipynb
[I 2022-06-13 15:54:23.514 ServerApp] Saving file at /jupyter_notebooks/paper/1.Precipitation_timeseries.ipynb
[I 2022-06-13 15:56:23.940 ServerApp] Saving file at /jupyter_notebooks/paper/1.Precipitation_timeseries.ipynb
[I 2022-06-13 15:58:24.174 ServerApp] Saving file at /jupyter_notebooks/paper/1.Precipitation_timeseries.ipynb
[I 2022-06-13 16:00:24.529 ServerApp] Saving file at /jupyter_notebooks/paper/1.Precipitation_timeseries.ipynb
[I 2022-06-13 16:02:24.798 ServerApp] Saving file at /jupyter_notebooks/paper/1.Precipitation_timeseries.ipynb
[I 2022-06-13 16:04:25.081 ServerApp] Saving file at /jupyter_notebooks/paper/1.Precipitation_timeseries.ipynb
[I 2022-06-13 16:06:25.509 ServerApp] Saving file at /jupyter_notebooks/paper/1.Precipitation_timeseries.ipynb
[I 2022-06-13 16:07:56.283 ServerApp] Saving file at /jupyter_notebooks/1.Timeseries_individual_precipitation.ipynb
[I 2022-06-13 16:08:25.827 ServerApp] Saving file at /jupyter_notebooks/paper/1.Precipitation_timeseries.ipynb
[I 2022-06-13 16:10:26.179 ServerApp] Saving file at /jupyter_notebooks/paper/1.Precipitation_timeseries.ipynb
[I 2022-06-13 16:12:26.770 ServerApp] Saving file at /jupyter_notebooks/paper/1.Precipitation_timeseries.ipynb
[I 2022-06-13 16:14:27.361 ServerApp] Saving file at /jupyter_notebooks/paper/1.Precipitation_timeseries.ipynb
[I 2022-06-13 16:16:27.943 ServerApp] Saving file at /jupyter_notebooks/paper/1.Precipitation_timeseries.ipynb
[I 2022-06-13 16:18:28.526 ServerApp] Saving file at /jupyter_notebooks/paper/1.Precipitation_timeseries.ipynb
[I 2022-06-13 16:20:00.504 ServerApp] Saving file at /jupyter_notebooks/1.Timeseries_individual_precipitation.ipynb
[I 2022-06-13 16:20:29.112 ServerApp] Saving file at /jupyter_notebooks/paper/1.Precipitation_timeseries.ipynb
[I 2022-06-13 16:22:29.699 ServerApp] Saving file at /jupyter_notebooks/paper/1.Precipitation_timeseries.ipynb
[I 2022-06-13 16:24:30.287 ServerApp] Saving file at /jupyter_notebooks/paper/1.Precipitation_timeseries.ipynb
[I 2022-06-13 16:26:30.875 ServerApp] Saving file at /jupyter_notebooks/paper/1.Precipitation_timeseries.ipynb
[I 2022-06-13 16:28:31.484 ServerApp] Saving file at /jupyter_notebooks/paper/1.Precipitation_timeseries.ipynb
[I 2022-06-13 16:30:32.055 ServerApp] Saving file at /jupyter_notebooks/paper/1.Precipitation_timeseries.ipynb
[I 2022-06-13 16:32:32.654 ServerApp] Saving file at /jupyter_notebooks/paper/1.Precipitation_timeseries.ipynb
[I 2022-06-13 16:34:33.275 ServerApp] Saving file at /jupyter_notebooks/paper/1.Precipitation_timeseries.ipynb
[I 2022-06-13 16:36:33.815 ServerApp] Saving file at /jupyter_notebooks/paper/1.Precipitation_timeseries.ipynb
[I 2022-06-13 16:38:34.400 ServerApp] Saving file at /jupyter_notebooks/paper/1.Precipitation_timeseries.ipynb
[I 2022-06-13 16:40:34.998 ServerApp] Saving file at /jupyter_notebooks/paper/1.Precipitation_timeseries.ipynb
[I 2022-06-13 16:42:35.577 ServerApp] Saving file at /jupyter_notebooks/paper/1.Precipitation_timeseries.ipynb
[I 2022-06-13 16:44:36.175 ServerApp] Saving file at /jupyter_notebooks/paper/1.Precipitation_timeseries.ipynb
[I 2022-06-13 16:46:36.805 ServerApp] Saving file at /jupyter_notebooks/paper/1.Precipitation_timeseries.ipynb
[I 2022-06-13 16:48:37.335 ServerApp] Saving file at /jupyter_notebooks/paper/1.Precipitation_timeseries.ipynb
[I 2022-06-13 16:50:37.927 ServerApp] Saving file at /jupyter_notebooks/paper/1.Precipitation_timeseries.ipynb
[I 2022-06-13 16:51:48.376 ServerApp] Copying jupyter_notebooks/1.Timeseries_ensemble-wm8.ipynb to /jupyter_notebooks
[I 2022-06-13 16:52:25.406 ServerApp] Kernel started: 0d705f20-a1a1-4d7d-b263-f5ab0c70db6d
[I 2022-06-13 16:52:38.511 ServerApp] Saving file at /jupyter_notebooks/paper/1b.Precipitation_timeseries.ipynb
[I 2022-06-13 16:54:39.617 ServerApp] Saving file at /jupyter_notebooks/paper/1b.Precipitation_timeseries.ipynb
[I 2022-06-13 16:56:40.178 ServerApp] Saving file at /jupyter_notebooks/paper/1b.Precipitation_timeseries.ipynb
[I 2022-06-13 16:58:40.774 ServerApp] Saving file at /jupyter_notebooks/paper/1b.Precipitation_timeseries.ipynb
[I 2022-06-13 16:59:05.806 ServerApp] Starting buffering for 0d705f20-a1a1-4d7d-b263-f5ab0c70db6d:69c53e6c-c8c5-4c26-8ab6-48cebb61dbf7
[I 2022-06-13 16:59:13.629 ServerApp] Kernel shutdown: 0d705f20-a1a1-4d7d-b263-f5ab0c70db6d
[W 2022-06-13 16:59:14.084 ServerApp] delete /jupyter_notebooks/paper/1a.Temperature_timeseries.ipynb
[W 2022-06-13 16:59:14.085 ServerApp] Skipping trash for /network/aopp/chaos/pred/kimpson/speedy-1/jupyter_notebooks/paper/1a.Temperature_timeseries.ipynb, on different device to home directory
[I 2022-06-13 16:59:17.502 ServerApp] Copying jupyter_notebooks/paper/1b.Precipitation_timeseries.ipynb to /jupyter_notebooks/paper
[I 2022-06-13 17:00:31.421 ServerApp] Kernel interrupted: aa43cd0c-abf8-4204-a364-b72d795cd894
[I 2022-06-13 17:00:32.232 ServerApp] Kernel interrupted: aa43cd0c-abf8-4204-a364-b72d795cd894
[I 2022-06-13 17:00:32.268 ServerApp] Kernel interrupted: aa43cd0c-abf8-4204-a364-b72d795cd894
[I 2022-06-13 17:00:41.152 ServerApp] Saving file at /jupyter_notebooks/paper/1b.Precipitation_timeseries.ipynb
[I 2022-06-13 17:00:55.555 ServerApp] Saving file at /jupyter_notebooks/paper/1b.Precipitation_timeseries.ipynb
[I 2022-06-13 17:00:55.750 ServerApp] Saving file at /jupyter_notebooks/paper/1b.Precipitation_timeseries.ipynb
[I 2022-06-13 17:01:01.643 ServerApp] Saving file at /jupyter_notebooks/1.Timeseries_individual.ipynb
[I 2022-06-13 17:01:04.418 ServerApp] Starting buffering for 0a408c42-0719-4783-8c0f-a69cffa4bca1:98be3506-f183-4da0-8614-aa42edfe8e50
[I 2022-06-13 17:01:06.867 ServerApp] Saving file at /jupyter_notebooks/1.Timeseries_individual.ipynb
[I 2022-06-13 17:01:08.295 ServerApp] Saving file at /jupyter_notebooks/1.Timeseries_individual.ipynb
[I 2022-06-13 17:01:08.723 ServerApp] Kernel started: feaa8cff-0254-4778-b8fd-76a5cbbbd6f0
[I 2022-06-13 17:03:03.583 ServerApp] Saving file at /jupyter_notebooks/paper/1a.Temperature_timeseries.ipynb
[I 2022-06-13 17:04:24.867 ServerApp] Saving file at /jupyter_notebooks/paper/1a.Temperature_timeseries.ipynb
[I 2022-06-13 17:06:25.347 ServerApp] Saving file at /jupyter_notebooks/paper/1a.Temperature_timeseries.ipynb
[I 2022-06-13 17:08:18.046 ServerApp] Saving file at /jupyter_notebooks/paper/1a.Temperature_timeseries.ipynb
[I 2022-06-13 17:08:23.104 ServerApp] Saving file at /jupyter_notebooks/paper/1a.Temperature_timeseries.ipynb
[I 2022-06-13 17:08:23.435 ServerApp] Saving file at /jupyter_notebooks/paper/1a.Temperature_timeseries.ipynb
[I 2022-06-13 17:08:33.099 ServerApp] Kernel interrupted: feaa8cff-0254-4778-b8fd-76a5cbbbd6f0
[I 2022-06-13 17:08:39.019 ServerApp] Saving file at /jupyter_notebooks/paper/1a.Temperature_timeseries.ipynb
[I 2022-06-13 17:14:39.636 ServerApp] Saving file at /jupyter_notebooks/paper/1a.Temperature_timeseries.ipynb
[I 2022-06-13 17:14:56.098 ServerApp] Saving file at /jupyter_notebooks/paper/1b.Precipitation_timeseries.ipynb
[I 2022-06-13 17:16:56.555 ServerApp] Saving file at /jupyter_notebooks/paper/1b.Precipitation_timeseries.ipynb
[I 2022-06-13 17:18:56.891 ServerApp] Saving file at /jupyter_notebooks/paper/1b.Precipitation_timeseries.ipynb
[I 2022-06-13 17:20:57.294 ServerApp] Saving file at /jupyter_notebooks/paper/1b.Precipitation_timeseries.ipynb
[I 2022-06-13 17:22:57.622 ServerApp] Saving file at /jupyter_notebooks/paper/1b.Precipitation_timeseries.ipynb
[I 2022-06-13 17:24:58.153 ServerApp] Saving file at /jupyter_notebooks/paper/1b.Precipitation_timeseries.ipynb
[I 2022-06-13 17:26:58.601 ServerApp] Saving file at /jupyter_notebooks/paper/1b.Precipitation_timeseries.ipynb
[I 2022-06-13 17:28:58.935 ServerApp] Saving file at /jupyter_notebooks/paper/1b.Precipitation_timeseries.ipynb
[I 2022-06-13 17:30:59.828 ServerApp] Saving file at /jupyter_notebooks/paper/1b.Precipitation_timeseries.ipynb
[I 2022-06-13 17:33:01.039 ServerApp] Saving file at /jupyter_notebooks/paper/1b.Precipitation_timeseries.ipynb
[I 2022-06-13 17:35:02.037 ServerApp] Saving file at /jupyter_notebooks/paper/1b.Precipitation_timeseries.ipynb
[I 2022-06-13 17:37:03.423 ServerApp] Saving file at /jupyter_notebooks/paper/1b.Precipitation_timeseries.ipynb
[I 2022-06-13 17:39:04.962 ServerApp] Saving file at /jupyter_notebooks/paper/1b.Precipitation_timeseries.ipynb
[I 2022-06-13 17:41:06.025 ServerApp] Saving file at /jupyter_notebooks/paper/1b.Precipitation_timeseries.ipynb
[I 2022-06-13 17:43:07.180 ServerApp] Saving file at /jupyter_notebooks/paper/1b.Precipitation_timeseries.ipynb
[I 2022-06-13 17:45:08.268 ServerApp] Saving file at /jupyter_notebooks/paper/1b.Precipitation_timeseries.ipynb
[I 2022-06-13 17:47:08.935 ServerApp] Saving file at /jupyter_notebooks/paper/1b.Precipitation_timeseries.ipynb
[I 2022-06-13 17:49:11.044 ServerApp] Saving file at /jupyter_notebooks/paper/1b.Precipitation_timeseries.ipynb
[I 2022-06-13 17:51:12.652 ServerApp] Saving file at /jupyter_notebooks/paper/1b.Precipitation_timeseries.ipynb
[I 2022-06-13 17:53:14.323 ServerApp] Saving file at /jupyter_notebooks/paper/1b.Precipitation_timeseries.ipynb
[I 2022-06-13 17:55:16.939 ServerApp] Saving file at /jupyter_notebooks/paper/1b.Precipitation_timeseries.ipynb
[I 2022-06-13 17:57:19.565 ServerApp] Saving file at /jupyter_notebooks/paper/1b.Precipitation_timeseries.ipynb
[I 2022-06-13 17:59:21.130 ServerApp] Saving file at /jupyter_notebooks/paper/1b.Precipitation_timeseries.ipynb
[I 2022-06-13 18:01:22.051 ServerApp] Saving file at /jupyter_notebooks/paper/1b.Precipitation_timeseries.ipynb
[I 2022-06-13 18:03:22.972 ServerApp] Saving file at /jupyter_notebooks/paper/1b.Precipitation_timeseries.ipynb
[I 2022-06-13 18:05:24.375 ServerApp] Saving file at /jupyter_notebooks/paper/1b.Precipitation_timeseries.ipynb
[I 2022-06-13 18:07:25.758 ServerApp] Saving file at /jupyter_notebooks/paper/1b.Precipitation_timeseries.ipynb
[I 2022-06-13 18:09:26.738 ServerApp] Saving file at /jupyter_notebooks/paper/1b.Precipitation_timeseries.ipynb
[I 2022-06-13 18:11:02.463 ServerApp] Kernel started: babec40f-135a-42c1-8757-5456a3cfceac
[I 2022-06-13 18:11:27.091 ServerApp] Saving file at /jupyter_notebooks/paper/1b.Precipitation_timeseries.ipynb
[I 2022-06-13 18:13:27.517 ServerApp] Saving file at /jupyter_notebooks/paper/1b.Precipitation_timeseries.ipynb
[I 2022-06-13 18:15:28.104 ServerApp] Saving file at /jupyter_notebooks/paper/1b.Precipitation_timeseries.ipynb
[I 2022-06-13 18:17:28.695 ServerApp] Saving file at /jupyter_notebooks/paper/1b.Precipitation_timeseries.ipynb
[I 2022-06-13 18:19:29.277 ServerApp] Saving file at /jupyter_notebooks/paper/1b.Precipitation_timeseries.ipynb
[I 2022-06-13 18:21:29.864 ServerApp] Saving file at /jupyter_notebooks/paper/1b.Precipitation_timeseries.ipynb
[I 2022-06-13 18:23:30.466 ServerApp] Saving file at /jupyter_notebooks/paper/1b.Precipitation_timeseries.ipynb
[I 2022-06-13 18:25:31.070 ServerApp] Saving file at /jupyter_notebooks/paper/1b.Precipitation_timeseries.ipynb
[I 2022-06-13 18:27:31.659 ServerApp] Saving file at /jupyter_notebooks/paper/1b.Precipitation_timeseries.ipynb
[I 2022-06-13 18:29:32.209 ServerApp] Saving file at /jupyter_notebooks/paper/1b.Precipitation_timeseries.ipynb
[I 2022-06-13 18:31:32.799 ServerApp] Saving file at /jupyter_notebooks/paper/1b.Precipitation_timeseries.ipynb
[I 2022-06-13 18:33:33.389 ServerApp] Saving file at /jupyter_notebooks/paper/1b.Precipitation_timeseries.ipynb
[I 2022-06-13 18:35:33.970 ServerApp] Saving file at /jupyter_notebooks/paper/1b.Precipitation_timeseries.ipynb
[I 2022-06-13 18:37:34.561 ServerApp] Saving file at /jupyter_notebooks/paper/1b.Precipitation_timeseries.ipynb
[I 2022-06-13 18:39:35.151 ServerApp] Saving file at /jupyter_notebooks/paper/1b.Precipitation_timeseries.ipynb
[I 2022-06-13 18:41:35.736 ServerApp] Saving file at /jupyter_notebooks/paper/1b.Precipitation_timeseries.ipynb
[E 2022-06-13 18:41:40.801 ServerApp] Error while saving file: jupyter_notebooks/paper/1b.Precipitation_timeseries.ipynb database is locked
    Traceback (most recent call last):
      File "/home/k/kimpson/bin/conda/envs/workhorse/lib/python3.7/site-packages/jupyter_server/services/contents/filemanager.py", line 427, in save
      File "/home/k/kimpson/bin/conda/envs/workhorse/lib/python3.7/site-packages/jupyter_server/services/contents/manager.py", line 644, in check_and_sign
      File "/home/k/kimpson/bin/conda/envs/workhorse/lib/python3.7/site-packages/nbformat/sign.py", line 482, in sign
      File "/home/k/kimpson/bin/conda/envs/workhorse/lib/python3.7/site-packages/nbformat/sign.py", line 224, in store_signature
      File "/home/k/kimpson/bin/conda/envs/workhorse/lib/python3.7/site-packages/nbformat/sign.py", line 255, in check_signature
    sqlite3.OperationalError: database is locked
[W 2022-06-13 18:41:40.810 ServerApp] 500 PUT /api/contents/jupyter_notebooks/paper/1b.Precipitation_timeseries.ipynb?1655142095441 (::1): Unexpected error while saving file: jupyter_notebooks/paper/1b.Precipitation_timeseries.ipynb database is locked
[W 2022-06-13 18:41:40.810 ServerApp] Unexpected error while saving file: jupyter_notebooks/paper/1b.Precipitation_timeseries.ipynb database is locked
[E 2022-06-13 18:41:40.811 ServerApp] {
      "Host": "localhost:8885",
      "Accept": "*/*",
      "Referer": "http://localhost:8885/lab/tree/jupyter_notebooks/paper/1b.Precipitation_timeseries.ipynb",
      "User-Agent": "Mozilla/5.0 (Macintosh; Intel Mac OS X 10_15_7) AppleWebKit/537.36 (KHTML, like Gecko) Chrome/100.0.4896.79 Safari/537.36"
    }
[E 2022-06-13 18:41:40.811 ServerApp] 500 PUT /api/contents/jupyter_notebooks/paper/1b.Precipitation_timeseries.ipynb?1655142095441 (::1) 5245.12ms referer=http://localhost:8885/lab/tree/jupyter_notebooks/paper/1b.Precipitation_timeseries.ipynb
[I 2022-06-13 18:43:35.641 ServerApp] Saving file at /jupyter_notebooks/paper/1b.Precipitation_timeseries.ipynb
[E 2022-06-13 18:43:40.706 ServerApp] Error while saving file: jupyter_notebooks/paper/1b.Precipitation_timeseries.ipynb database is locked
    Traceback (most recent call last):
      File "/home/k/kimpson/bin/conda/envs/workhorse/lib/python3.7/site-packages/jupyter_server/services/contents/filemanager.py", line 427, in save
      File "/home/k/kimpson/bin/conda/envs/workhorse/lib/python3.7/site-packages/jupyter_server/services/contents/manager.py", line 644, in check_and_sign
      File "/home/k/kimpson/bin/conda/envs/workhorse/lib/python3.7/site-packages/nbformat/sign.py", line 482, in sign
      File "/home/k/kimpson/bin/conda/envs/workhorse/lib/python3.7/site-packages/nbformat/sign.py", line 224, in store_signature
      File "/home/k/kimpson/bin/conda/envs/workhorse/lib/python3.7/site-packages/nbformat/sign.py", line 255, in check_signature
    sqlite3.OperationalError: database is locked
[W 2022-06-13 18:43:40.714 ServerApp] 500 PUT /api/contents/jupyter_notebooks/paper/1b.Precipitation_timeseries.ipynb?1655142215349 (::1): Unexpected error while saving file: jupyter_notebooks/paper/1b.Precipitation_timeseries.ipynb database is locked
[W 2022-06-13 18:43:40.714 ServerApp] Unexpected error while saving file: jupyter_notebooks/paper/1b.Precipitation_timeseries.ipynb database is locked
[E 2022-06-13 18:43:40.715 ServerApp] {
      "Host": "localhost:8885",
      "Accept": "*/*",
      "Referer": "http://localhost:8885/lab/tree/jupyter_notebooks/paper/1b.Precipitation_timeseries.ipynb",
      "User-Agent": "Mozilla/5.0 (Macintosh; Intel Mac OS X 10_15_7) AppleWebKit/537.36 (KHTML, like Gecko) Chrome/100.0.4896.79 Safari/537.36"
    }
[E 2022-06-13 18:43:40.716 ServerApp] 500 PUT /api/contents/jupyter_notebooks/paper/1b.Precipitation_timeseries.ipynb?1655142215349 (::1) 5244.93ms referer=http://localhost:8885/lab/tree/jupyter_notebooks/paper/1b.Precipitation_timeseries.ipynb
[I 2022-06-13 18:45:35.748 ServerApp] Saving file at /jupyter_notebooks/paper/1b.Precipitation_timeseries.ipynb
[E 2022-06-13 18:45:40.815 ServerApp] Error while saving file: jupyter_notebooks/paper/1b.Precipitation_timeseries.ipynb database is locked
    Traceback (most recent call last):
      File "/home/k/kimpson/bin/conda/envs/workhorse/lib/python3.7/site-packages/jupyter_server/services/contents/filemanager.py", line 427, in save
      File "/home/k/kimpson/bin/conda/envs/workhorse/lib/python3.7/site-packages/jupyter_server/services/contents/manager.py", line 644, in check_and_sign
      File "/home/k/kimpson/bin/conda/envs/workhorse/lib/python3.7/site-packages/nbformat/sign.py", line 482, in sign
      File "/home/k/kimpson/bin/conda/envs/workhorse/lib/python3.7/site-packages/nbformat/sign.py", line 224, in store_signature
      File "/home/k/kimpson/bin/conda/envs/workhorse/lib/python3.7/site-packages/nbformat/sign.py", line 255, in check_signature
    sqlite3.OperationalError: database is locked
[W 2022-06-13 18:45:40.824 ServerApp] 500 PUT /api/contents/jupyter_notebooks/paper/1b.Precipitation_timeseries.ipynb?1655142335261 (::1): Unexpected error while saving file: jupyter_notebooks/paper/1b.Precipitation_timeseries.ipynb database is locked
[W 2022-06-13 18:45:40.824 ServerApp] Unexpected error while saving file: jupyter_notebooks/paper/1b.Precipitation_timeseries.ipynb database is locked
[E 2022-06-13 18:45:40.825 ServerApp] {
      "Host": "localhost:8885",
      "Accept": "*/*",
      "Referer": "http://localhost:8885/lab/tree/jupyter_notebooks/paper/1b.Precipitation_timeseries.ipynb",
      "User-Agent": "Mozilla/5.0 (Macintosh; Intel Mac OS X 10_15_7) AppleWebKit/537.36 (KHTML, like Gecko) Chrome/100.0.4896.79 Safari/537.36"
    }
[E 2022-06-13 18:45:40.825 ServerApp] 500 PUT /api/contents/jupyter_notebooks/paper/1b.Precipitation_timeseries.ipynb?1655142335261 (::1) 5437.80ms referer=http://localhost:8885/lab/tree/jupyter_notebooks/paper/1b.Precipitation_timeseries.ipynb
[I 2022-06-13 18:47:35.573 ServerApp] Saving file at /jupyter_notebooks/paper/1b.Precipitation_timeseries.ipynb
[E 2022-06-13 18:47:40.638 ServerApp] Error while saving file: jupyter_notebooks/paper/1b.Precipitation_timeseries.ipynb database is locked
    Traceback (most recent call last):
      File "/home/k/kimpson/bin/conda/envs/workhorse/lib/python3.7/site-packages/jupyter_server/services/contents/filemanager.py", line 427, in save
      File "/home/k/kimpson/bin/conda/envs/workhorse/lib/python3.7/site-packages/jupyter_server/services/contents/manager.py", line 644, in check_and_sign
      File "/home/k/kimpson/bin/conda/envs/workhorse/lib/python3.7/site-packages/nbformat/sign.py", line 482, in sign
      File "/home/k/kimpson/bin/conda/envs/workhorse/lib/python3.7/site-packages/nbformat/sign.py", line 224, in store_signature
      File "/home/k/kimpson/bin/conda/envs/workhorse/lib/python3.7/site-packages/nbformat/sign.py", line 255, in check_signature
    sqlite3.OperationalError: database is locked
[W 2022-06-13 18:47:40.646 ServerApp] 500 PUT /api/contents/jupyter_notebooks/paper/1b.Precipitation_timeseries.ipynb?1655142455264 (::1): Unexpected error while saving file: jupyter_notebooks/paper/1b.Precipitation_timeseries.ipynb database is locked
[W 2022-06-13 18:47:40.647 ServerApp] Unexpected error while saving file: jupyter_notebooks/paper/1b.Precipitation_timeseries.ipynb database is locked
[E 2022-06-13 18:47:40.648 ServerApp] {
      "Host": "localhost:8885",
      "Accept": "*/*",
      "Referer": "http://localhost:8885/lab/tree/jupyter_notebooks/paper/1b.Precipitation_timeseries.ipynb",
      "User-Agent": "Mozilla/5.0 (Macintosh; Intel Mac OS X 10_15_7) AppleWebKit/537.36 (KHTML, like Gecko) Chrome/100.0.4896.79 Safari/537.36"
    }
[E 2022-06-13 18:47:40.648 ServerApp] 500 PUT /api/contents/jupyter_notebooks/paper/1b.Precipitation_timeseries.ipynb?1655142455264 (::1) 5251.58ms referer=http://localhost:8885/lab/tree/jupyter_notebooks/paper/1b.Precipitation_timeseries.ipynb
[I 2022-06-13 18:49:35.584 ServerApp] Saving file at /jupyter_notebooks/paper/1b.Precipitation_timeseries.ipynb
[E 2022-06-13 18:49:40.649 ServerApp] Error while saving file: jupyter_notebooks/paper/1b.Precipitation_timeseries.ipynb database is locked
    Traceback (most recent call last):
      File "/home/k/kimpson/bin/conda/envs/workhorse/lib/python3.7/site-packages/jupyter_server/services/contents/filemanager.py", line 427, in save
      File "/home/k/kimpson/bin/conda/envs/workhorse/lib/python3.7/site-packages/jupyter_server/services/contents/manager.py", line 644, in check_and_sign
      File "/home/k/kimpson/bin/conda/envs/workhorse/lib/python3.7/site-packages/nbformat/sign.py", line 482, in sign
      File "/home/k/kimpson/bin/conda/envs/workhorse/lib/python3.7/site-packages/nbformat/sign.py", line 224, in store_signature
      File "/home/k/kimpson/bin/conda/envs/workhorse/lib/python3.7/site-packages/nbformat/sign.py", line 255, in check_signature
    sqlite3.OperationalError: database is locked
[W 2022-06-13 18:49:40.657 ServerApp] 500 PUT /api/contents/jupyter_notebooks/paper/1b.Precipitation_timeseries.ipynb?1655142575272 (::1): Unexpected error while saving file: jupyter_notebooks/paper/1b.Precipitation_timeseries.ipynb database is locked
[W 2022-06-13 18:49:40.658 ServerApp] Unexpected error while saving file: jupyter_notebooks/paper/1b.Precipitation_timeseries.ipynb database is locked
[E 2022-06-13 18:49:40.659 ServerApp] {
      "Host": "localhost:8885",
      "Accept": "*/*",
      "Referer": "http://localhost:8885/lab/tree/jupyter_notebooks/paper/1b.Precipitation_timeseries.ipynb",
      "User-Agent": "Mozilla/5.0 (Macintosh; Intel Mac OS X 10_15_7) AppleWebKit/537.36 (KHTML, like Gecko) Chrome/100.0.4896.79 Safari/537.36"
    }
[E 2022-06-13 18:49:40.659 ServerApp] 500 PUT /api/contents/jupyter_notebooks/paper/1b.Precipitation_timeseries.ipynb?1655142575272 (::1) 5282.15ms referer=http://localhost:8885/lab/tree/jupyter_notebooks/paper/1b.Precipitation_timeseries.ipynb
[I 2022-06-13 18:51:35.585 ServerApp] Saving file at /jupyter_notebooks/paper/1b.Precipitation_timeseries.ipynb
[E 2022-06-13 18:51:40.649 ServerApp] Error while saving file: jupyter_notebooks/paper/1b.Precipitation_timeseries.ipynb database is locked
    Traceback (most recent call last):
      File "/home/k/kimpson/bin/conda/envs/workhorse/lib/python3.7/site-packages/jupyter_server/services/contents/filemanager.py", line 427, in save
      File "/home/k/kimpson/bin/conda/envs/workhorse/lib/python3.7/site-packages/jupyter_server/services/contents/manager.py", line 644, in check_and_sign
      File "/home/k/kimpson/bin/conda/envs/workhorse/lib/python3.7/site-packages/nbformat/sign.py", line 482, in sign
      File "/home/k/kimpson/bin/conda/envs/workhorse/lib/python3.7/site-packages/nbformat/sign.py", line 224, in store_signature
      File "/home/k/kimpson/bin/conda/envs/workhorse/lib/python3.7/site-packages/nbformat/sign.py", line 255, in check_signature
    sqlite3.OperationalError: database is locked
[W 2022-06-13 18:51:40.658 ServerApp] 500 PUT /api/contents/jupyter_notebooks/paper/1b.Precipitation_timeseries.ipynb?1655142695266 (::1): Unexpected error while saving file: jupyter_notebooks/paper/1b.Precipitation_timeseries.ipynb database is locked
[W 2022-06-13 18:51:40.658 ServerApp] Unexpected error while saving file: jupyter_notebooks/paper/1b.Precipitation_timeseries.ipynb database is locked
[E 2022-06-13 18:51:40.659 ServerApp] {
      "Host": "localhost:8885",
      "Accept": "*/*",
      "Referer": "http://localhost:8885/lab/tree/jupyter_notebooks/paper/1b.Precipitation_timeseries.ipynb",
      "User-Agent": "Mozilla/5.0 (Macintosh; Intel Mac OS X 10_15_7) AppleWebKit/537.36 (KHTML, like Gecko) Chrome/100.0.4896.79 Safari/537.36"
    }
[E 2022-06-13 18:51:40.659 ServerApp] 500 PUT /api/contents/jupyter_notebooks/paper/1b.Precipitation_timeseries.ipynb?1655142695266 (::1) 5245.58ms referer=http://localhost:8885/lab/tree/jupyter_notebooks/paper/1b.Precipitation_timeseries.ipynb
[I 2022-06-13 18:53:35.564 ServerApp] Saving file at /jupyter_notebooks/paper/1b.Precipitation_timeseries.ipynb
[E 2022-06-13 18:53:40.630 ServerApp] Error while saving file: jupyter_notebooks/paper/1b.Precipitation_timeseries.ipynb database is locked
    Traceback (most recent call last):
      File "/home/k/kimpson/bin/conda/envs/workhorse/lib/python3.7/site-packages/jupyter_server/services/contents/filemanager.py", line 427, in save
      File "/home/k/kimpson/bin/conda/envs/workhorse/lib/python3.7/site-packages/jupyter_server/services/contents/manager.py", line 644, in check_and_sign
      File "/home/k/kimpson/bin/conda/envs/workhorse/lib/python3.7/site-packages/nbformat/sign.py", line 482, in sign
      File "/home/k/kimpson/bin/conda/envs/workhorse/lib/python3.7/site-packages/nbformat/sign.py", line 224, in store_signature
      File "/home/k/kimpson/bin/conda/envs/workhorse/lib/python3.7/site-packages/nbformat/sign.py", line 255, in check_signature
    sqlite3.OperationalError: database is locked
[W 2022-06-13 18:53:40.638 ServerApp] 500 PUT /api/contents/jupyter_notebooks/paper/1b.Precipitation_timeseries.ipynb?1655142815266 (::1): Unexpected error while saving file: jupyter_notebooks/paper/1b.Precipitation_timeseries.ipynb database is locked
[W 2022-06-13 18:53:40.639 ServerApp] Unexpected error while saving file: jupyter_notebooks/paper/1b.Precipitation_timeseries.ipynb database is locked
[E 2022-06-13 18:53:40.639 ServerApp] {
      "Host": "localhost:8885",
      "Accept": "*/*",
      "Referer": "http://localhost:8885/lab/tree/jupyter_notebooks/paper/1b.Precipitation_timeseries.ipynb",
      "User-Agent": "Mozilla/5.0 (Macintosh; Intel Mac OS X 10_15_7) AppleWebKit/537.36 (KHTML, like Gecko) Chrome/100.0.4896.79 Safari/537.36"
    }
[E 2022-06-13 18:53:40.640 ServerApp] 500 PUT /api/contents/jupyter_notebooks/paper/1b.Precipitation_timeseries.ipynb?1655142815266 (::1) 5245.83ms referer=http://localhost:8885/lab/tree/jupyter_notebooks/paper/1b.Precipitation_timeseries.ipynb
[I 2022-06-13 18:55:35.660 ServerApp] Saving file at /jupyter_notebooks/paper/1b.Precipitation_timeseries.ipynb
[E 2022-06-13 18:55:40.725 ServerApp] Error while saving file: jupyter_notebooks/paper/1b.Precipitation_timeseries.ipynb database is locked
    Traceback (most recent call last):
      File "/home/k/kimpson/bin/conda/envs/workhorse/lib/python3.7/site-packages/jupyter_server/services/contents/filemanager.py", line 427, in save
      File "/home/k/kimpson/bin/conda/envs/workhorse/lib/python3.7/site-packages/jupyter_server/services/contents/manager.py", line 644, in check_and_sign
      File "/home/k/kimpson/bin/conda/envs/workhorse/lib/python3.7/site-packages/nbformat/sign.py", line 482, in sign
      File "/home/k/kimpson/bin/conda/envs/workhorse/lib/python3.7/site-packages/nbformat/sign.py", line 224, in store_signature
      File "/home/k/kimpson/bin/conda/envs/workhorse/lib/python3.7/site-packages/nbformat/sign.py", line 255, in check_signature
    sqlite3.OperationalError: database is locked
[W 2022-06-13 18:55:40.734 ServerApp] 500 PUT /api/contents/jupyter_notebooks/paper/1b.Precipitation_timeseries.ipynb?1655142935350 (::1): Unexpected error while saving file: jupyter_notebooks/paper/1b.Precipitation_timeseries.ipynb database is locked
[W 2022-06-13 18:55:40.734 ServerApp] Unexpected error while saving file: jupyter_notebooks/paper/1b.Precipitation_timeseries.ipynb database is locked
[E 2022-06-13 18:55:40.735 ServerApp] {
      "Host": "localhost:8885",
      "Accept": "*/*",
      "Referer": "http://localhost:8885/lab/tree/jupyter_notebooks/paper/1b.Precipitation_timeseries.ipynb",
      "User-Agent": "Mozilla/5.0 (Macintosh; Intel Mac OS X 10_15_7) AppleWebKit/537.36 (KHTML, like Gecko) Chrome/100.0.4896.79 Safari/537.36"
    }
[E 2022-06-13 18:55:40.735 ServerApp] 500 PUT /api/contents/jupyter_notebooks/paper/1b.Precipitation_timeseries.ipynb?1655142935350 (::1) 5245.77ms referer=http://localhost:8885/lab/tree/jupyter_notebooks/paper/1b.Precipitation_timeseries.ipynb
[I 2022-06-13 18:57:35.577 ServerApp] Saving file at /jupyter_notebooks/paper/1b.Precipitation_timeseries.ipynb
[E 2022-06-13 18:57:40.641 ServerApp] Error while saving file: jupyter_notebooks/paper/1b.Precipitation_timeseries.ipynb database is locked
    Traceback (most recent call last):
      File "/home/k/kimpson/bin/conda/envs/workhorse/lib/python3.7/site-packages/jupyter_server/services/contents/filemanager.py", line 427, in save
      File "/home/k/kimpson/bin/conda/envs/workhorse/lib/python3.7/site-packages/jupyter_server/services/contents/manager.py", line 644, in check_and_sign
      File "/home/k/kimpson/bin/conda/envs/workhorse/lib/python3.7/site-packages/nbformat/sign.py", line 482, in sign
      File "/home/k/kimpson/bin/conda/envs/workhorse/lib/python3.7/site-packages/nbformat/sign.py", line 224, in store_signature
      File "/home/k/kimpson/bin/conda/envs/workhorse/lib/python3.7/site-packages/nbformat/sign.py", line 255, in check_signature
    sqlite3.OperationalError: database is locked
[W 2022-06-13 18:57:40.650 ServerApp] 500 PUT /api/contents/jupyter_notebooks/paper/1b.Precipitation_timeseries.ipynb?1655143055277 (::1): Unexpected error while saving file: jupyter_notebooks/paper/1b.Precipitation_timeseries.ipynb database is locked
[W 2022-06-13 18:57:40.651 ServerApp] Unexpected error while saving file: jupyter_notebooks/paper/1b.Precipitation_timeseries.ipynb database is locked
[E 2022-06-13 18:57:40.652 ServerApp] {
      "Host": "localhost:8885",
      "Accept": "*/*",
      "Referer": "http://localhost:8885/lab/tree/jupyter_notebooks/paper/1b.Precipitation_timeseries.ipynb",
      "User-Agent": "Mozilla/5.0 (Macintosh; Intel Mac OS X 10_15_7) AppleWebKit/537.36 (KHTML, like Gecko) Chrome/100.0.4896.79 Safari/537.36"
    }
[E 2022-06-13 18:57:40.652 ServerApp] 500 PUT /api/contents/jupyter_notebooks/paper/1b.Precipitation_timeseries.ipynb?1655143055277 (::1) 5245.51ms referer=http://localhost:8885/lab/tree/jupyter_notebooks/paper/1b.Precipitation_timeseries.ipynb
[I 2022-06-13 18:59:35.853 ServerApp] Saving file at /jupyter_notebooks/paper/1b.Precipitation_timeseries.ipynb
[E 2022-06-13 18:59:40.920 ServerApp] Error while saving file: jupyter_notebooks/paper/1b.Precipitation_timeseries.ipynb database is locked
    Traceback (most recent call last):
      File "/home/k/kimpson/bin/conda/envs/workhorse/lib/python3.7/site-packages/jupyter_server/services/contents/filemanager.py", line 427, in save
      File "/home/k/kimpson/bin/conda/envs/workhorse/lib/python3.7/site-packages/jupyter_server/services/contents/manager.py", line 644, in check_and_sign
      File "/home/k/kimpson/bin/conda/envs/workhorse/lib/python3.7/site-packages/nbformat/sign.py", line 482, in sign
      File "/home/k/kimpson/bin/conda/envs/workhorse/lib/python3.7/site-packages/nbformat/sign.py", line 224, in store_signature
      File "/home/k/kimpson/bin/conda/envs/workhorse/lib/python3.7/site-packages/nbformat/sign.py", line 255, in check_signature
    sqlite3.OperationalError: database is locked
[W 2022-06-13 18:59:40.928 ServerApp] 500 PUT /api/contents/jupyter_notebooks/paper/1b.Precipitation_timeseries.ipynb?1655143175472 (::1): Unexpected error while saving file: jupyter_notebooks/paper/1b.Precipitation_timeseries.ipynb database is locked
[W 2022-06-13 18:59:40.929 ServerApp] Unexpected error while saving file: jupyter_notebooks/paper/1b.Precipitation_timeseries.ipynb database is locked
[E 2022-06-13 18:59:40.929 ServerApp] {
      "Host": "localhost:8885",
      "Accept": "*/*",
      "Referer": "http://localhost:8885/lab/tree/jupyter_notebooks/paper/1b.Precipitation_timeseries.ipynb",
      "User-Agent": "Mozilla/5.0 (Macintosh; Intel Mac OS X 10_15_7) AppleWebKit/537.36 (KHTML, like Gecko) Chrome/100.0.4896.79 Safari/537.36"
    }
[E 2022-06-13 18:59:40.930 ServerApp] 500 PUT /api/contents/jupyter_notebooks/paper/1b.Precipitation_timeseries.ipynb?1655143175472 (::1) 5250.40ms referer=http://localhost:8885/lab/tree/jupyter_notebooks/paper/1b.Precipitation_timeseries.ipynb
[I 2022-06-13 19:01:35.969 ServerApp] Saving file at /jupyter_notebooks/paper/1b.Precipitation_timeseries.ipynb
[E 2022-06-13 19:01:41.034 ServerApp] Error while saving file: jupyter_notebooks/paper/1b.Precipitation_timeseries.ipynb database is locked
    Traceback (most recent call last):
      File "/home/k/kimpson/bin/conda/envs/workhorse/lib/python3.7/site-packages/jupyter_server/services/contents/filemanager.py", line 427, in save
      File "/home/k/kimpson/bin/conda/envs/workhorse/lib/python3.7/site-packages/jupyter_server/services/contents/manager.py", line 644, in check_and_sign
      File "/home/k/kimpson/bin/conda/envs/workhorse/lib/python3.7/site-packages/nbformat/sign.py", line 482, in sign
      File "/home/k/kimpson/bin/conda/envs/workhorse/lib/python3.7/site-packages/nbformat/sign.py", line 224, in store_signature
      File "/home/k/kimpson/bin/conda/envs/workhorse/lib/python3.7/site-packages/nbformat/sign.py", line 255, in check_signature
    sqlite3.OperationalError: database is locked
[W 2022-06-13 19:01:41.043 ServerApp] 500 PUT /api/contents/jupyter_notebooks/paper/1b.Precipitation_timeseries.ipynb?1655143295667 (::1): Unexpected error while saving file: jupyter_notebooks/paper/1b.Precipitation_timeseries.ipynb database is locked
[W 2022-06-13 19:01:41.043 ServerApp] Unexpected error while saving file: jupyter_notebooks/paper/1b.Precipitation_timeseries.ipynb database is locked
[E 2022-06-13 19:01:41.044 ServerApp] {
      "Host": "localhost:8885",
      "Accept": "*/*",
      "Referer": "http://localhost:8885/lab/tree/jupyter_notebooks/paper/1b.Precipitation_timeseries.ipynb",
      "User-Agent": "Mozilla/5.0 (Macintosh; Intel Mac OS X 10_15_7) AppleWebKit/537.36 (KHTML, like Gecko) Chrome/100.0.4896.79 Safari/537.36"
    }
[E 2022-06-13 19:01:41.044 ServerApp] 500 PUT /api/contents/jupyter_notebooks/paper/1b.Precipitation_timeseries.ipynb?1655143295667 (::1) 5246.11ms referer=http://localhost:8885/lab/tree/jupyter_notebooks/paper/1b.Precipitation_timeseries.ipynb
[I 2022-06-13 19:03:36.188 ServerApp] Saving file at /jupyter_notebooks/paper/1b.Precipitation_timeseries.ipynb
[E 2022-06-13 19:03:41.254 ServerApp] Error while saving file: jupyter_notebooks/paper/1b.Precipitation_timeseries.ipynb database is locked
    Traceback (most recent call last):
      File "/home/k/kimpson/bin/conda/envs/workhorse/lib/python3.7/site-packages/jupyter_server/services/contents/filemanager.py", line 427, in save
      File "/home/k/kimpson/bin/conda/envs/workhorse/lib/python3.7/site-packages/jupyter_server/services/contents/manager.py", line 644, in check_and_sign
      File "/home/k/kimpson/bin/conda/envs/workhorse/lib/python3.7/site-packages/nbformat/sign.py", line 482, in sign
      File "/home/k/kimpson/bin/conda/envs/workhorse/lib/python3.7/site-packages/nbformat/sign.py", line 224, in store_signature
      File "/home/k/kimpson/bin/conda/envs/workhorse/lib/python3.7/site-packages/nbformat/sign.py", line 255, in check_signature
    sqlite3.OperationalError: database is locked
[W 2022-06-13 19:03:41.262 ServerApp] 500 PUT /api/contents/jupyter_notebooks/paper/1b.Precipitation_timeseries.ipynb?1655143415819 (::1): Unexpected error while saving file: jupyter_notebooks/paper/1b.Precipitation_timeseries.ipynb database is locked
[W 2022-06-13 19:03:41.263 ServerApp] Unexpected error while saving file: jupyter_notebooks/paper/1b.Precipitation_timeseries.ipynb database is locked
[E 2022-06-13 19:03:41.264 ServerApp] {
      "Host": "localhost:8885",
      "Accept": "*/*",
      "Referer": "http://localhost:8885/lab/tree/jupyter_notebooks/paper/1b.Precipitation_timeseries.ipynb",
      "User-Agent": "Mozilla/5.0 (Macintosh; Intel Mac OS X 10_15_7) AppleWebKit/537.36 (KHTML, like Gecko) Chrome/100.0.4896.79 Safari/537.36"
    }
[E 2022-06-13 19:03:41.264 ServerApp] 500 PUT /api/contents/jupyter_notebooks/paper/1b.Precipitation_timeseries.ipynb?1655143415819 (::1) 5312.05ms referer=http://localhost:8885/lab/tree/jupyter_notebooks/paper/1b.Precipitation_timeseries.ipynb
[I 2022-06-13 19:06:25.254 ServerApp] Saving file at /jupyter_notebooks/paper/1b.Precipitation_timeseries.ipynb
[E 2022-06-13 19:06:30.319 ServerApp] Error while saving file: jupyter_notebooks/paper/1b.Precipitation_timeseries.ipynb database is locked
    Traceback (most recent call last):
      File "/home/k/kimpson/bin/conda/envs/workhorse/lib/python3.7/site-packages/jupyter_server/services/contents/filemanager.py", line 427, in save
      File "/home/k/kimpson/bin/conda/envs/workhorse/lib/python3.7/site-packages/jupyter_server/services/contents/manager.py", line 644, in check_and_sign
      File "/home/k/kimpson/bin/conda/envs/workhorse/lib/python3.7/site-packages/nbformat/sign.py", line 482, in sign
      File "/home/k/kimpson/bin/conda/envs/workhorse/lib/python3.7/site-packages/nbformat/sign.py", line 224, in store_signature
      File "/home/k/kimpson/bin/conda/envs/workhorse/lib/python3.7/site-packages/nbformat/sign.py", line 255, in check_signature
    sqlite3.OperationalError: database is locked
[W 2022-06-13 19:06:30.327 ServerApp] 500 PUT /api/contents/jupyter_notebooks/paper/1b.Precipitation_timeseries.ipynb?1655143584949 (::1): Unexpected error while saving file: jupyter_notebooks/paper/1b.Precipitation_timeseries.ipynb database is locked
[W 2022-06-13 19:06:30.328 ServerApp] Unexpected error while saving file: jupyter_notebooks/paper/1b.Precipitation_timeseries.ipynb database is locked
[E 2022-06-13 19:06:30.329 ServerApp] {
      "Host": "localhost:8885",
      "Accept": "*/*",
      "Referer": "http://localhost:8885/lab/tree/jupyter_notebooks/paper/1b.Precipitation_timeseries.ipynb",
      "User-Agent": "Mozilla/5.0 (Macintosh; Intel Mac OS X 10_15_7) AppleWebKit/537.36 (KHTML, like Gecko) Chrome/100.0.4896.79 Safari/537.36"
    }
[E 2022-06-13 19:06:30.329 ServerApp] 500 PUT /api/contents/jupyter_notebooks/paper/1b.Precipitation_timeseries.ipynb?1655143584949 (::1) 5246.98ms referer=http://localhost:8885/lab/tree/jupyter_notebooks/paper/1b.Precipitation_timeseries.ipynb
[I 2022-06-13 19:08:25.595 ServerApp] Saving file at /jupyter_notebooks/paper/1b.Precipitation_timeseries.ipynb
[E 2022-06-13 19:08:30.662 ServerApp] Error while saving file: jupyter_notebooks/paper/1b.Precipitation_timeseries.ipynb database is locked
    Traceback (most recent call last):
      File "/home/k/kimpson/bin/conda/envs/workhorse/lib/python3.7/site-packages/jupyter_server/services/contents/filemanager.py", line 427, in save
      File "/home/k/kimpson/bin/conda/envs/workhorse/lib/python3.7/site-packages/jupyter_server/services/contents/manager.py", line 644, in check_and_sign
      File "/home/k/kimpson/bin/conda/envs/workhorse/lib/python3.7/site-packages/nbformat/sign.py", line 482, in sign
      File "/home/k/kimpson/bin/conda/envs/workhorse/lib/python3.7/site-packages/nbformat/sign.py", line 224, in store_signature
      File "/home/k/kimpson/bin/conda/envs/workhorse/lib/python3.7/site-packages/nbformat/sign.py", line 255, in check_signature
    sqlite3.OperationalError: database is locked
[W 2022-06-13 19:08:30.670 ServerApp] 500 PUT /api/contents/jupyter_notebooks/paper/1b.Precipitation_timeseries.ipynb?1655143705226 (::1): Unexpected error while saving file: jupyter_notebooks/paper/1b.Precipitation_timeseries.ipynb database is locked
[W 2022-06-13 19:08:30.671 ServerApp] Unexpected error while saving file: jupyter_notebooks/paper/1b.Precipitation_timeseries.ipynb database is locked
[E 2022-06-13 19:08:30.672 ServerApp] {
      "Host": "localhost:8885",
      "Accept": "*/*",
      "Referer": "http://localhost:8885/lab/tree/jupyter_notebooks/paper/1b.Precipitation_timeseries.ipynb",
      "User-Agent": "Mozilla/5.0 (Macintosh; Intel Mac OS X 10_15_7) AppleWebKit/537.36 (KHTML, like Gecko) Chrome/100.0.4896.79 Safari/537.36"
    }
[E 2022-06-13 19:08:30.672 ServerApp] 500 PUT /api/contents/jupyter_notebooks/paper/1b.Precipitation_timeseries.ipynb?1655143705226 (::1) 5311.49ms referer=http://localhost:8885/lab/tree/jupyter_notebooks/paper/1b.Precipitation_timeseries.ipynb
[I 2022-06-13 19:11:24.824 ServerApp] Saving file at /jupyter_notebooks/paper/1b.Precipitation_timeseries.ipynb
[E 2022-06-13 19:11:29.889 ServerApp] Error while saving file: jupyter_notebooks/paper/1b.Precipitation_timeseries.ipynb database is locked
    Traceback (most recent call last):
      File "/home/k/kimpson/bin/conda/envs/workhorse/lib/python3.7/site-packages/jupyter_server/services/contents/filemanager.py", line 427, in save
      File "/home/k/kimpson/bin/conda/envs/workhorse/lib/python3.7/site-packages/jupyter_server/services/contents/manager.py", line 644, in check_and_sign
      File "/home/k/kimpson/bin/conda/envs/workhorse/lib/python3.7/site-packages/nbformat/sign.py", line 482, in sign
      File "/home/k/kimpson/bin/conda/envs/workhorse/lib/python3.7/site-packages/nbformat/sign.py", line 224, in store_signature
      File "/home/k/kimpson/bin/conda/envs/workhorse/lib/python3.7/site-packages/nbformat/sign.py", line 255, in check_signature
    sqlite3.OperationalError: database is locked
[W 2022-06-13 19:11:29.897 ServerApp] 500 PUT /api/contents/jupyter_notebooks/paper/1b.Precipitation_timeseries.ipynb?1655143884495 (::1): Unexpected error while saving file: jupyter_notebooks/paper/1b.Precipitation_timeseries.ipynb database is locked
[W 2022-06-13 19:11:29.898 ServerApp] Unexpected error while saving file: jupyter_notebooks/paper/1b.Precipitation_timeseries.ipynb database is locked
[E 2022-06-13 19:11:29.899 ServerApp] {
      "Host": "localhost:8885",
      "Accept": "*/*",
      "Referer": "http://localhost:8885/lab/tree/jupyter_notebooks/paper/1b.Precipitation_timeseries.ipynb",
      "User-Agent": "Mozilla/5.0 (Macintosh; Intel Mac OS X 10_15_7) AppleWebKit/537.36 (KHTML, like Gecko) Chrome/100.0.4896.79 Safari/537.36"
    }
[E 2022-06-13 19:11:29.899 ServerApp] 500 PUT /api/contents/jupyter_notebooks/paper/1b.Precipitation_timeseries.ipynb?1655143884495 (::1) 5270.20ms referer=http://localhost:8885/lab/tree/jupyter_notebooks/paper/1b.Precipitation_timeseries.ipynb
[I 2022-06-13 19:13:25.306 ServerApp] Saving file at /jupyter_notebooks/paper/1b.Precipitation_timeseries.ipynb
[E 2022-06-13 19:13:30.371 ServerApp] Error while saving file: jupyter_notebooks/paper/1b.Precipitation_timeseries.ipynb database is locked
    Traceback (most recent call last):
      File "/home/k/kimpson/bin/conda/envs/workhorse/lib/python3.7/site-packages/jupyter_server/services/contents/filemanager.py", line 427, in save
      File "/home/k/kimpson/bin/conda/envs/workhorse/lib/python3.7/site-packages/jupyter_server/services/contents/manager.py", line 644, in check_and_sign
      File "/home/k/kimpson/bin/conda/envs/workhorse/lib/python3.7/site-packages/nbformat/sign.py", line 482, in sign
      File "/home/k/kimpson/bin/conda/envs/workhorse/lib/python3.7/site-packages/nbformat/sign.py", line 224, in store_signature
      File "/home/k/kimpson/bin/conda/envs/workhorse/lib/python3.7/site-packages/nbformat/sign.py", line 255, in check_signature
    sqlite3.OperationalError: database is locked
[W 2022-06-13 19:13:30.380 ServerApp] 500 PUT /api/contents/jupyter_notebooks/paper/1b.Precipitation_timeseries.ipynb?1655144005018 (::1): Unexpected error while saving file: jupyter_notebooks/paper/1b.Precipitation_timeseries.ipynb database is locked
[W 2022-06-13 19:13:30.380 ServerApp] Unexpected error while saving file: jupyter_notebooks/paper/1b.Precipitation_timeseries.ipynb database is locked
[E 2022-06-13 19:13:30.381 ServerApp] {
      "Host": "localhost:8885",
      "Accept": "*/*",
      "Referer": "http://localhost:8885/lab/tree/jupyter_notebooks/paper/1b.Precipitation_timeseries.ipynb",
      "User-Agent": "Mozilla/5.0 (Macintosh; Intel Mac OS X 10_15_7) AppleWebKit/537.36 (KHTML, like Gecko) Chrome/100.0.4896.79 Safari/537.36"
    }
[E 2022-06-13 19:13:30.381 ServerApp] 500 PUT /api/contents/jupyter_notebooks/paper/1b.Precipitation_timeseries.ipynb?1655144005018 (::1) 5248.51ms referer=http://localhost:8885/lab/tree/jupyter_notebooks/paper/1b.Precipitation_timeseries.ipynb
[I 2022-06-13 19:16:25.039 ServerApp] Saving file at /jupyter_notebooks/paper/1b.Precipitation_timeseries.ipynb
[E 2022-06-13 19:16:30.105 ServerApp] Error while saving file: jupyter_notebooks/paper/1b.Precipitation_timeseries.ipynb database is locked
    Traceback (most recent call last):
      File "/home/k/kimpson/bin/conda/envs/workhorse/lib/python3.7/site-packages/jupyter_server/services/contents/filemanager.py", line 427, in save
      File "/home/k/kimpson/bin/conda/envs/workhorse/lib/python3.7/site-packages/jupyter_server/services/contents/manager.py", line 644, in check_and_sign
      File "/home/k/kimpson/bin/conda/envs/workhorse/lib/python3.7/site-packages/nbformat/sign.py", line 482, in sign
      File "/home/k/kimpson/bin/conda/envs/workhorse/lib/python3.7/site-packages/nbformat/sign.py", line 224, in store_signature
      File "/home/k/kimpson/bin/conda/envs/workhorse/lib/python3.7/site-packages/nbformat/sign.py", line 255, in check_signature
    sqlite3.OperationalError: database is locked
[W 2022-06-13 19:16:30.113 ServerApp] 500 PUT /api/contents/jupyter_notebooks/paper/1b.Precipitation_timeseries.ipynb?1655144184746 (::1): Unexpected error while saving file: jupyter_notebooks/paper/1b.Precipitation_timeseries.ipynb database is locked
[W 2022-06-13 19:16:30.114 ServerApp] Unexpected error while saving file: jupyter_notebooks/paper/1b.Precipitation_timeseries.ipynb database is locked
[E 2022-06-13 19:16:30.115 ServerApp] {
      "Host": "localhost:8885",
      "Accept": "*/*",
      "Referer": "http://localhost:8885/lab/tree/jupyter_notebooks/paper/1b.Precipitation_timeseries.ipynb",
      "User-Agent": "Mozilla/5.0 (Macintosh; Intel Mac OS X 10_15_7) AppleWebKit/537.36 (KHTML, like Gecko) Chrome/100.0.4896.79 Safari/537.36"
    }
[E 2022-06-13 19:16:30.115 ServerApp] 500 PUT /api/contents/jupyter_notebooks/paper/1b.Precipitation_timeseries.ipynb?1655144184746 (::1) 5256.64ms referer=http://localhost:8885/lab/tree/jupyter_notebooks/paper/1b.Precipitation_timeseries.ipynb
[I 2022-06-13 19:19:25.518 ServerApp] Saving file at /jupyter_notebooks/paper/1b.Precipitation_timeseries.ipynb
[E 2022-06-13 19:19:30.584 ServerApp] Error while saving file: jupyter_notebooks/paper/1b.Precipitation_timeseries.ipynb database is locked
    Traceback (most recent call last):
      File "/home/k/kimpson/bin/conda/envs/workhorse/lib/python3.7/site-packages/jupyter_server/services/contents/filemanager.py", line 427, in save
      File "/home/k/kimpson/bin/conda/envs/workhorse/lib/python3.7/site-packages/jupyter_server/services/contents/manager.py", line 644, in check_and_sign
      File "/home/k/kimpson/bin/conda/envs/workhorse/lib/python3.7/site-packages/nbformat/sign.py", line 482, in sign
      File "/home/k/kimpson/bin/conda/envs/workhorse/lib/python3.7/site-packages/nbformat/sign.py", line 224, in store_signature
      File "/home/k/kimpson/bin/conda/envs/workhorse/lib/python3.7/site-packages/nbformat/sign.py", line 255, in check_signature
    sqlite3.OperationalError: database is locked
[W 2022-06-13 19:19:30.593 ServerApp] 500 PUT /api/contents/jupyter_notebooks/paper/1b.Precipitation_timeseries.ipynb?1655144365232 (::1): Unexpected error while saving file: jupyter_notebooks/paper/1b.Precipitation_timeseries.ipynb database is locked
[W 2022-06-13 19:19:30.593 ServerApp] Unexpected error while saving file: jupyter_notebooks/paper/1b.Precipitation_timeseries.ipynb database is locked
[E 2022-06-13 19:19:30.594 ServerApp] {
      "Host": "localhost:8885",
      "Accept": "*/*",
      "Referer": "http://localhost:8885/lab/tree/jupyter_notebooks/paper/1b.Precipitation_timeseries.ipynb",
      "User-Agent": "Mozilla/5.0 (Macintosh; Intel Mac OS X 10_15_7) AppleWebKit/537.36 (KHTML, like Gecko) Chrome/100.0.4896.79 Safari/537.36"
    }
[E 2022-06-13 19:19:30.594 ServerApp] 500 PUT /api/contents/jupyter_notebooks/paper/1b.Precipitation_timeseries.ipynb?1655144365232 (::1) 5248.70ms referer=http://localhost:8885/lab/tree/jupyter_notebooks/paper/1b.Precipitation_timeseries.ipynb
[I 2022-06-13 19:22:25.221 ServerApp] Saving file at /jupyter_notebooks/paper/1b.Precipitation_timeseries.ipynb
[E 2022-06-13 19:22:30.287 ServerApp] Error while saving file: jupyter_notebooks/paper/1b.Precipitation_timeseries.ipynb database is locked
    Traceback (most recent call last):
      File "/home/k/kimpson/bin/conda/envs/workhorse/lib/python3.7/site-packages/jupyter_server/services/contents/filemanager.py", line 427, in save
      File "/home/k/kimpson/bin/conda/envs/workhorse/lib/python3.7/site-packages/jupyter_server/services/contents/manager.py", line 644, in check_and_sign
      File "/home/k/kimpson/bin/conda/envs/workhorse/lib/python3.7/site-packages/nbformat/sign.py", line 482, in sign
      File "/home/k/kimpson/bin/conda/envs/workhorse/lib/python3.7/site-packages/nbformat/sign.py", line 224, in store_signature
      File "/home/k/kimpson/bin/conda/envs/workhorse/lib/python3.7/site-packages/nbformat/sign.py", line 255, in check_signature
    sqlite3.OperationalError: database is locked
[W 2022-06-13 19:22:30.295 ServerApp] 500 PUT /api/contents/jupyter_notebooks/paper/1b.Precipitation_timeseries.ipynb?1655144544934 (::1): Unexpected error while saving file: jupyter_notebooks/paper/1b.Precipitation_timeseries.ipynb database is locked
[W 2022-06-13 19:22:30.295 ServerApp] Unexpected error while saving file: jupyter_notebooks/paper/1b.Precipitation_timeseries.ipynb database is locked
[E 2022-06-13 19:22:30.296 ServerApp] {
      "Host": "localhost:8885",
      "Accept": "*/*",
      "Referer": "http://localhost:8885/lab/tree/jupyter_notebooks/paper/1b.Precipitation_timeseries.ipynb",
      "User-Agent": "Mozilla/5.0 (Macintosh; Intel Mac OS X 10_15_7) AppleWebKit/537.36 (KHTML, like Gecko) Chrome/100.0.4896.79 Safari/537.36"
    }
[E 2022-06-13 19:22:30.296 ServerApp] 500 PUT /api/contents/jupyter_notebooks/paper/1b.Precipitation_timeseries.ipynb?1655144544934 (::1) 5248.80ms referer=http://localhost:8885/lab/tree/jupyter_notebooks/paper/1b.Precipitation_timeseries.ipynb
[I 2022-06-13 19:24:25.574 ServerApp] Saving file at /jupyter_notebooks/paper/1b.Precipitation_timeseries.ipynb
[E 2022-06-13 19:24:30.640 ServerApp] Error while saving file: jupyter_notebooks/paper/1b.Precipitation_timeseries.ipynb database is locked
    Traceback (most recent call last):
      File "/home/k/kimpson/bin/conda/envs/workhorse/lib/python3.7/site-packages/jupyter_server/services/contents/filemanager.py", line 427, in save
      File "/home/k/kimpson/bin/conda/envs/workhorse/lib/python3.7/site-packages/jupyter_server/services/contents/manager.py", line 644, in check_and_sign
      File "/home/k/kimpson/bin/conda/envs/workhorse/lib/python3.7/site-packages/nbformat/sign.py", line 482, in sign
      File "/home/k/kimpson/bin/conda/envs/workhorse/lib/python3.7/site-packages/nbformat/sign.py", line 224, in store_signature
      File "/home/k/kimpson/bin/conda/envs/workhorse/lib/python3.7/site-packages/nbformat/sign.py", line 255, in check_signature
    sqlite3.OperationalError: database is locked
[W 2022-06-13 19:24:30.648 ServerApp] 500 PUT /api/contents/jupyter_notebooks/paper/1b.Precipitation_timeseries.ipynb?1655144665153 (::1): Unexpected error while saving file: jupyter_notebooks/paper/1b.Precipitation_timeseries.ipynb database is locked
[W 2022-06-13 19:24:30.648 ServerApp] Unexpected error while saving file: jupyter_notebooks/paper/1b.Precipitation_timeseries.ipynb database is locked
[E 2022-06-13 19:24:30.649 ServerApp] {
      "Host": "localhost:8885",
      "Accept": "*/*",
      "Referer": "http://localhost:8885/lab/tree/jupyter_notebooks/paper/1b.Precipitation_timeseries.ipynb",
      "User-Agent": "Mozilla/5.0 (Macintosh; Intel Mac OS X 10_15_7) AppleWebKit/537.36 (KHTML, like Gecko) Chrome/100.0.4896.79 Safari/537.36"
    }
[E 2022-06-13 19:24:30.649 ServerApp] 500 PUT /api/contents/jupyter_notebooks/paper/1b.Precipitation_timeseries.ipynb?1655144665153 (::1) 5377.14ms referer=http://localhost:8885/lab/tree/jupyter_notebooks/paper/1b.Precipitation_timeseries.ipynb
[I 2022-06-13 19:27:25.129 ServerApp] Saving file at /jupyter_notebooks/paper/1b.Precipitation_timeseries.ipynb
[E 2022-06-13 19:27:30.197 ServerApp] Error while saving file: jupyter_notebooks/paper/1b.Precipitation_timeseries.ipynb database is locked
    Traceback (most recent call last):
      File "/home/k/kimpson/bin/conda/envs/workhorse/lib/python3.7/site-packages/jupyter_server/services/contents/filemanager.py", line 427, in save
      File "/home/k/kimpson/bin/conda/envs/workhorse/lib/python3.7/site-packages/jupyter_server/services/contents/manager.py", line 644, in check_and_sign
      File "/home/k/kimpson/bin/conda/envs/workhorse/lib/python3.7/site-packages/nbformat/sign.py", line 482, in sign
      File "/home/k/kimpson/bin/conda/envs/workhorse/lib/python3.7/site-packages/nbformat/sign.py", line 224, in store_signature
      File "/home/k/kimpson/bin/conda/envs/workhorse/lib/python3.7/site-packages/nbformat/sign.py", line 255, in check_signature
    sqlite3.OperationalError: database is locked
[W 2022-06-13 19:27:30.205 ServerApp] 500 PUT /api/contents/jupyter_notebooks/paper/1b.Precipitation_timeseries.ipynb?1655144844839 (::1): Unexpected error while saving file: jupyter_notebooks/paper/1b.Precipitation_timeseries.ipynb database is locked
[W 2022-06-13 19:27:30.205 ServerApp] Unexpected error while saving file: jupyter_notebooks/paper/1b.Precipitation_timeseries.ipynb database is locked
[E 2022-06-13 19:27:30.206 ServerApp] {
      "Host": "localhost:8885",
      "Accept": "*/*",
      "Referer": "http://localhost:8885/lab/tree/jupyter_notebooks/paper/1b.Precipitation_timeseries.ipynb",
      "User-Agent": "Mozilla/5.0 (Macintosh; Intel Mac OS X 10_15_7) AppleWebKit/537.36 (KHTML, like Gecko) Chrome/100.0.4896.79 Safari/537.36"
    }
[E 2022-06-13 19:27:30.206 ServerApp] 500 PUT /api/contents/jupyter_notebooks/paper/1b.Precipitation_timeseries.ipynb?1655144844839 (::1) 5251.14ms referer=http://localhost:8885/lab/tree/jupyter_notebooks/paper/1b.Precipitation_timeseries.ipynb
[I 2022-06-13 19:30:25.484 ServerApp] Saving file at /jupyter_notebooks/paper/1b.Precipitation_timeseries.ipynb
[E 2022-06-13 19:30:30.550 ServerApp] Error while saving file: jupyter_notebooks/paper/1b.Precipitation_timeseries.ipynb database is locked
    Traceback (most recent call last):
      File "/home/k/kimpson/bin/conda/envs/workhorse/lib/python3.7/site-packages/jupyter_server/services/contents/filemanager.py", line 427, in save
      File "/home/k/kimpson/bin/conda/envs/workhorse/lib/python3.7/site-packages/jupyter_server/services/contents/manager.py", line 644, in check_and_sign
      File "/home/k/kimpson/bin/conda/envs/workhorse/lib/python3.7/site-packages/nbformat/sign.py", line 482, in sign
      File "/home/k/kimpson/bin/conda/envs/workhorse/lib/python3.7/site-packages/nbformat/sign.py", line 224, in store_signature
      File "/home/k/kimpson/bin/conda/envs/workhorse/lib/python3.7/site-packages/nbformat/sign.py", line 255, in check_signature
    sqlite3.OperationalError: database is locked
[W 2022-06-13 19:30:30.558 ServerApp] 500 PUT /api/contents/jupyter_notebooks/paper/1b.Precipitation_timeseries.ipynb?1655145025185 (::1): Unexpected error while saving file: jupyter_notebooks/paper/1b.Precipitation_timeseries.ipynb database is locked
[W 2022-06-13 19:30:30.558 ServerApp] Unexpected error while saving file: jupyter_notebooks/paper/1b.Precipitation_timeseries.ipynb database is locked
[E 2022-06-13 19:30:30.559 ServerApp] {
      "Host": "localhost:8885",
      "Accept": "*/*",
      "Referer": "http://localhost:8885/lab/tree/jupyter_notebooks/paper/1b.Precipitation_timeseries.ipynb",
      "User-Agent": "Mozilla/5.0 (Macintosh; Intel Mac OS X 10_15_7) AppleWebKit/537.36 (KHTML, like Gecko) Chrome/100.0.4896.79 Safari/537.36"
    }
[E 2022-06-13 19:30:30.559 ServerApp] 500 PUT /api/contents/jupyter_notebooks/paper/1b.Precipitation_timeseries.ipynb?1655145025185 (::1) 5294.97ms referer=http://localhost:8885/lab/tree/jupyter_notebooks/paper/1b.Precipitation_timeseries.ipynb
[I 2022-06-13 19:33:25.185 ServerApp] Saving file at /jupyter_notebooks/paper/1b.Precipitation_timeseries.ipynb
[E 2022-06-13 19:33:30.252 ServerApp] Error while saving file: jupyter_notebooks/paper/1b.Precipitation_timeseries.ipynb database is locked
    Traceback (most recent call last):
      File "/home/k/kimpson/bin/conda/envs/workhorse/lib/python3.7/site-packages/jupyter_server/services/contents/filemanager.py", line 427, in save
      File "/home/k/kimpson/bin/conda/envs/workhorse/lib/python3.7/site-packages/jupyter_server/services/contents/manager.py", line 644, in check_and_sign
      File "/home/k/kimpson/bin/conda/envs/workhorse/lib/python3.7/site-packages/nbformat/sign.py", line 482, in sign
      File "/home/k/kimpson/bin/conda/envs/workhorse/lib/python3.7/site-packages/nbformat/sign.py", line 224, in store_signature
      File "/home/k/kimpson/bin/conda/envs/workhorse/lib/python3.7/site-packages/nbformat/sign.py", line 255, in check_signature
    sqlite3.OperationalError: database is locked
[W 2022-06-13 19:33:30.260 ServerApp] 500 PUT /api/contents/jupyter_notebooks/paper/1b.Precipitation_timeseries.ipynb?1655145204896 (::1): Unexpected error while saving file: jupyter_notebooks/paper/1b.Precipitation_timeseries.ipynb database is locked
[W 2022-06-13 19:33:30.260 ServerApp] Unexpected error while saving file: jupyter_notebooks/paper/1b.Precipitation_timeseries.ipynb database is locked
[E 2022-06-13 19:33:30.261 ServerApp] {
      "Host": "localhost:8885",
      "Accept": "*/*",
      "Referer": "http://localhost:8885/lab/tree/jupyter_notebooks/paper/1b.Precipitation_timeseries.ipynb",
      "User-Agent": "Mozilla/5.0 (Macintosh; Intel Mac OS X 10_15_7) AppleWebKit/537.36 (KHTML, like Gecko) Chrome/100.0.4896.79 Safari/537.36"
    }
[E 2022-06-13 19:33:30.261 ServerApp] 500 PUT /api/contents/jupyter_notebooks/paper/1b.Precipitation_timeseries.ipynb?1655145204896 (::1) 5249.75ms referer=http://localhost:8885/lab/tree/jupyter_notebooks/paper/1b.Precipitation_timeseries.ipynb
[I 2022-06-13 19:36:35.119 ServerApp] Saving file at /jupyter_notebooks/paper/1b.Precipitation_timeseries.ipynb
[E 2022-06-13 19:36:40.188 ServerApp] Error while saving file: jupyter_notebooks/paper/1b.Precipitation_timeseries.ipynb database is locked
    Traceback (most recent call last):
      File "/home/k/kimpson/bin/conda/envs/workhorse/lib/python3.7/site-packages/jupyter_server/services/contents/filemanager.py", line 427, in save
      File "/home/k/kimpson/bin/conda/envs/workhorse/lib/python3.7/site-packages/jupyter_server/services/contents/manager.py", line 644, in check_and_sign
      File "/home/k/kimpson/bin/conda/envs/workhorse/lib/python3.7/site-packages/nbformat/sign.py", line 482, in sign
      File "/home/k/kimpson/bin/conda/envs/workhorse/lib/python3.7/site-packages/nbformat/sign.py", line 224, in store_signature
      File "/home/k/kimpson/bin/conda/envs/workhorse/lib/python3.7/site-packages/nbformat/sign.py", line 255, in check_signature
    sqlite3.OperationalError: database is locked
[W 2022-06-13 19:36:40.196 ServerApp] 500 PUT /api/contents/jupyter_notebooks/paper/1b.Precipitation_timeseries.ipynb?1655145394796 (::1): Unexpected error while saving file: jupyter_notebooks/paper/1b.Precipitation_timeseries.ipynb database is locked
[W 2022-06-13 19:36:40.196 ServerApp] Unexpected error while saving file: jupyter_notebooks/paper/1b.Precipitation_timeseries.ipynb database is locked
[E 2022-06-13 19:36:40.197 ServerApp] {
      "Host": "localhost:8885",
      "Accept": "*/*",
      "Referer": "http://localhost:8885/lab/tree/jupyter_notebooks/paper/1b.Precipitation_timeseries.ipynb",
      "User-Agent": "Mozilla/5.0 (Macintosh; Intel Mac OS X 10_15_7) AppleWebKit/537.36 (KHTML, like Gecko) Chrome/100.0.4896.79 Safari/537.36"
    }
[E 2022-06-13 19:36:40.197 ServerApp] 500 PUT /api/contents/jupyter_notebooks/paper/1b.Precipitation_timeseries.ipynb?1655145394796 (::1) 5250.92ms referer=http://localhost:8885/lab/tree/jupyter_notebooks/paper/1b.Precipitation_timeseries.ipynb
[I 2022-06-13 19:39:31.816 ServerApp] Saving file at /jupyter_notebooks/paper/1b.Precipitation_timeseries.ipynb
[E 2022-06-13 19:39:36.883 ServerApp] Error while saving file: jupyter_notebooks/paper/1b.Precipitation_timeseries.ipynb database is locked
    Traceback (most recent call last):
      File "/home/k/kimpson/bin/conda/envs/workhorse/lib/python3.7/site-packages/jupyter_server/services/contents/filemanager.py", line 427, in save
      File "/home/k/kimpson/bin/conda/envs/workhorse/lib/python3.7/site-packages/jupyter_server/services/contents/manager.py", line 644, in check_and_sign
      File "/home/k/kimpson/bin/conda/envs/workhorse/lib/python3.7/site-packages/nbformat/sign.py", line 482, in sign
      File "/home/k/kimpson/bin/conda/envs/workhorse/lib/python3.7/site-packages/nbformat/sign.py", line 224, in store_signature
      File "/home/k/kimpson/bin/conda/envs/workhorse/lib/python3.7/site-packages/nbformat/sign.py", line 255, in check_signature
    sqlite3.OperationalError: database is locked
[W 2022-06-13 19:39:36.891 ServerApp] 500 PUT /api/contents/jupyter_notebooks/paper/1b.Precipitation_timeseries.ipynb?1655145571527 (::1): Unexpected error while saving file: jupyter_notebooks/paper/1b.Precipitation_timeseries.ipynb database is locked
[W 2022-06-13 19:39:36.891 ServerApp] Unexpected error while saving file: jupyter_notebooks/paper/1b.Precipitation_timeseries.ipynb database is locked
[E 2022-06-13 19:39:36.892 ServerApp] {
      "Host": "localhost:8885",
      "Accept": "*/*",
      "Referer": "http://localhost:8885/lab/tree/jupyter_notebooks/paper/1b.Precipitation_timeseries.ipynb",
      "User-Agent": "Mozilla/5.0 (Macintosh; Intel Mac OS X 10_15_7) AppleWebKit/537.36 (KHTML, like Gecko) Chrome/100.0.4896.79 Safari/537.36"
    }
[E 2022-06-13 19:39:36.892 ServerApp] 500 PUT /api/contents/jupyter_notebooks/paper/1b.Precipitation_timeseries.ipynb?1655145571527 (::1) 5247.55ms referer=http://localhost:8885/lab/tree/jupyter_notebooks/paper/1b.Precipitation_timeseries.ipynb
[I 2022-06-13 19:42:25.259 ServerApp] Saving file at /jupyter_notebooks/paper/1b.Precipitation_timeseries.ipynb
[E 2022-06-13 19:42:30.327 ServerApp] Error while saving file: jupyter_notebooks/paper/1b.Precipitation_timeseries.ipynb database is locked
    Traceback (most recent call last):
      File "/home/k/kimpson/bin/conda/envs/workhorse/lib/python3.7/site-packages/jupyter_server/services/contents/filemanager.py", line 427, in save
      File "/home/k/kimpson/bin/conda/envs/workhorse/lib/python3.7/site-packages/jupyter_server/services/contents/manager.py", line 644, in check_and_sign
      File "/home/k/kimpson/bin/conda/envs/workhorse/lib/python3.7/site-packages/nbformat/sign.py", line 482, in sign
      File "/home/k/kimpson/bin/conda/envs/workhorse/lib/python3.7/site-packages/nbformat/sign.py", line 224, in store_signature
      File "/home/k/kimpson/bin/conda/envs/workhorse/lib/python3.7/site-packages/nbformat/sign.py", line 255, in check_signature
    sqlite3.OperationalError: database is locked
[W 2022-06-13 19:42:30.336 ServerApp] 500 PUT /api/contents/jupyter_notebooks/paper/1b.Precipitation_timeseries.ipynb?1655145744881 (::1): Unexpected error while saving file: jupyter_notebooks/paper/1b.Precipitation_timeseries.ipynb database is locked
[W 2022-06-13 19:42:30.337 ServerApp] Unexpected error while saving file: jupyter_notebooks/paper/1b.Precipitation_timeseries.ipynb database is locked
[E 2022-06-13 19:42:30.338 ServerApp] {
      "Host": "localhost:8885",
      "Accept": "*/*",
      "Referer": "http://localhost:8885/lab/tree/jupyter_notebooks/paper/1b.Precipitation_timeseries.ipynb",
      "User-Agent": "Mozilla/5.0 (Macintosh; Intel Mac OS X 10_15_7) AppleWebKit/537.36 (KHTML, like Gecko) Chrome/100.0.4896.79 Safari/537.36"
    }
[E 2022-06-13 19:42:30.338 ServerApp] 500 PUT /api/contents/jupyter_notebooks/paper/1b.Precipitation_timeseries.ipynb?1655145744881 (::1) 5318.35ms referer=http://localhost:8885/lab/tree/jupyter_notebooks/paper/1b.Precipitation_timeseries.ipynb
[I 2022-06-13 19:45:08.412 ServerApp] Saving file at /jupyter_notebooks/paper/1b.Precipitation_timeseries.ipynb
[E 2022-06-13 19:45:13.478 ServerApp] Error while saving file: jupyter_notebooks/paper/1b.Precipitation_timeseries.ipynb database is locked
    Traceback (most recent call last):
      File "/home/k/kimpson/bin/conda/envs/workhorse/lib/python3.7/site-packages/jupyter_server/services/contents/filemanager.py", line 427, in save
      File "/home/k/kimpson/bin/conda/envs/workhorse/lib/python3.7/site-packages/jupyter_server/services/contents/manager.py", line 644, in check_and_sign
      File "/home/k/kimpson/bin/conda/envs/workhorse/lib/python3.7/site-packages/nbformat/sign.py", line 482, in sign
      File "/home/k/kimpson/bin/conda/envs/workhorse/lib/python3.7/site-packages/nbformat/sign.py", line 224, in store_signature
      File "/home/k/kimpson/bin/conda/envs/workhorse/lib/python3.7/site-packages/nbformat/sign.py", line 255, in check_signature
    sqlite3.OperationalError: database is locked
[W 2022-06-13 19:45:13.486 ServerApp] 500 PUT /api/contents/jupyter_notebooks/paper/1b.Precipitation_timeseries.ipynb?1655145908111 (::1): Unexpected error while saving file: jupyter_notebooks/paper/1b.Precipitation_timeseries.ipynb database is locked
[W 2022-06-13 19:45:13.487 ServerApp] Unexpected error while saving file: jupyter_notebooks/paper/1b.Precipitation_timeseries.ipynb database is locked
[E 2022-06-13 19:45:13.487 ServerApp] {
      "Host": "localhost:8885",
      "Accept": "*/*",
      "Referer": "http://localhost:8885/lab/tree/jupyter_notebooks/paper/1b.Precipitation_timeseries.ipynb",
      "User-Agent": "Mozilla/5.0 (Macintosh; Intel Mac OS X 10_15_7) AppleWebKit/537.36 (KHTML, like Gecko) Chrome/100.0.4896.79 Safari/537.36"
    }
[E 2022-06-13 19:45:13.487 ServerApp] 500 PUT /api/contents/jupyter_notebooks/paper/1b.Precipitation_timeseries.ipynb?1655145908111 (::1) 5248.21ms referer=http://localhost:8885/lab/tree/jupyter_notebooks/paper/1b.Precipitation_timeseries.ipynb
[I 2022-06-13 19:47:08.315 ServerApp] Saving file at /jupyter_notebooks/paper/1b.Precipitation_timeseries.ipynb
[E 2022-06-13 19:47:13.381 ServerApp] Error while saving file: jupyter_notebooks/paper/1b.Precipitation_timeseries.ipynb database is locked
    Traceback (most recent call last):
      File "/home/k/kimpson/bin/conda/envs/workhorse/lib/python3.7/site-packages/jupyter_server/services/contents/filemanager.py", line 427, in save
      File "/home/k/kimpson/bin/conda/envs/workhorse/lib/python3.7/site-packages/jupyter_server/services/contents/manager.py", line 644, in check_and_sign
      File "/home/k/kimpson/bin/conda/envs/workhorse/lib/python3.7/site-packages/nbformat/sign.py", line 482, in sign
      File "/home/k/kimpson/bin/conda/envs/workhorse/lib/python3.7/site-packages/nbformat/sign.py", line 224, in store_signature
      File "/home/k/kimpson/bin/conda/envs/workhorse/lib/python3.7/site-packages/nbformat/sign.py", line 255, in check_signature
    sqlite3.OperationalError: database is locked
[W 2022-06-13 19:47:13.390 ServerApp] 500 PUT /api/contents/jupyter_notebooks/paper/1b.Precipitation_timeseries.ipynb?1655146028019 (::1): Unexpected error while saving file: jupyter_notebooks/paper/1b.Precipitation_timeseries.ipynb database is locked
[W 2022-06-13 19:47:13.390 ServerApp] Unexpected error while saving file: jupyter_notebooks/paper/1b.Precipitation_timeseries.ipynb database is locked
[E 2022-06-13 19:47:13.392 ServerApp] {
      "Host": "localhost:8885",
      "Accept": "*/*",
      "Referer": "http://localhost:8885/lab/tree/jupyter_notebooks/paper/1b.Precipitation_timeseries.ipynb",
      "User-Agent": "Mozilla/5.0 (Macintosh; Intel Mac OS X 10_15_7) AppleWebKit/537.36 (KHTML, like Gecko) Chrome/100.0.4896.79 Safari/537.36"
    }
[E 2022-06-13 19:47:13.393 ServerApp] 500 PUT /api/contents/jupyter_notebooks/paper/1b.Precipitation_timeseries.ipynb?1655146028019 (::1) 5248.30ms referer=http://localhost:8885/lab/tree/jupyter_notebooks/paper/1b.Precipitation_timeseries.ipynb
[I 2022-06-13 19:49:08.507 ServerApp] Saving file at /jupyter_notebooks/paper/1b.Precipitation_timeseries.ipynb
[E 2022-06-13 19:49:13.575 ServerApp] Error while saving file: jupyter_notebooks/paper/1b.Precipitation_timeseries.ipynb database is locked
    Traceback (most recent call last):
      File "/home/k/kimpson/bin/conda/envs/workhorse/lib/python3.7/site-packages/jupyter_server/services/contents/filemanager.py", line 427, in save
      File "/home/k/kimpson/bin/conda/envs/workhorse/lib/python3.7/site-packages/jupyter_server/services/contents/manager.py", line 644, in check_and_sign
      File "/home/k/kimpson/bin/conda/envs/workhorse/lib/python3.7/site-packages/nbformat/sign.py", line 482, in sign
      File "/home/k/kimpson/bin/conda/envs/workhorse/lib/python3.7/site-packages/nbformat/sign.py", line 224, in store_signature
      File "/home/k/kimpson/bin/conda/envs/workhorse/lib/python3.7/site-packages/nbformat/sign.py", line 255, in check_signature
    sqlite3.OperationalError: database is locked
[W 2022-06-13 19:49:13.583 ServerApp] 500 PUT /api/contents/jupyter_notebooks/paper/1b.Precipitation_timeseries.ipynb?1655146148213 (::1): Unexpected error while saving file: jupyter_notebooks/paper/1b.Precipitation_timeseries.ipynb database is locked
[W 2022-06-13 19:49:13.584 ServerApp] Unexpected error while saving file: jupyter_notebooks/paper/1b.Precipitation_timeseries.ipynb database is locked
[E 2022-06-13 19:49:13.585 ServerApp] {
      "Host": "localhost:8885",
      "Accept": "*/*",
      "Referer": "http://localhost:8885/lab/tree/jupyter_notebooks/paper/1b.Precipitation_timeseries.ipynb",
      "User-Agent": "Mozilla/5.0 (Macintosh; Intel Mac OS X 10_15_7) AppleWebKit/537.36 (KHTML, like Gecko) Chrome/100.0.4896.79 Safari/537.36"
    }
[E 2022-06-13 19:49:13.585 ServerApp] 500 PUT /api/contents/jupyter_notebooks/paper/1b.Precipitation_timeseries.ipynb?1655146148213 (::1) 5249.91ms referer=http://localhost:8885/lab/tree/jupyter_notebooks/paper/1b.Precipitation_timeseries.ipynb
[I 2022-06-13 19:51:08.428 ServerApp] Saving file at /jupyter_notebooks/paper/1b.Precipitation_timeseries.ipynb
[E 2022-06-13 19:51:13.495 ServerApp] Error while saving file: jupyter_notebooks/paper/1b.Precipitation_timeseries.ipynb database is locked
    Traceback (most recent call last):
      File "/home/k/kimpson/bin/conda/envs/workhorse/lib/python3.7/site-packages/jupyter_server/services/contents/filemanager.py", line 427, in save
      File "/home/k/kimpson/bin/conda/envs/workhorse/lib/python3.7/site-packages/jupyter_server/services/contents/manager.py", line 644, in check_and_sign
      File "/home/k/kimpson/bin/conda/envs/workhorse/lib/python3.7/site-packages/nbformat/sign.py", line 482, in sign
      File "/home/k/kimpson/bin/conda/envs/workhorse/lib/python3.7/site-packages/nbformat/sign.py", line 224, in store_signature
      File "/home/k/kimpson/bin/conda/envs/workhorse/lib/python3.7/site-packages/nbformat/sign.py", line 255, in check_signature
    sqlite3.OperationalError: database is locked
[W 2022-06-13 19:51:13.504 ServerApp] 500 PUT /api/contents/jupyter_notebooks/paper/1b.Precipitation_timeseries.ipynb?1655146268121 (::1): Unexpected error while saving file: jupyter_notebooks/paper/1b.Precipitation_timeseries.ipynb database is locked
[W 2022-06-13 19:51:13.504 ServerApp] Unexpected error while saving file: jupyter_notebooks/paper/1b.Precipitation_timeseries.ipynb database is locked
[E 2022-06-13 19:51:13.505 ServerApp] {
      "Host": "localhost:8885",
      "Accept": "*/*",
      "Referer": "http://localhost:8885/lab/tree/jupyter_notebooks/paper/1b.Precipitation_timeseries.ipynb",
      "User-Agent": "Mozilla/5.0 (Macintosh; Intel Mac OS X 10_15_7) AppleWebKit/537.36 (KHTML, like Gecko) Chrome/100.0.4896.79 Safari/537.36"
    }
[E 2022-06-13 19:51:13.505 ServerApp] 500 PUT /api/contents/jupyter_notebooks/paper/1b.Precipitation_timeseries.ipynb?1655146268121 (::1) 5285.27ms referer=http://localhost:8885/lab/tree/jupyter_notebooks/paper/1b.Precipitation_timeseries.ipynb
[I 2022-06-13 19:53:08.611 ServerApp] Saving file at /jupyter_notebooks/paper/1b.Precipitation_timeseries.ipynb
[E 2022-06-13 19:53:13.679 ServerApp] Error while saving file: jupyter_notebooks/paper/1b.Precipitation_timeseries.ipynb database is locked
    Traceback (most recent call last):
      File "/home/k/kimpson/bin/conda/envs/workhorse/lib/python3.7/site-packages/jupyter_server/services/contents/filemanager.py", line 427, in save
      File "/home/k/kimpson/bin/conda/envs/workhorse/lib/python3.7/site-packages/jupyter_server/services/contents/manager.py", line 644, in check_and_sign
      File "/home/k/kimpson/bin/conda/envs/workhorse/lib/python3.7/site-packages/nbformat/sign.py", line 482, in sign
      File "/home/k/kimpson/bin/conda/envs/workhorse/lib/python3.7/site-packages/nbformat/sign.py", line 224, in store_signature
      File "/home/k/kimpson/bin/conda/envs/workhorse/lib/python3.7/site-packages/nbformat/sign.py", line 255, in check_signature
    sqlite3.OperationalError: database is locked
[W 2022-06-13 19:53:13.689 ServerApp] 500 PUT /api/contents/jupyter_notebooks/paper/1b.Precipitation_timeseries.ipynb?1655146388043 (::1): Unexpected error while saving file: jupyter_notebooks/paper/1b.Precipitation_timeseries.ipynb database is locked
[W 2022-06-13 19:53:13.689 ServerApp] Unexpected error while saving file: jupyter_notebooks/paper/1b.Precipitation_timeseries.ipynb database is locked
[E 2022-06-13 19:53:13.690 ServerApp] {
      "Host": "localhost:8885",
      "Accept": "*/*",
      "Referer": "http://localhost:8885/lab/tree/jupyter_notebooks/paper/1b.Precipitation_timeseries.ipynb",
      "User-Agent": "Mozilla/5.0 (Macintosh; Intel Mac OS X 10_15_7) AppleWebKit/537.36 (KHTML, like Gecko) Chrome/100.0.4896.79 Safari/537.36"
    }
[E 2022-06-13 19:53:13.690 ServerApp] 500 PUT /api/contents/jupyter_notebooks/paper/1b.Precipitation_timeseries.ipynb?1655146388043 (::1) 5295.06ms referer=http://localhost:8885/lab/tree/jupyter_notebooks/paper/1b.Precipitation_timeseries.ipynb
