[I 2022-06-14 09:36:16.796 ServerApp] jupyterlab | extension was successfully linked.
[I 2022-06-14 09:36:16.827 ServerApp] nbclassic | extension was successfully linked.
[I 2022-06-14 09:36:22.623 ServerApp] notebook_shim | extension was successfully linked.
[I 2022-06-14 09:36:22.624 ServerApp] panel.io.jupyter_server_extension | extension was successfully linked.
[I 2022-06-14 09:36:22.941 ServerApp] notebook_shim | extension was successfully loaded.
[I 2022-06-14 09:36:22.944 LabApp] JupyterLab extension loaded from /home/k/kimpson/bin/conda/envs/workhorse/lib/python3.7/site-packages/jupyterlab
[I 2022-06-14 09:36:22.944 LabApp] JupyterLab application directory is /home/k/kimpson/bin/conda/envs/workhorse/share/jupyter/lab
[I 2022-06-14 09:36:22.958 ServerApp] jupyterlab | extension was successfully loaded.
[I 2022-06-14 09:36:23.042 ServerApp] nbclassic | extension was successfully loaded.
[I 2022-06-14 09:36:23.048 ServerApp] panel.io.jupyter_server_extension | extension was successfully loaded.
[I 2022-06-14 09:36:23.050 ServerApp] Serving notebooks from local directory: /gf3/predict2/TIP020_KIMPSON_SPML4L/speedy-1
[I 2022-06-14 09:36:23.050 ServerApp] Jupyter Server 1.15.6 is running at:
[I 2022-06-14 09:36:23.051 ServerApp] http://localhost:9168/lab
[I 2022-06-14 09:36:23.051 ServerApp]  or http://127.0.0.1:9168/lab
[I 2022-06-14 09:36:23.051 ServerApp] Use Control-C to stop this server and shut down all kernels (twice to skip confirmation).
[W 2022-06-14 09:36:23.312 ServerApp] 404 GET /api/kernels/d78a54fc-b9cc-4a8b-b05c-0548884240c5?1655195783030 (::1): Kernel does not exist: d78a54fc-b9cc-4a8b-b05c-0548884240c5
[W 2022-06-14 09:36:23.313 ServerApp] Kernel does not exist: d78a54fc-b9cc-4a8b-b05c-0548884240c5
[W 2022-06-14 09:36:23.314 ServerApp] 404 GET /api/kernels/d78a54fc-b9cc-4a8b-b05c-0548884240c5?1655195783030 (::1) 4.91ms referer=http://localhost:8885/lab/tree/jupyter_notebooks/paper/1b.Precipitation_timeseries.ipynb
[W 2022-06-14 09:36:24.216 ServerApp] 404 GET /api/kernels/d78a54fc-b9cc-4a8b-b05c-0548884240c5/channels?session_id=656fd1e3-868d-4a92-8062-60eb8624fa7b (::1): Kernel does not exist: d78a54fc-b9cc-4a8b-b05c-0548884240c5
[W 2022-06-14 09:36:24.274 ServerApp] 404 GET /api/kernels/d78a54fc-b9cc-4a8b-b05c-0548884240c5/channels?session_id=656fd1e3-868d-4a92-8062-60eb8624fa7b (::1) 62.01ms referer=None
[W 2022-06-14 09:36:24.363 ServerApp] 404 GET /api/kernels/d78a54fc-b9cc-4a8b-b05c-0548884240c5?1655195784187 (::1): Kernel does not exist: d78a54fc-b9cc-4a8b-b05c-0548884240c5
[W 2022-06-14 09:36:24.363 ServerApp] Kernel does not exist: d78a54fc-b9cc-4a8b-b05c-0548884240c5
[W 2022-06-14 09:36:24.364 ServerApp] 404 GET /api/kernels/d78a54fc-b9cc-4a8b-b05c-0548884240c5?1655195784187 (::1) 2.99ms referer=http://localhost:8885/lab/tree/jupyter_notebooks/paper/1b.Precipitation_timeseries.ipynb
[W 2022-06-14 09:36:27.110 ServerApp] 404 GET /api/kernels/aa43cd0c-abf8-4204-a364-b72d795cd894?1655195786787 (::1): Kernel does not exist: aa43cd0c-abf8-4204-a364-b72d795cd894
[W 2022-06-14 09:36:27.111 ServerApp] Kernel does not exist: aa43cd0c-abf8-4204-a364-b72d795cd894
[W 2022-06-14 09:36:27.112 ServerApp] 404 GET /api/kernels/aa43cd0c-abf8-4204-a364-b72d795cd894?1655195786787 (::1) 3.39ms referer=http://localhost:8885/lab/tree/jupyter_notebooks/paper/1b.Precipitation_timeseries.ipynb
[W 2022-06-14 09:36:27.131 ServerApp] 404 GET /api/kernels/d78a54fc-b9cc-4a8b-b05c-0548884240c5/channels?session_id=656fd1e3-868d-4a92-8062-60eb8624fa7b (::1): Kernel does not exist: d78a54fc-b9cc-4a8b-b05c-0548884240c5
[W 2022-06-14 09:36:27.133 ServerApp] 404 GET /api/kernels/d78a54fc-b9cc-4a8b-b05c-0548884240c5/channels?session_id=656fd1e3-868d-4a92-8062-60eb8624fa7b (::1) 6.25ms referer=None
[W 2022-06-14 09:36:27.163 ServerApp] 404 GET /api/kernels/d78a54fc-b9cc-4a8b-b05c-0548884240c5?1655195786989 (::1): Kernel does not exist: d78a54fc-b9cc-4a8b-b05c-0548884240c5
[W 2022-06-14 09:36:27.164 ServerApp] Kernel does not exist: d78a54fc-b9cc-4a8b-b05c-0548884240c5
[W 2022-06-14 09:36:27.164 ServerApp] 404 GET /api/kernels/d78a54fc-b9cc-4a8b-b05c-0548884240c5?1655195786989 (::1) 2.11ms referer=http://localhost:8885/lab/tree/jupyter_notebooks/paper/1b.Precipitation_timeseries.ipynb
[W 2022-06-14 09:36:28.181 ServerApp] 404 GET /api/kernels/aa43cd0c-abf8-4204-a364-b72d795cd894/channels?session_id=5a7b8783-a5b3-4dfb-a9d4-c4bcffba341a (::1): Kernel does not exist: aa43cd0c-abf8-4204-a364-b72d795cd894
[W 2022-06-14 09:36:28.183 ServerApp] 404 GET /api/kernels/aa43cd0c-abf8-4204-a364-b72d795cd894/channels?session_id=5a7b8783-a5b3-4dfb-a9d4-c4bcffba341a (::1) 6.91ms referer=None
[W 2022-06-14 09:36:28.206 ServerApp] 404 GET /api/kernels/aa43cd0c-abf8-4204-a364-b72d795cd894?1655195788032 (::1): Kernel does not exist: aa43cd0c-abf8-4204-a364-b72d795cd894
[W 2022-06-14 09:36:28.207 ServerApp] Kernel does not exist: aa43cd0c-abf8-4204-a364-b72d795cd894
[W 2022-06-14 09:36:28.208 ServerApp] 404 GET /api/kernels/aa43cd0c-abf8-4204-a364-b72d795cd894?1655195788032 (::1) 2.81ms referer=http://localhost:8885/lab/tree/jupyter_notebooks/paper/1b.Precipitation_timeseries.ipynb
[W 2022-06-14 09:36:29.270 ServerApp] 404 GET /api/kernels/aa43cd0c-abf8-4204-a364-b72d795cd894/channels?session_id=5a7b8783-a5b3-4dfb-a9d4-c4bcffba341a (::1): Kernel does not exist: aa43cd0c-abf8-4204-a364-b72d795cd894
[W 2022-06-14 09:36:29.273 ServerApp] 404 GET /api/kernels/aa43cd0c-abf8-4204-a364-b72d795cd894/channels?session_id=5a7b8783-a5b3-4dfb-a9d4-c4bcffba341a (::1) 6.44ms referer=None
[W 2022-06-14 09:36:29.297 ServerApp] 404 GET /api/kernels/aa43cd0c-abf8-4204-a364-b72d795cd894?1655195789122 (::1): Kernel does not exist: aa43cd0c-abf8-4204-a364-b72d795cd894
[W 2022-06-14 09:36:29.298 ServerApp] Kernel does not exist: aa43cd0c-abf8-4204-a364-b72d795cd894
[W 2022-06-14 09:36:29.299 ServerApp] 404 GET /api/kernels/aa43cd0c-abf8-4204-a364-b72d795cd894?1655195789122 (::1) 2.85ms referer=http://localhost:8885/lab/tree/jupyter_notebooks/paper/1b.Precipitation_timeseries.ipynb
[W 2022-06-14 09:36:31.725 ServerApp] 404 GET /api/kernels/d78a54fc-b9cc-4a8b-b05c-0548884240c5/channels?session_id=656fd1e3-868d-4a92-8062-60eb8624fa7b (::1): Kernel does not exist: d78a54fc-b9cc-4a8b-b05c-0548884240c5
[W 2022-06-14 09:36:31.728 ServerApp] 404 GET /api/kernels/d78a54fc-b9cc-4a8b-b05c-0548884240c5/channels?session_id=656fd1e3-868d-4a92-8062-60eb8624fa7b (::1) 6.26ms referer=None
[W 2022-06-14 09:36:31.753 ServerApp] 404 GET /api/kernels/d78a54fc-b9cc-4a8b-b05c-0548884240c5?1655195791578 (::1): Kernel does not exist: d78a54fc-b9cc-4a8b-b05c-0548884240c5
[W 2022-06-14 09:36:31.754 ServerApp] Kernel does not exist: d78a54fc-b9cc-4a8b-b05c-0548884240c5
[W 2022-06-14 09:36:31.755 ServerApp] 404 GET /api/kernels/d78a54fc-b9cc-4a8b-b05c-0548884240c5?1655195791578 (::1) 2.39ms referer=http://localhost:8885/lab/tree/jupyter_notebooks/paper/1b.Precipitation_timeseries.ipynb
[W 2022-06-14 09:36:31.994 ServerApp] 404 GET /api/kernels/aa43cd0c-abf8-4204-a364-b72d795cd894/channels?session_id=5a7b8783-a5b3-4dfb-a9d4-c4bcffba341a (::1): Kernel does not exist: aa43cd0c-abf8-4204-a364-b72d795cd894
[W 2022-06-14 09:36:31.996 ServerApp] 404 GET /api/kernels/aa43cd0c-abf8-4204-a364-b72d795cd894/channels?session_id=5a7b8783-a5b3-4dfb-a9d4-c4bcffba341a (::1) 5.46ms referer=None
[W 2022-06-14 09:36:32.025 ServerApp] 404 GET /api/kernels/aa43cd0c-abf8-4204-a364-b72d795cd894?1655195791848 (::1): Kernel does not exist: aa43cd0c-abf8-4204-a364-b72d795cd894
[W 2022-06-14 09:36:32.026 ServerApp] Kernel does not exist: aa43cd0c-abf8-4204-a364-b72d795cd894
[W 2022-06-14 09:36:32.027 ServerApp] 404 GET /api/kernels/aa43cd0c-abf8-4204-a364-b72d795cd894?1655195791848 (::1) 3.63ms referer=http://localhost:8885/lab/tree/jupyter_notebooks/paper/1b.Precipitation_timeseries.ipynb
[W 2022-06-14 09:36:34.469 ServerApp] 404 GET /api/kernels/866ff731-88f0-4d5c-b354-d1cf987557d3?1655195794294 (::1): Kernel does not exist: 866ff731-88f0-4d5c-b354-d1cf987557d3
[W 2022-06-14 09:36:34.470 ServerApp] Kernel does not exist: 866ff731-88f0-4d5c-b354-d1cf987557d3
[W 2022-06-14 09:36:34.471 ServerApp] 404 GET /api/kernels/866ff731-88f0-4d5c-b354-d1cf987557d3?1655195794294 (::1) 3.30ms referer=http://localhost:8885/lab/tree/jupyter_notebooks/paper/1b.Precipitation_timeseries.ipynb
[W 2022-06-14 09:36:35.148 ServerApp] 404 GET /api/kernels/866ff731-88f0-4d5c-b354-d1cf987557d3/channels?session_id=1df673bb-5d78-4553-8bb4-2d1b0345ad62 (::1): Kernel does not exist: 866ff731-88f0-4d5c-b354-d1cf987557d3
[W 2022-06-14 09:36:35.151 ServerApp] 404 GET /api/kernels/866ff731-88f0-4d5c-b354-d1cf987557d3/channels?session_id=1df673bb-5d78-4553-8bb4-2d1b0345ad62 (::1) 6.11ms referer=None
[W 2022-06-14 09:36:35.177 ServerApp] 404 GET /api/kernels/866ff731-88f0-4d5c-b354-d1cf987557d3?1655195795000 (::1): Kernel does not exist: 866ff731-88f0-4d5c-b354-d1cf987557d3
[W 2022-06-14 09:36:35.178 ServerApp] Kernel does not exist: 866ff731-88f0-4d5c-b354-d1cf987557d3
[W 2022-06-14 09:36:35.178 ServerApp] 404 GET /api/kernels/866ff731-88f0-4d5c-b354-d1cf987557d3?1655195795000 (::1) 2.32ms referer=http://localhost:8885/lab/tree/jupyter_notebooks/paper/1b.Precipitation_timeseries.ipynb
[W 2022-06-14 09:36:36.259 ServerApp] 404 GET /api/kernels/0a408c42-0719-4783-8c0f-a69cffa4bca1?1655195796083 (::1): Kernel does not exist: 0a408c42-0719-4783-8c0f-a69cffa4bca1
[W 2022-06-14 09:36:36.260 ServerApp] Kernel does not exist: 0a408c42-0719-4783-8c0f-a69cffa4bca1
[W 2022-06-14 09:36:36.262 ServerApp] 404 GET /api/kernels/0a408c42-0719-4783-8c0f-a69cffa4bca1?1655195796083 (::1) 4.22ms referer=http://localhost:8885/lab/tree/jupyter_notebooks/paper/1b.Precipitation_timeseries.ipynb
[W 2022-06-14 09:36:37.205 ServerApp] 404 GET /api/kernels/866ff731-88f0-4d5c-b354-d1cf987557d3/channels?session_id=1df673bb-5d78-4553-8bb4-2d1b0345ad62 (::1): Kernel does not exist: 866ff731-88f0-4d5c-b354-d1cf987557d3
[W 2022-06-14 09:36:37.207 ServerApp] 404 GET /api/kernels/866ff731-88f0-4d5c-b354-d1cf987557d3/channels?session_id=1df673bb-5d78-4553-8bb4-2d1b0345ad62 (::1) 6.27ms referer=None
[W 2022-06-14 09:36:37.233 ServerApp] 404 GET /api/kernels/866ff731-88f0-4d5c-b354-d1cf987557d3?1655195797057 (::1): Kernel does not exist: 866ff731-88f0-4d5c-b354-d1cf987557d3
[W 2022-06-14 09:36:37.234 ServerApp] Kernel does not exist: 866ff731-88f0-4d5c-b354-d1cf987557d3
[W 2022-06-14 09:36:37.235 ServerApp] 404 GET /api/kernels/866ff731-88f0-4d5c-b354-d1cf987557d3?1655195797057 (::1) 2.95ms referer=http://localhost:8885/lab/tree/jupyter_notebooks/paper/1b.Precipitation_timeseries.ipynb
[W 2022-06-14 09:36:37.265 ServerApp] 404 GET /api/kernels/0a408c42-0719-4783-8c0f-a69cffa4bca1/channels?session_id=d3482239-6978-4838-b5a2-f843d4c5f607 (::1): Kernel does not exist: 0a408c42-0719-4783-8c0f-a69cffa4bca1
[W 2022-06-14 09:36:37.267 ServerApp] 404 GET /api/kernels/0a408c42-0719-4783-8c0f-a69cffa4bca1/channels?session_id=d3482239-6978-4838-b5a2-f843d4c5f607 (::1) 5.45ms referer=None
[W 2022-06-14 09:36:37.318 ServerApp] 404 GET /api/kernels/0a408c42-0719-4783-8c0f-a69cffa4bca1?1655195797139 (::1): Kernel does not exist: 0a408c42-0719-4783-8c0f-a69cffa4bca1
[W 2022-06-14 09:36:37.318 ServerApp] Kernel does not exist: 0a408c42-0719-4783-8c0f-a69cffa4bca1
[W 2022-06-14 09:36:37.319 ServerApp] 404 GET /api/kernels/0a408c42-0719-4783-8c0f-a69cffa4bca1?1655195797139 (::1) 2.36ms referer=http://localhost:8885/lab/tree/jupyter_notebooks/paper/1b.Precipitation_timeseries.ipynb
[W 2022-06-14 09:36:37.345 ServerApp] 404 GET /api/kernels/aa43cd0c-abf8-4204-a364-b72d795cd894/channels?session_id=5a7b8783-a5b3-4dfb-a9d4-c4bcffba341a (::1): Kernel does not exist: aa43cd0c-abf8-4204-a364-b72d795cd894
[W 2022-06-14 09:36:37.348 ServerApp] 404 GET /api/kernels/aa43cd0c-abf8-4204-a364-b72d795cd894/channels?session_id=5a7b8783-a5b3-4dfb-a9d4-c4bcffba341a (::1) 5.85ms referer=None
[W 2022-06-14 09:36:37.597 ServerApp] 404 GET /api/kernels/aa43cd0c-abf8-4204-a364-b72d795cd894?1655195797201 (::1): Kernel does not exist: aa43cd0c-abf8-4204-a364-b72d795cd894
[W 2022-06-14 09:36:37.598 ServerApp] Kernel does not exist: aa43cd0c-abf8-4204-a364-b72d795cd894
[W 2022-06-14 09:36:37.599 ServerApp] 404 GET /api/kernels/aa43cd0c-abf8-4204-a364-b72d795cd894?1655195797201 (::1) 2.96ms referer=http://localhost:8885/lab/tree/jupyter_notebooks/paper/1b.Precipitation_timeseries.ipynb
[W 2022-06-14 09:36:38.210 ServerApp] 404 GET /api/kernels/866ff731-88f0-4d5c-b354-d1cf987557d3/channels?session_id=1df673bb-5d78-4553-8bb4-2d1b0345ad62 (::1): Kernel does not exist: 866ff731-88f0-4d5c-b354-d1cf987557d3
[W 2022-06-14 09:36:38.212 ServerApp] 404 GET /api/kernels/866ff731-88f0-4d5c-b354-d1cf987557d3/channels?session_id=1df673bb-5d78-4553-8bb4-2d1b0345ad62 (::1) 5.56ms referer=None
[W 2022-06-14 09:36:38.238 ServerApp] 404 GET /api/kernels/866ff731-88f0-4d5c-b354-d1cf987557d3?1655195798062 (::1): Kernel does not exist: 866ff731-88f0-4d5c-b354-d1cf987557d3
[W 2022-06-14 09:36:38.239 ServerApp] Kernel does not exist: 866ff731-88f0-4d5c-b354-d1cf987557d3
[W 2022-06-14 09:36:38.239 ServerApp] 404 GET /api/kernels/866ff731-88f0-4d5c-b354-d1cf987557d3?1655195798062 (::1) 2.31ms referer=http://localhost:8885/lab/tree/jupyter_notebooks/paper/1b.Precipitation_timeseries.ipynb
[W 2022-06-14 09:36:39.159 ServerApp] 404 GET /api/kernels/babec40f-135a-42c1-8757-5456a3cfceac?1655195798977 (::1): Kernel does not exist: babec40f-135a-42c1-8757-5456a3cfceac
[W 2022-06-14 09:36:39.160 ServerApp] Kernel does not exist: babec40f-135a-42c1-8757-5456a3cfceac
[W 2022-06-14 09:36:39.161 ServerApp] 404 GET /api/kernels/babec40f-135a-42c1-8757-5456a3cfceac?1655195798977 (::1) 3.99ms referer=http://localhost:8885/lab/tree/jupyter_notebooks/paper/1b.Precipitation_timeseries.ipynb
[W 2022-06-14 09:36:39.364 ServerApp] 404 GET /api/kernels/866ff731-88f0-4d5c-b354-d1cf987557d3/channels?session_id=1df673bb-5d78-4553-8bb4-2d1b0345ad62 (::1): Kernel does not exist: 866ff731-88f0-4d5c-b354-d1cf987557d3
[W 2022-06-14 09:36:39.367 ServerApp] 404 GET /api/kernels/866ff731-88f0-4d5c-b354-d1cf987557d3/channels?session_id=1df673bb-5d78-4553-8bb4-2d1b0345ad62 (::1) 5.84ms referer=None
[W 2022-06-14 09:36:39.391 ServerApp] 404 GET /api/kernels/866ff731-88f0-4d5c-b354-d1cf987557d3?1655195799216 (::1): Kernel does not exist: 866ff731-88f0-4d5c-b354-d1cf987557d3
[W 2022-06-14 09:36:39.392 ServerApp] Kernel does not exist: 866ff731-88f0-4d5c-b354-d1cf987557d3
[W 2022-06-14 09:36:39.393 ServerApp] 404 GET /api/kernels/866ff731-88f0-4d5c-b354-d1cf987557d3?1655195799216 (::1) 2.82ms referer=http://localhost:8885/lab/tree/jupyter_notebooks/paper/1b.Precipitation_timeseries.ipynb
[W 2022-06-14 09:36:39.429 ServerApp] 404 GET /api/kernels/0a408c42-0719-4783-8c0f-a69cffa4bca1/channels?session_id=d3482239-6978-4838-b5a2-f843d4c5f607 (::1): Kernel does not exist: 0a408c42-0719-4783-8c0f-a69cffa4bca1
[W 2022-06-14 09:36:39.432 ServerApp] 404 GET /api/kernels/0a408c42-0719-4783-8c0f-a69cffa4bca1/channels?session_id=d3482239-6978-4838-b5a2-f843d4c5f607 (::1) 6.93ms referer=None
[W 2022-06-14 09:36:39.456 ServerApp] 404 GET /api/kernels/0a408c42-0719-4783-8c0f-a69cffa4bca1?1655195799281 (::1): Kernel does not exist: 0a408c42-0719-4783-8c0f-a69cffa4bca1
[W 2022-06-14 09:36:39.457 ServerApp] Kernel does not exist: 0a408c42-0719-4783-8c0f-a69cffa4bca1
[W 2022-06-14 09:36:39.458 ServerApp] 404 GET /api/kernels/0a408c42-0719-4783-8c0f-a69cffa4bca1?1655195799281 (::1) 3.15ms referer=http://localhost:8885/lab/tree/jupyter_notebooks/paper/1b.Precipitation_timeseries.ipynb
[W 2022-06-14 09:36:41.201 ServerApp] 404 GET /api/kernels/babec40f-135a-42c1-8757-5456a3cfceac/channels?session_id=c5d6e77e-cf84-4d48-a922-a2fc7fd8f4a6 (::1): Kernel does not exist: babec40f-135a-42c1-8757-5456a3cfceac
[W 2022-06-14 09:36:41.204 ServerApp] 404 GET /api/kernels/babec40f-135a-42c1-8757-5456a3cfceac/channels?session_id=c5d6e77e-cf84-4d48-a922-a2fc7fd8f4a6 (::1) 13.21ms referer=None
[W 2022-06-14 09:36:41.246 ServerApp] 404 GET /api/kernels/babec40f-135a-42c1-8757-5456a3cfceac?1655195801068 (::1): Kernel does not exist: babec40f-135a-42c1-8757-5456a3cfceac
[W 2022-06-14 09:36:41.246 ServerApp] Kernel does not exist: babec40f-135a-42c1-8757-5456a3cfceac
[W 2022-06-14 09:36:41.247 ServerApp] 404 GET /api/kernels/babec40f-135a-42c1-8757-5456a3cfceac?1655195801068 (::1) 1.93ms referer=http://localhost:8885/lab/tree/jupyter_notebooks/paper/1b.Precipitation_timeseries.ipynb
[W 2022-06-14 09:36:44.177 ServerApp] 404 GET /api/kernels/9348b8a3-e482-424f-9f0c-735584fde370?1655195804002 (::1): Kernel does not exist: 9348b8a3-e482-424f-9f0c-735584fde370
[W 2022-06-14 09:36:44.178 ServerApp] Kernel does not exist: 9348b8a3-e482-424f-9f0c-735584fde370
[W 2022-06-14 09:36:44.179 ServerApp] 404 GET /api/kernels/9348b8a3-e482-424f-9f0c-735584fde370?1655195804002 (::1) 3.56ms referer=http://localhost:8885/lab/tree/jupyter_notebooks/paper/1b.Precipitation_timeseries.ipynb
[W 2022-06-14 09:36:45.742 ServerApp] 404 GET /api/kernels/0a408c42-0719-4783-8c0f-a69cffa4bca1/channels?session_id=d3482239-6978-4838-b5a2-f843d4c5f607 (::1): Kernel does not exist: 0a408c42-0719-4783-8c0f-a69cffa4bca1
[W 2022-06-14 09:36:45.744 ServerApp] 404 GET /api/kernels/0a408c42-0719-4783-8c0f-a69cffa4bca1/channels?session_id=d3482239-6978-4838-b5a2-f843d4c5f607 (::1) 6.21ms referer=None
[W 2022-06-14 09:36:45.996 ServerApp] 404 GET /api/kernels/0a408c42-0719-4783-8c0f-a69cffa4bca1?1655195805815 (::1): Kernel does not exist: 0a408c42-0719-4783-8c0f-a69cffa4bca1
[W 2022-06-14 09:36:45.996 ServerApp] Kernel does not exist: 0a408c42-0719-4783-8c0f-a69cffa4bca1
[W 2022-06-14 09:36:45.997 ServerApp] 404 GET /api/kernels/0a408c42-0719-4783-8c0f-a69cffa4bca1?1655195805815 (::1) 3.01ms referer=http://localhost:8885/lab/tree/jupyter_notebooks/paper/1b.Precipitation_timeseries.ipynb
[W 2022-06-14 09:36:46.022 ServerApp] 404 GET /api/kernels/feaa8cff-0254-4778-b8fd-76a5cbbbd6f0?1655195805817 (::1): Kernel does not exist: feaa8cff-0254-4778-b8fd-76a5cbbbd6f0
[W 2022-06-14 09:36:46.023 ServerApp] Kernel does not exist: feaa8cff-0254-4778-b8fd-76a5cbbbd6f0
[W 2022-06-14 09:36:46.023 ServerApp] 404 GET /api/kernels/feaa8cff-0254-4778-b8fd-76a5cbbbd6f0?1655195805817 (::1) 2.77ms referer=http://localhost:8885/lab/tree/jupyter_notebooks/paper/1b.Precipitation_timeseries.ipynb
[W 2022-06-14 09:36:47.038 ServerApp] 404 GET /api/kernels/babec40f-135a-42c1-8757-5456a3cfceac/channels?session_id=c5d6e77e-cf84-4d48-a922-a2fc7fd8f4a6 (::1): Kernel does not exist: babec40f-135a-42c1-8757-5456a3cfceac
[W 2022-06-14 09:36:47.041 ServerApp] 404 GET /api/kernels/babec40f-135a-42c1-8757-5456a3cfceac/channels?session_id=c5d6e77e-cf84-4d48-a922-a2fc7fd8f4a6 (::1) 7.21ms referer=None
[W 2022-06-14 09:36:47.067 ServerApp] 404 GET /api/kernels/babec40f-135a-42c1-8757-5456a3cfceac?1655195806891 (::1): Kernel does not exist: babec40f-135a-42c1-8757-5456a3cfceac
[W 2022-06-14 09:36:47.068 ServerApp] Kernel does not exist: babec40f-135a-42c1-8757-5456a3cfceac
[W 2022-06-14 09:36:47.069 ServerApp] 404 GET /api/kernels/babec40f-135a-42c1-8757-5456a3cfceac?1655195806891 (::1) 3.24ms referer=http://localhost:8885/lab/tree/jupyter_notebooks/paper/1b.Precipitation_timeseries.ipynb
[W 2022-06-14 09:36:49.152 ServerApp] 404 GET /api/kernels/d78a54fc-b9cc-4a8b-b05c-0548884240c5/channels?session_id=656fd1e3-868d-4a92-8062-60eb8624fa7b (::1): Kernel does not exist: d78a54fc-b9cc-4a8b-b05c-0548884240c5
[W 2022-06-14 09:36:49.155 ServerApp] 404 GET /api/kernels/d78a54fc-b9cc-4a8b-b05c-0548884240c5/channels?session_id=656fd1e3-868d-4a92-8062-60eb8624fa7b (::1) 5.97ms referer=None
[W 2022-06-14 09:36:49.182 ServerApp] 404 GET /api/kernels/d78a54fc-b9cc-4a8b-b05c-0548884240c5?1655195809005 (::1): Kernel does not exist: d78a54fc-b9cc-4a8b-b05c-0548884240c5
[W 2022-06-14 09:36:49.183 ServerApp] Kernel does not exist: d78a54fc-b9cc-4a8b-b05c-0548884240c5
[W 2022-06-14 09:36:49.183 ServerApp] 404 GET /api/kernels/d78a54fc-b9cc-4a8b-b05c-0548884240c5?1655195809005 (::1) 2.54ms referer=http://localhost:8885/lab/tree/jupyter_notebooks/paper/1b.Precipitation_timeseries.ipynb
[W 2022-06-14 09:36:49.719 ServerApp] 404 GET /api/kernels/feaa8cff-0254-4778-b8fd-76a5cbbbd6f0/channels?session_id=a6d5de86-ad1e-4b3b-8dab-448f3270469a (::1): Kernel does not exist: feaa8cff-0254-4778-b8fd-76a5cbbbd6f0
[W 2022-06-14 09:36:49.721 ServerApp] 404 GET /api/kernels/feaa8cff-0254-4778-b8fd-76a5cbbbd6f0/channels?session_id=a6d5de86-ad1e-4b3b-8dab-448f3270469a (::1) 5.47ms referer=None
[W 2022-06-14 09:36:49.744 ServerApp] 404 GET /api/kernels/feaa8cff-0254-4778-b8fd-76a5cbbbd6f0?1655195809570 (::1): Kernel does not exist: feaa8cff-0254-4778-b8fd-76a5cbbbd6f0
[W 2022-06-14 09:36:49.745 ServerApp] Kernel does not exist: feaa8cff-0254-4778-b8fd-76a5cbbbd6f0
[W 2022-06-14 09:36:49.745 ServerApp] 404 GET /api/kernels/feaa8cff-0254-4778-b8fd-76a5cbbbd6f0?1655195809570 (::1) 2.36ms referer=http://localhost:8885/lab/tree/jupyter_notebooks/paper/1b.Precipitation_timeseries.ipynb
[W 2022-06-14 09:36:50.453 ServerApp] 404 GET /api/kernels/9348b8a3-e482-424f-9f0c-735584fde370/channels?session_id=57d39b8f-e8f4-4926-b2e2-9d272139c8b5 (::1): Kernel does not exist: 9348b8a3-e482-424f-9f0c-735584fde370
[W 2022-06-14 09:36:50.455 ServerApp] 404 GET /api/kernels/9348b8a3-e482-424f-9f0c-735584fde370/channels?session_id=57d39b8f-e8f4-4926-b2e2-9d272139c8b5 (::1) 5.67ms referer=None
[W 2022-06-14 09:36:50.482 ServerApp] 404 GET /api/kernels/9348b8a3-e482-424f-9f0c-735584fde370?1655195810304 (::1): Kernel does not exist: 9348b8a3-e482-424f-9f0c-735584fde370
[W 2022-06-14 09:36:50.483 ServerApp] Kernel does not exist: 9348b8a3-e482-424f-9f0c-735584fde370
[W 2022-06-14 09:36:50.484 ServerApp] 404 GET /api/kernels/9348b8a3-e482-424f-9f0c-735584fde370?1655195810304 (::1) 3.66ms referer=http://localhost:8885/lab/tree/jupyter_notebooks/paper/1b.Precipitation_timeseries.ipynb
[W 2022-06-14 09:36:53.723 ServerApp] 404 GET /api/kernels/866ff731-88f0-4d5c-b354-d1cf987557d3/channels?session_id=1df673bb-5d78-4553-8bb4-2d1b0345ad62 (::1): Kernel does not exist: 866ff731-88f0-4d5c-b354-d1cf987557d3
[W 2022-06-14 09:36:53.725 ServerApp] 404 GET /api/kernels/866ff731-88f0-4d5c-b354-d1cf987557d3/channels?session_id=1df673bb-5d78-4553-8bb4-2d1b0345ad62 (::1) 6.45ms referer=None
[W 2022-06-14 09:36:53.752 ServerApp] 404 GET /api/kernels/866ff731-88f0-4d5c-b354-d1cf987557d3?1655195813576 (::1): Kernel does not exist: 866ff731-88f0-4d5c-b354-d1cf987557d3
[W 2022-06-14 09:36:53.753 ServerApp] Kernel does not exist: 866ff731-88f0-4d5c-b354-d1cf987557d3
[W 2022-06-14 09:36:53.753 ServerApp] 404 GET /api/kernels/866ff731-88f0-4d5c-b354-d1cf987557d3?1655195813576 (::1) 2.95ms referer=http://localhost:8885/lab/tree/jupyter_notebooks/paper/1b.Precipitation_timeseries.ipynb
[W 2022-06-14 09:36:54.514 ServerApp] 404 GET /api/kernels/feaa8cff-0254-4778-b8fd-76a5cbbbd6f0/channels?session_id=a6d5de86-ad1e-4b3b-8dab-448f3270469a (::1): Kernel does not exist: feaa8cff-0254-4778-b8fd-76a5cbbbd6f0
[W 2022-06-14 09:36:54.516 ServerApp] 404 GET /api/kernels/feaa8cff-0254-4778-b8fd-76a5cbbbd6f0/channels?session_id=a6d5de86-ad1e-4b3b-8dab-448f3270469a (::1) 6.00ms referer=None
[W 2022-06-14 09:36:54.541 ServerApp] 404 GET /api/kernels/feaa8cff-0254-4778-b8fd-76a5cbbbd6f0?1655195814365 (::1): Kernel does not exist: feaa8cff-0254-4778-b8fd-76a5cbbbd6f0
[W 2022-06-14 09:36:54.542 ServerApp] Kernel does not exist: feaa8cff-0254-4778-b8fd-76a5cbbbd6f0
[W 2022-06-14 09:36:54.543 ServerApp] 404 GET /api/kernels/feaa8cff-0254-4778-b8fd-76a5cbbbd6f0?1655195814365 (::1) 2.96ms referer=http://localhost:8885/lab/tree/jupyter_notebooks/paper/1b.Precipitation_timeseries.ipynb
[W 2022-06-14 09:36:54.786 ServerApp] 404 GET /api/kernels/9348b8a3-e482-424f-9f0c-735584fde370/channels?session_id=57d39b8f-e8f4-4926-b2e2-9d272139c8b5 (::1): Kernel does not exist: 9348b8a3-e482-424f-9f0c-735584fde370
[W 2022-06-14 09:36:54.788 ServerApp] 404 GET /api/kernels/9348b8a3-e482-424f-9f0c-735584fde370/channels?session_id=57d39b8f-e8f4-4926-b2e2-9d272139c8b5 (::1) 6.09ms referer=None
[W 2022-06-14 09:36:54.817 ServerApp] 404 GET /api/kernels/9348b8a3-e482-424f-9f0c-735584fde370?1655195814637 (::1): Kernel does not exist: 9348b8a3-e482-424f-9f0c-735584fde370
[W 2022-06-14 09:36:54.818 ServerApp] Kernel does not exist: 9348b8a3-e482-424f-9f0c-735584fde370
[W 2022-06-14 09:36:54.819 ServerApp] 404 GET /api/kernels/9348b8a3-e482-424f-9f0c-735584fde370?1655195814637 (::1) 2.94ms referer=http://localhost:8885/lab/tree/jupyter_notebooks/paper/1b.Precipitation_timeseries.ipynb
[W 2022-06-14 09:36:55.442 ServerApp] 404 GET /api/kernels/babec40f-135a-42c1-8757-5456a3cfceac/channels?session_id=c5d6e77e-cf84-4d48-a922-a2fc7fd8f4a6 (::1): Kernel does not exist: babec40f-135a-42c1-8757-5456a3cfceac
[W 2022-06-14 09:36:55.444 ServerApp] 404 GET /api/kernels/babec40f-135a-42c1-8757-5456a3cfceac/channels?session_id=c5d6e77e-cf84-4d48-a922-a2fc7fd8f4a6 (::1) 5.53ms referer=None
[W 2022-06-14 09:36:55.467 ServerApp] 404 GET /api/kernels/babec40f-135a-42c1-8757-5456a3cfceac?1655195815293 (::1): Kernel does not exist: babec40f-135a-42c1-8757-5456a3cfceac
[W 2022-06-14 09:36:55.468 ServerApp] Kernel does not exist: babec40f-135a-42c1-8757-5456a3cfceac
[W 2022-06-14 09:36:55.469 ServerApp] 404 GET /api/kernels/babec40f-135a-42c1-8757-5456a3cfceac?1655195815293 (::1) 2.57ms referer=http://localhost:8885/lab/tree/jupyter_notebooks/paper/1b.Precipitation_timeseries.ipynb
[W 2022-06-14 09:36:59.791 ServerApp] 404 GET /api/kernels/9348b8a3-e482-424f-9f0c-735584fde370/channels?session_id=57d39b8f-e8f4-4926-b2e2-9d272139c8b5 (::1): Kernel does not exist: 9348b8a3-e482-424f-9f0c-735584fde370
[W 2022-06-14 09:36:59.796 ServerApp] 404 GET /api/kernels/9348b8a3-e482-424f-9f0c-735584fde370/channels?session_id=57d39b8f-e8f4-4926-b2e2-9d272139c8b5 (::1) 9.14ms referer=None
[W 2022-06-14 09:36:59.823 ServerApp] 404 GET /api/kernels/9348b8a3-e482-424f-9f0c-735584fde370?1655195819645 (::1): Kernel does not exist: 9348b8a3-e482-424f-9f0c-735584fde370
[W 2022-06-14 09:36:59.824 ServerApp] Kernel does not exist: 9348b8a3-e482-424f-9f0c-735584fde370
[W 2022-06-14 09:36:59.825 ServerApp] 404 GET /api/kernels/9348b8a3-e482-424f-9f0c-735584fde370?1655195819645 (::1) 3.38ms referer=http://localhost:8885/lab/tree/jupyter_notebooks/paper/1b.Precipitation_timeseries.ipynb
[W 2022-06-14 09:37:00.250 ServerApp] 404 GET /api/kernels/feaa8cff-0254-4778-b8fd-76a5cbbbd6f0/channels?session_id=a6d5de86-ad1e-4b3b-8dab-448f3270469a (::1): Kernel does not exist: feaa8cff-0254-4778-b8fd-76a5cbbbd6f0
[W 2022-06-14 09:37:00.252 ServerApp] 404 GET /api/kernels/feaa8cff-0254-4778-b8fd-76a5cbbbd6f0/channels?session_id=a6d5de86-ad1e-4b3b-8dab-448f3270469a (::1) 5.58ms referer=None
[W 2022-06-14 09:37:00.275 ServerApp] 404 GET /api/kernels/feaa8cff-0254-4778-b8fd-76a5cbbbd6f0?1655195820101 (::1): Kernel does not exist: feaa8cff-0254-4778-b8fd-76a5cbbbd6f0
[W 2022-06-14 09:37:00.276 ServerApp] Kernel does not exist: feaa8cff-0254-4778-b8fd-76a5cbbbd6f0
[W 2022-06-14 09:37:00.277 ServerApp] 404 GET /api/kernels/feaa8cff-0254-4778-b8fd-76a5cbbbd6f0?1655195820101 (::1) 2.51ms referer=http://localhost:8885/lab/tree/jupyter_notebooks/paper/1b.Precipitation_timeseries.ipynb
[W 2022-06-14 09:37:01.079 ServerApp] 404 GET /api/kernels/0a408c42-0719-4783-8c0f-a69cffa4bca1/channels?session_id=d3482239-6978-4838-b5a2-f843d4c5f607 (::1): Kernel does not exist: 0a408c42-0719-4783-8c0f-a69cffa4bca1
[W 2022-06-14 09:37:01.081 ServerApp] 404 GET /api/kernels/0a408c42-0719-4783-8c0f-a69cffa4bca1/channels?session_id=d3482239-6978-4838-b5a2-f843d4c5f607 (::1) 5.53ms referer=None
[W 2022-06-14 09:37:01.105 ServerApp] 404 GET /api/kernels/0a408c42-0719-4783-8c0f-a69cffa4bca1?1655195820930 (::1): Kernel does not exist: 0a408c42-0719-4783-8c0f-a69cffa4bca1
[W 2022-06-14 09:37:01.105 ServerApp] Kernel does not exist: 0a408c42-0719-4783-8c0f-a69cffa4bca1
[W 2022-06-14 09:37:01.106 ServerApp] 404 GET /api/kernels/0a408c42-0719-4783-8c0f-a69cffa4bca1?1655195820930 (::1) 2.34ms referer=http://localhost:8885/lab/tree/jupyter_notebooks/paper/1b.Precipitation_timeseries.ipynb
[W 2022-06-14 09:37:05.344 ServerApp] 404 GET /api/kernels/babec40f-135a-42c1-8757-5456a3cfceac/channels?session_id=c5d6e77e-cf84-4d48-a922-a2fc7fd8f4a6 (::1): Kernel does not exist: babec40f-135a-42c1-8757-5456a3cfceac
[W 2022-06-14 09:37:05.347 ServerApp] 404 GET /api/kernels/babec40f-135a-42c1-8757-5456a3cfceac/channels?session_id=c5d6e77e-cf84-4d48-a922-a2fc7fd8f4a6 (::1) 6.63ms referer=None
[W 2022-06-14 09:37:05.370 ServerApp] 404 GET /api/kernels/babec40f-135a-42c1-8757-5456a3cfceac?1655195825195 (::1): Kernel does not exist: babec40f-135a-42c1-8757-5456a3cfceac
[W 2022-06-14 09:37:05.370 ServerApp] Kernel does not exist: babec40f-135a-42c1-8757-5456a3cfceac
[W 2022-06-14 09:37:05.371 ServerApp] 404 GET /api/kernels/babec40f-135a-42c1-8757-5456a3cfceac?1655195825195 (::1) 2.41ms referer=http://localhost:8885/lab/tree/jupyter_notebooks/paper/1b.Precipitation_timeseries.ipynb
[W 2022-06-14 09:37:05.402 ServerApp] 404 GET /api/kernels/aa43cd0c-abf8-4204-a364-b72d795cd894/channels?session_id=5a7b8783-a5b3-4dfb-a9d4-c4bcffba341a (::1): Kernel does not exist: aa43cd0c-abf8-4204-a364-b72d795cd894
[W 2022-06-14 09:37:05.404 ServerApp] 404 GET /api/kernels/aa43cd0c-abf8-4204-a364-b72d795cd894/channels?session_id=5a7b8783-a5b3-4dfb-a9d4-c4bcffba341a (::1) 5.86ms referer=None
[W 2022-06-14 09:37:05.432 ServerApp] 404 GET /api/kernels/aa43cd0c-abf8-4204-a364-b72d795cd894?1655195825253 (::1): Kernel does not exist: aa43cd0c-abf8-4204-a364-b72d795cd894
[W 2022-06-14 09:37:05.432 ServerApp] Kernel does not exist: aa43cd0c-abf8-4204-a364-b72d795cd894
[W 2022-06-14 09:37:05.433 ServerApp] 404 GET /api/kernels/aa43cd0c-abf8-4204-a364-b72d795cd894?1655195825253 (::1) 2.99ms referer=http://localhost:8885/lab/tree/jupyter_notebooks/paper/1b.Precipitation_timeseries.ipynb
[W 2022-06-14 09:37:09.465 ServerApp] 404 GET /api/kernels/866ff731-88f0-4d5c-b354-d1cf987557d3/channels?session_id=1df673bb-5d78-4553-8bb4-2d1b0345ad62 (::1): Kernel does not exist: 866ff731-88f0-4d5c-b354-d1cf987557d3
[W 2022-06-14 09:37:09.468 ServerApp] 404 GET /api/kernels/866ff731-88f0-4d5c-b354-d1cf987557d3/channels?session_id=1df673bb-5d78-4553-8bb4-2d1b0345ad62 (::1) 6.60ms referer=None
[W 2022-06-14 09:37:09.491 ServerApp] 404 GET /api/kernels/866ff731-88f0-4d5c-b354-d1cf987557d3?1655195829316 (::1): Kernel does not exist: 866ff731-88f0-4d5c-b354-d1cf987557d3
[W 2022-06-14 09:37:09.491 ServerApp] Kernel does not exist: 866ff731-88f0-4d5c-b354-d1cf987557d3
[W 2022-06-14 09:37:09.492 ServerApp] 404 GET /api/kernels/866ff731-88f0-4d5c-b354-d1cf987557d3?1655195829316 (::1) 2.27ms referer=http://localhost:8885/lab/tree/jupyter_notebooks/paper/1b.Precipitation_timeseries.ipynb
[W 2022-06-14 09:37:10.132 ServerApp] 404 GET /api/kernels/babec40f-135a-42c1-8757-5456a3cfceac/channels?session_id=c5d6e77e-cf84-4d48-a922-a2fc7fd8f4a6 (::1): Kernel does not exist: babec40f-135a-42c1-8757-5456a3cfceac
[W 2022-06-14 09:37:10.135 ServerApp] 404 GET /api/kernels/babec40f-135a-42c1-8757-5456a3cfceac/channels?session_id=c5d6e77e-cf84-4d48-a922-a2fc7fd8f4a6 (::1) 6.43ms referer=None
[W 2022-06-14 09:37:10.169 ServerApp] 404 GET /api/kernels/babec40f-135a-42c1-8757-5456a3cfceac?1655195829992 (::1): Kernel does not exist: babec40f-135a-42c1-8757-5456a3cfceac
[W 2022-06-14 09:37:10.169 ServerApp] Kernel does not exist: babec40f-135a-42c1-8757-5456a3cfceac
[W 2022-06-14 09:37:10.170 ServerApp] 404 GET /api/kernels/babec40f-135a-42c1-8757-5456a3cfceac?1655195829992 (::1) 3.12ms referer=http://localhost:8885/lab/tree/jupyter_notebooks/paper/1b.Precipitation_timeseries.ipynb
[W 2022-06-14 09:37:11.761 ServerApp] 404 GET /api/kernels/feaa8cff-0254-4778-b8fd-76a5cbbbd6f0/channels?session_id=a6d5de86-ad1e-4b3b-8dab-448f3270469a (::1): Kernel does not exist: feaa8cff-0254-4778-b8fd-76a5cbbbd6f0
[W 2022-06-14 09:37:11.764 ServerApp] 404 GET /api/kernels/feaa8cff-0254-4778-b8fd-76a5cbbbd6f0/channels?session_id=a6d5de86-ad1e-4b3b-8dab-448f3270469a (::1) 6.21ms referer=None
[W 2022-06-14 09:37:11.791 ServerApp] 404 GET /api/kernels/feaa8cff-0254-4778-b8fd-76a5cbbbd6f0?1655195831613 (::1): Kernel does not exist: feaa8cff-0254-4778-b8fd-76a5cbbbd6f0
[W 2022-06-14 09:37:11.791 ServerApp] Kernel does not exist: feaa8cff-0254-4778-b8fd-76a5cbbbd6f0
[W 2022-06-14 09:37:11.792 ServerApp] 404 GET /api/kernels/feaa8cff-0254-4778-b8fd-76a5cbbbd6f0?1655195831613 (::1) 2.56ms referer=http://localhost:8885/lab/tree/jupyter_notebooks/paper/1b.Precipitation_timeseries.ipynb
[W 2022-06-14 09:37:13.482 ServerApp] 404 GET /api/kernels/9348b8a3-e482-424f-9f0c-735584fde370/channels?session_id=57d39b8f-e8f4-4926-b2e2-9d272139c8b5 (::1): Kernel does not exist: 9348b8a3-e482-424f-9f0c-735584fde370
[W 2022-06-14 09:37:13.484 ServerApp] 404 GET /api/kernels/9348b8a3-e482-424f-9f0c-735584fde370/channels?session_id=57d39b8f-e8f4-4926-b2e2-9d272139c8b5 (::1) 5.97ms referer=None
[W 2022-06-14 09:37:13.509 ServerApp] 404 GET /api/kernels/9348b8a3-e482-424f-9f0c-735584fde370?1655195833333 (::1): Kernel does not exist: 9348b8a3-e482-424f-9f0c-735584fde370
[W 2022-06-14 09:37:13.510 ServerApp] Kernel does not exist: 9348b8a3-e482-424f-9f0c-735584fde370
[W 2022-06-14 09:37:13.511 ServerApp] 404 GET /api/kernels/9348b8a3-e482-424f-9f0c-735584fde370?1655195833333 (::1) 2.95ms referer=http://localhost:8885/lab/tree/jupyter_notebooks/paper/1b.Precipitation_timeseries.ipynb
[W 2022-06-14 09:37:18.264 ServerApp] 404 GET /api/kernels/0a408c42-0719-4783-8c0f-a69cffa4bca1/channels?session_id=d3482239-6978-4838-b5a2-f843d4c5f607 (::1): Kernel does not exist: 0a408c42-0719-4783-8c0f-a69cffa4bca1
[W 2022-06-14 09:37:18.267 ServerApp] 404 GET /api/kernels/0a408c42-0719-4783-8c0f-a69cffa4bca1/channels?session_id=d3482239-6978-4838-b5a2-f843d4c5f607 (::1) 6.85ms referer=None
[W 2022-06-14 09:37:18.496 ServerApp] 404 GET /api/kernels/0a408c42-0719-4783-8c0f-a69cffa4bca1?1655195838320 (::1): Kernel does not exist: 0a408c42-0719-4783-8c0f-a69cffa4bca1
[W 2022-06-14 09:37:18.497 ServerApp] Kernel does not exist: 0a408c42-0719-4783-8c0f-a69cffa4bca1
[W 2022-06-14 09:37:18.498 ServerApp] 404 GET /api/kernels/0a408c42-0719-4783-8c0f-a69cffa4bca1?1655195838320 (::1) 3.56ms referer=http://localhost:8885/lab/tree/jupyter_notebooks/paper/1b.Precipitation_timeseries.ipynb
[W 2022-06-14 09:37:18.904 ServerApp] 404 GET /api/kernels/d78a54fc-b9cc-4a8b-b05c-0548884240c5/channels?session_id=656fd1e3-868d-4a92-8062-60eb8624fa7b (::1): Kernel does not exist: d78a54fc-b9cc-4a8b-b05c-0548884240c5
[W 2022-06-14 09:37:18.906 ServerApp] 404 GET /api/kernels/d78a54fc-b9cc-4a8b-b05c-0548884240c5/channels?session_id=656fd1e3-868d-4a92-8062-60eb8624fa7b (::1) 6.13ms referer=None
[W 2022-06-14 09:37:18.930 ServerApp] 404 GET /api/kernels/d78a54fc-b9cc-4a8b-b05c-0548884240c5?1655195838755 (::1): Kernel does not exist: d78a54fc-b9cc-4a8b-b05c-0548884240c5
[W 2022-06-14 09:37:18.931 ServerApp] Kernel does not exist: d78a54fc-b9cc-4a8b-b05c-0548884240c5
[W 2022-06-14 09:37:18.931 ServerApp] 404 GET /api/kernels/d78a54fc-b9cc-4a8b-b05c-0548884240c5?1655195838755 (::1) 2.36ms referer=http://localhost:8885/lab/tree/jupyter_notebooks/paper/1b.Precipitation_timeseries.ipynb
[W 2022-06-14 09:37:34.332 ServerApp] 404 GET /api/kernels/9348b8a3-e482-424f-9f0c-735584fde370/channels?session_id=57d39b8f-e8f4-4926-b2e2-9d272139c8b5 (::1): Kernel does not exist: 9348b8a3-e482-424f-9f0c-735584fde370
[W 2022-06-14 09:37:34.337 ServerApp] 404 GET /api/kernels/9348b8a3-e482-424f-9f0c-735584fde370/channels?session_id=57d39b8f-e8f4-4926-b2e2-9d272139c8b5 (::1) 8.07ms referer=None
[W 2022-06-14 09:37:34.379 ServerApp] 404 GET /api/kernels/9348b8a3-e482-424f-9f0c-735584fde370?1655195854203 (::1): Kernel does not exist: 9348b8a3-e482-424f-9f0c-735584fde370
[W 2022-06-14 09:37:34.379 ServerApp] Kernel does not exist: 9348b8a3-e482-424f-9f0c-735584fde370
[W 2022-06-14 09:37:34.380 ServerApp] 404 GET /api/kernels/9348b8a3-e482-424f-9f0c-735584fde370?1655195854203 (::1) 3.01ms referer=http://localhost:8885/lab/tree/jupyter_notebooks/paper/1b.Precipitation_timeseries.ipynb
[W 2022-06-14 09:37:40.531 ServerApp] 404 GET /api/kernels/9348b8a3-e482-424f-9f0c-735584fde370/channels?session_id=57d39b8f-e8f4-4926-b2e2-9d272139c8b5 (::1): Kernel does not exist: 9348b8a3-e482-424f-9f0c-735584fde370
[W 2022-06-14 09:37:40.534 ServerApp] 404 GET /api/kernels/9348b8a3-e482-424f-9f0c-735584fde370/channels?session_id=57d39b8f-e8f4-4926-b2e2-9d272139c8b5 (::1) 7.27ms referer=None
[W 2022-06-14 09:37:40.559 ServerApp] 404 GET /api/kernels/9348b8a3-e482-424f-9f0c-735584fde370?1655195860382 (::1): Kernel does not exist: 9348b8a3-e482-424f-9f0c-735584fde370
[W 2022-06-14 09:37:40.560 ServerApp] Kernel does not exist: 9348b8a3-e482-424f-9f0c-735584fde370
[W 2022-06-14 09:37:40.561 ServerApp] 404 GET /api/kernels/9348b8a3-e482-424f-9f0c-735584fde370?1655195860382 (::1) 3.06ms referer=http://localhost:8885/lab/tree/jupyter_notebooks/paper/1b.Precipitation_timeseries.ipynb
[W 2022-06-14 09:37:45.353 ServerApp] 404 GET /api/kernels/feaa8cff-0254-4778-b8fd-76a5cbbbd6f0/channels?session_id=a6d5de86-ad1e-4b3b-8dab-448f3270469a (::1): Kernel does not exist: feaa8cff-0254-4778-b8fd-76a5cbbbd6f0
[W 2022-06-14 09:37:45.355 ServerApp] 404 GET /api/kernels/feaa8cff-0254-4778-b8fd-76a5cbbbd6f0/channels?session_id=a6d5de86-ad1e-4b3b-8dab-448f3270469a (::1) 6.18ms referer=None
[W 2022-06-14 09:37:45.390 ServerApp] 404 GET /api/kernels/feaa8cff-0254-4778-b8fd-76a5cbbbd6f0?1655195865214 (::1): Kernel does not exist: feaa8cff-0254-4778-b8fd-76a5cbbbd6f0
[W 2022-06-14 09:37:45.391 ServerApp] Kernel does not exist: feaa8cff-0254-4778-b8fd-76a5cbbbd6f0
[W 2022-06-14 09:37:45.391 ServerApp] 404 GET /api/kernels/feaa8cff-0254-4778-b8fd-76a5cbbbd6f0?1655195865214 (::1) 2.30ms referer=http://localhost:8885/lab/tree/jupyter_notebooks/paper/1b.Precipitation_timeseries.ipynb
[W 2022-06-14 09:37:53.506 ServerApp] 404 GET /api/kernels/d78a54fc-b9cc-4a8b-b05c-0548884240c5/channels?session_id=656fd1e3-868d-4a92-8062-60eb8624fa7b (::1): Kernel does not exist: d78a54fc-b9cc-4a8b-b05c-0548884240c5
[W 2022-06-14 09:37:53.509 ServerApp] 404 GET /api/kernels/d78a54fc-b9cc-4a8b-b05c-0548884240c5/channels?session_id=656fd1e3-868d-4a92-8062-60eb8624fa7b (::1) 6.66ms referer=None
[W 2022-06-14 09:37:53.534 ServerApp] 404 GET /api/kernels/d78a54fc-b9cc-4a8b-b05c-0548884240c5?1655195873356 (::1): Kernel does not exist: d78a54fc-b9cc-4a8b-b05c-0548884240c5
[W 2022-06-14 09:37:53.534 ServerApp] Kernel does not exist: d78a54fc-b9cc-4a8b-b05c-0548884240c5
[W 2022-06-14 09:37:53.535 ServerApp] 404 GET /api/kernels/d78a54fc-b9cc-4a8b-b05c-0548884240c5?1655195873356 (::1) 3.01ms referer=http://localhost:8885/lab/tree/jupyter_notebooks/paper/1b.Precipitation_timeseries.ipynb
[W 2022-06-14 09:37:58.754 ServerApp] 404 GET /api/kernels/0a408c42-0719-4783-8c0f-a69cffa4bca1/channels?session_id=d3482239-6978-4838-b5a2-f843d4c5f607 (::1): Kernel does not exist: 0a408c42-0719-4783-8c0f-a69cffa4bca1
[W 2022-06-14 09:37:58.756 ServerApp] 404 GET /api/kernels/0a408c42-0719-4783-8c0f-a69cffa4bca1/channels?session_id=d3482239-6978-4838-b5a2-f843d4c5f607 (::1) 6.36ms referer=None
[W 2022-06-14 09:37:58.780 ServerApp] 404 GET /api/kernels/0a408c42-0719-4783-8c0f-a69cffa4bca1?1655195878603 (::1): Kernel does not exist: 0a408c42-0719-4783-8c0f-a69cffa4bca1
[W 2022-06-14 09:37:58.781 ServerApp] Kernel does not exist: 0a408c42-0719-4783-8c0f-a69cffa4bca1
[W 2022-06-14 09:37:58.782 ServerApp] 404 GET /api/kernels/0a408c42-0719-4783-8c0f-a69cffa4bca1?1655195878603 (::1) 2.79ms referer=http://localhost:8885/lab/tree/jupyter_notebooks/paper/1b.Precipitation_timeseries.ipynb
[W 2022-06-14 09:38:07.797 ServerApp] 404 GET /api/kernels/aa43cd0c-abf8-4204-a364-b72d795cd894/channels?session_id=5a7b8783-a5b3-4dfb-a9d4-c4bcffba341a (::1): Kernel does not exist: aa43cd0c-abf8-4204-a364-b72d795cd894
[W 2022-06-14 09:38:07.802 ServerApp] 404 GET /api/kernels/aa43cd0c-abf8-4204-a364-b72d795cd894/channels?session_id=5a7b8783-a5b3-4dfb-a9d4-c4bcffba341a (::1) 9.75ms referer=None
[W 2022-06-14 09:38:07.830 ServerApp] 404 GET /api/kernels/aa43cd0c-abf8-4204-a364-b72d795cd894?1655195887649 (::1): Kernel does not exist: aa43cd0c-abf8-4204-a364-b72d795cd894
[W 2022-06-14 09:38:07.831 ServerApp] Kernel does not exist: aa43cd0c-abf8-4204-a364-b72d795cd894
[W 2022-06-14 09:38:07.832 ServerApp] 404 GET /api/kernels/aa43cd0c-abf8-4204-a364-b72d795cd894?1655195887649 (::1) 3.06ms referer=http://localhost:8885/lab/tree/jupyter_notebooks/paper/1b.Precipitation_timeseries.ipynb
[W 2022-06-14 09:38:09.392 ServerApp] 404 GET /api/kernels/babec40f-135a-42c1-8757-5456a3cfceac/channels?session_id=c5d6e77e-cf84-4d48-a922-a2fc7fd8f4a6 (::1): Kernel does not exist: babec40f-135a-42c1-8757-5456a3cfceac
[W 2022-06-14 09:38:09.395 ServerApp] 404 GET /api/kernels/babec40f-135a-42c1-8757-5456a3cfceac/channels?session_id=c5d6e77e-cf84-4d48-a922-a2fc7fd8f4a6 (::1) 6.21ms referer=None
[W 2022-06-14 09:38:09.432 ServerApp] 404 GET /api/kernels/babec40f-135a-42c1-8757-5456a3cfceac?1655195889255 (::1): Kernel does not exist: babec40f-135a-42c1-8757-5456a3cfceac
[W 2022-06-14 09:38:09.433 ServerApp] Kernel does not exist: babec40f-135a-42c1-8757-5456a3cfceac
[W 2022-06-14 09:38:09.433 ServerApp] 404 GET /api/kernels/babec40f-135a-42c1-8757-5456a3cfceac?1655195889255 (::1) 2.35ms referer=http://localhost:8885/lab/tree/jupyter_notebooks/paper/1b.Precipitation_timeseries.ipynb
[W 2022-06-14 09:38:19.333 ServerApp] 404 GET /api/kernels/feaa8cff-0254-4778-b8fd-76a5cbbbd6f0/channels?session_id=a6d5de86-ad1e-4b3b-8dab-448f3270469a (::1): Kernel does not exist: feaa8cff-0254-4778-b8fd-76a5cbbbd6f0
[W 2022-06-14 09:38:19.335 ServerApp] 404 GET /api/kernels/feaa8cff-0254-4778-b8fd-76a5cbbbd6f0/channels?session_id=a6d5de86-ad1e-4b3b-8dab-448f3270469a (::1) 6.35ms referer=None
[W 2022-06-14 09:38:19.364 ServerApp] 404 GET /api/kernels/feaa8cff-0254-4778-b8fd-76a5cbbbd6f0?1655195899184 (::1): Kernel does not exist: feaa8cff-0254-4778-b8fd-76a5cbbbd6f0
[W 2022-06-14 09:38:19.365 ServerApp] Kernel does not exist: feaa8cff-0254-4778-b8fd-76a5cbbbd6f0
[W 2022-06-14 09:38:19.365 ServerApp] 404 GET /api/kernels/feaa8cff-0254-4778-b8fd-76a5cbbbd6f0?1655195899184 (::1) 2.95ms referer=http://localhost:8885/lab/tree/jupyter_notebooks/paper/1b.Precipitation_timeseries.ipynb
[I 2022-06-14 10:04:38.875 LabApp] Build is up to date
[E 2022-06-14 10:04:40.260 ServerApp] Uncaught exception GET /lab/api/settings/@jupyterlab/csvviewer-extension:tsv?1655197477663 (::1)
    HTTPServerRequest(protocol='http', host='localhost:8885', method='GET', uri='/lab/api/settings/@jupyterlab/csvviewer-extension:tsv?1655197477663', version='HTTP/1.1', remote_ip='::1')
    Traceback (most recent call last):
      File "/home/k/kimpson/bin/conda/envs/workhorse/lib/python3.7/site-packages/tornado/web.py", line 1704, in _execute
        result = await result
    tornado.iostream.StreamClosedError: Stream is closed
[E 2022-06-14 10:04:40.362 ServerApp] Uncaught exception GET /lab/api/settings/@jupyterlab/csvviewer-extension:csv?1655197477663 (::1)
    HTTPServerRequest(protocol='http', host='localhost:8885', method='GET', uri='/lab/api/settings/@jupyterlab/csvviewer-extension:csv?1655197477663', version='HTTP/1.1', remote_ip='::1')
    Traceback (most recent call last):
      File "/home/k/kimpson/bin/conda/envs/workhorse/lib/python3.7/site-packages/tornado/web.py", line 1704, in _execute
        result = await result
    tornado.iostream.StreamClosedError: Stream is closed
[E 2022-06-14 10:04:46.657 ServerApp] Uncaught exception GET /lab/api/settings?1655197486317 (::1)
    HTTPServerRequest(protocol='http', host='localhost:8885', method='GET', uri='/lab/api/settings?1655197486317', version='HTTP/1.1', remote_ip='::1')
    Traceback (most recent call last):
      File "/home/k/kimpson/bin/conda/envs/workhorse/lib/python3.7/site-packages/tornado/web.py", line 1704, in _execute
        result = await result
    tornado.iostream.StreamClosedError: Stream is closed
[I 2022-06-14 10:04:50.256 LabApp] Build is up to date
[I 2022-06-14 10:04:56.702 ServerApp] Kernel started: e83b10e3-f0f4-4818-bf0f-af3f4520a3f3
[I 2022-06-14 10:04:56.705 ServerApp] Kernel started: 406b89bf-6704-4f5c-81a6-a49361f6aafd
[I 2022-06-14 10:04:56.707 ServerApp] Kernel started: 9d5c4c84-d95d-45be-9c9f-212a7cc53f5a
[I 2022-06-14 10:04:56.711 ServerApp] Kernel started: db9d49e7-b2e4-4643-b27c-3fa1902eaaaf
[I 2022-06-14 10:04:56.714 ServerApp] Kernel started: 9aac199e-45ec-4a45-9eb8-e3bf34a8a587
[I 2022-06-14 10:04:56.717 ServerApp] Kernel started: 4dc1853a-044e-4c3a-a63f-0c24d583e060
[I 2022-06-14 10:05:03.380 ServerApp] Starting buffering for 4dc1853a-044e-4c3a-a63f-0c24d583e060:fdd37e63-930f-4829-abf3-3114c1638d34
[I 2022-06-14 10:09:00.039 ServerApp] Saving file at /jupyter_notebooks/paper/1b.Precipitation_timeseries.ipynb
[I 2022-06-14 10:10:47.843 ServerApp] Saving file at /jupyter_notebooks/paper/1b.Precipitation_timeseries.ipynb
[I 2022-06-14 10:10:59.155 ServerApp] Saving file at /jupyter_notebooks/paper/1a.Temperature_timeseries.ipynb
[I 2022-06-14 10:12:10.963 ServerApp] Saving file at /jupyter_notebooks/paper/1a.Temperature_timeseries.ipynb
[I 2022-06-14 12:32:28.631 ServerApp] Saving file at /jupyter_notebooks/paper/1a.Temperature_timeseries.ipynb
[I 2022-06-14 12:34:33.638 ServerApp] Saving file at /jupyter_notebooks/paper/1a.Temperature_timeseries.ipynb
[I 2022-06-14 12:40:31.873 ServerApp] Saving file at /jupyter_notebooks/paper/1b.Precipitation_timeseries.ipynb
[I 2022-06-14 13:32:44.081 ServerApp] Copying jupyter_notebooks/2.GlobalMap.ipynb to /jupyter_notebooks
[I 2022-06-14 13:33:12.669 ServerApp] Starting buffering for 406b89bf-6704-4f5c-81a6-a49361f6aafd:3dc0ded3-a4fc-496d-b17a-15adde42c047
[I 2022-06-14 13:33:13.437 ServerApp] Starting buffering for 9d5c4c84-d95d-45be-9c9f-212a7cc53f5a:7fdf4e83-37b7-411e-9019-bf9d89d9a725
[I 2022-06-14 13:33:13.448 ServerApp] Kernel started: f6d2ed52-7440-4378-9ed5-d917f03e7f9b
[I 2022-06-14 13:33:14.761 ServerApp] Starting buffering for 9aac199e-45ec-4a45-9eb8-e3bf34a8a587:dddd45fe-6be2-4741-9c40-4916de398cf4
[I 2022-06-14 13:33:15.162 ServerApp] Starting buffering for e83b10e3-f0f4-4818-bf0f-af3f4520a3f3:bebc96ea-e2c3-450d-aa1a-cfed4019f671
[I 2022-06-14 13:33:15.873 ServerApp] Starting buffering for db9d49e7-b2e4-4643-b27c-3fa1902eaaaf:9b4e4388-dcf6-4633-9085-270e0be1cd8e
[I 2022-06-14 13:35:05.515 ServerApp] Saving file at /jupyter_notebooks/paper/2a.Temperature_globalmap.ipynb
[I 2022-06-14 13:37:08.692 ServerApp] Saving file at /jupyter_notebooks/paper/2a.Temperature_globalmap.ipynb
[I 2022-06-14 13:39:11.081 ServerApp] Saving file at /jupyter_notebooks/paper/2a.Temperature_globalmap.ipynb
[I 2022-06-14 13:40:22.790 ServerApp] Saving file at /jupyter_notebooks/paper/2a.Temperature_globalmap.ipynb
[I 2022-06-14 13:40:28.064 ServerApp] Saving file at /jupyter_notebooks/paper/2a.Temperature_globalmap.ipynb
[I 2022-06-14 13:41:57.896 ServerApp] Saving file at /jupyter_notebooks/paper/2a.Temperature_globalmap.ipynb
[I 2022-06-14 13:42:12.504 ServerApp] Saving file at /jupyter_notebooks/paper/2a.Temperature_globalmap.ipynb
[I 2022-06-14 13:44:14.673 ServerApp] Saving file at /jupyter_notebooks/paper/2a.Temperature_globalmap.ipynb
[I 2022-06-14 13:44:22.932 ServerApp] Saving file at /jupyter_notebooks/paper/2a.Temperature_globalmap.ipynb
[I 2022-06-14 13:44:49.131 ServerApp] Saving file at /jupyter_notebooks/paper/2a.Temperature_globalmap.ipynb
[I 2022-06-14 13:45:12.847 ServerApp] Saving file at /jupyter_notebooks/paper/2a.Temperature_globalmap.ipynb
[I 2022-06-14 13:46:52.470 ServerApp] Saving file at /jupyter_notebooks/paper/2a.Temperature_globalmap.ipynb
[I 2022-06-14 13:46:57.745 ServerApp] Saving file at /jupyter_notebooks/paper/2a.Temperature_globalmap.ipynb
[I 2022-06-14 13:47:55.894 ServerApp] Saving file at /jupyter_notebooks/paper/2a.Temperature_globalmap.ipynb
[I 2022-06-14 13:48:43.629 ServerApp] Saving file at /jupyter_notebooks/paper/2a.Temperature_globalmap.ipynb
[I 2022-06-14 13:49:09.052 ServerApp] Saving file at /jupyter_notebooks/paper/2a.Temperature_globalmap.ipynb
[I 2022-06-14 13:50:04.637 ServerApp] Saving file at /jupyter_notebooks/paper/2a.Temperature_globalmap.ipynb
[I 2022-06-14 13:52:06.989 ServerApp] Saving file at /jupyter_notebooks/paper/2a.Temperature_globalmap.ipynb
[I 2022-06-14 13:54:09.944 ServerApp] Saving file at /jupyter_notebooks/paper/2a.Temperature_globalmap.ipynb
[I 2022-06-14 13:54:52.822 ServerApp] Saving file at /jupyter_notebooks/paper/2a.Temperature_globalmap.ipynb
[I 2022-06-14 13:56:04.168 ServerApp] Saving file at /jupyter_notebooks/paper/2a.Temperature_globalmap.ipynb
[I 2022-06-14 13:58:06.449 ServerApp] Saving file at /jupyter_notebooks/paper/2a.Temperature_globalmap.ipynb
[I 2022-06-14 13:59:40.412 ServerApp] Kernel started: 6d665d7c-f556-4438-a1f9-d614a2533813
[I 2022-06-14 14:00:08.840 ServerApp] Saving file at /jupyter_notebooks/paper/2a.Temperature_globalmap.ipynb
[I 2022-06-14 14:02:11.341 ServerApp] Saving file at /jupyter_notebooks/paper/2a.Temperature_globalmap.ipynb
[I 2022-06-14 14:04:14.127 ServerApp] Saving file at /jupyter_notebooks/paper/2a.Temperature_globalmap.ipynb
[I 2022-06-14 14:06:16.777 ServerApp] Saving file at /jupyter_notebooks/paper/2a.Temperature_globalmap.ipynb
[I 2022-06-14 14:08:19.416 ServerApp] Saving file at /jupyter_notebooks/paper/2a.Temperature_globalmap.ipynb
[I 2022-06-14 14:10:22.161 ServerApp] Saving file at /jupyter_notebooks/paper/2a.Temperature_globalmap.ipynb
[I 2022-06-14 14:12:24.760 ServerApp] Saving file at /jupyter_notebooks/paper/2a.Temperature_globalmap.ipynb
[I 2022-06-14 14:16:28.731 ServerApp] Saving file at /jupyter_notebooks/paper/2a.Temperature_globalmap.ipynb
[I 2022-06-14 14:18:33.880 ServerApp] Saving file at /jupyter_notebooks/paper/2a.Temperature_globalmap.ipynb
[I 2022-06-14 14:50:59.382 ServerApp] Saving file at /jupyter_notebooks/paper/2a.Temperature_globalmap.ipynb
[I 2022-06-14 15:01:44.334 ServerApp] Saving file at /jupyter_notebooks/paper/2a.Temperature_globalmap.ipynb
[I 2022-06-14 15:18:32.708 ServerApp] Saving file at /jupyter_notebooks/paper/2a.Temperature_globalmap.ipynb
[E 2022-06-14 15:18:37.795 ServerApp] Error while saving file: jupyter_notebooks/paper/2a.Temperature_globalmap.ipynb database is locked
    Traceback (most recent call last):
      File "/home/k/kimpson/bin/conda/envs/workhorse/lib/python3.7/site-packages/jupyter_server/services/contents/filemanager.py", line 427, in save
      File "/home/k/kimpson/bin/conda/envs/workhorse/lib/python3.7/site-packages/jupyter_server/services/contents/manager.py", line 644, in check_and_sign
      File "/home/k/kimpson/bin/conda/envs/workhorse/lib/python3.7/site-packages/nbformat/sign.py", line 482, in sign
      File "/home/k/kimpson/bin/conda/envs/workhorse/lib/python3.7/site-packages/nbformat/sign.py", line 224, in store_signature
      File "/home/k/kimpson/bin/conda/envs/workhorse/lib/python3.7/site-packages/nbformat/sign.py", line 255, in check_signature
    sqlite3.OperationalError: database is locked
[W 2022-06-14 15:18:37.804 ServerApp] 500 PUT /api/contents/jupyter_notebooks/paper/2a.Temperature_globalmap.ipynb?1655216306531 (::1): Unexpected error while saving file: jupyter_notebooks/paper/2a.Temperature_globalmap.ipynb database is locked
[W 2022-06-14 15:18:37.805 ServerApp] Unexpected error while saving file: jupyter_notebooks/paper/2a.Temperature_globalmap.ipynb database is locked
[E 2022-06-14 15:18:37.806 ServerApp] {
      "Host": "localhost:8885",
      "Accept": "*/*",
      "Referer": "http://localhost:8885/lab/tree/jupyter_notebooks/paper/2a.Temperature_globalmap.ipynb",
      "User-Agent": "Mozilla/5.0 (Macintosh; Intel Mac OS X 10_15_7) AppleWebKit/537.36 (KHTML, like Gecko) Chrome/100.0.4896.79 Safari/537.36"
    }
[E 2022-06-14 15:18:37.807 ServerApp] 500 PUT /api/contents/jupyter_notebooks/paper/2a.Temperature_globalmap.ipynb?1655216306531 (::1) 11065.47ms referer=http://localhost:8885/lab/tree/jupyter_notebooks/paper/2a.Temperature_globalmap.ipynb
[I 2022-06-14 15:21:31.000 ServerApp] Saving file at /jupyter_notebooks/paper/2a.Temperature_globalmap.ipynb
[E 2022-06-14 15:21:36.091 ServerApp] Error while saving file: jupyter_notebooks/paper/2a.Temperature_globalmap.ipynb database is locked
    Traceback (most recent call last):
      File "/home/k/kimpson/bin/conda/envs/workhorse/lib/python3.7/site-packages/jupyter_server/services/contents/filemanager.py", line 427, in save
      File "/home/k/kimpson/bin/conda/envs/workhorse/lib/python3.7/site-packages/jupyter_server/services/contents/manager.py", line 644, in check_and_sign
      File "/home/k/kimpson/bin/conda/envs/workhorse/lib/python3.7/site-packages/nbformat/sign.py", line 482, in sign
      File "/home/k/kimpson/bin/conda/envs/workhorse/lib/python3.7/site-packages/nbformat/sign.py", line 224, in store_signature
      File "/home/k/kimpson/bin/conda/envs/workhorse/lib/python3.7/site-packages/nbformat/sign.py", line 255, in check_signature
    sqlite3.OperationalError: database is locked
[W 2022-06-14 15:21:36.107 ServerApp] 500 PUT /api/contents/jupyter_notebooks/paper/2a.Temperature_globalmap.ipynb?1655216485370 (::1): Unexpected error while saving file: jupyter_notebooks/paper/2a.Temperature_globalmap.ipynb database is locked
[W 2022-06-14 15:21:36.108 ServerApp] Unexpected error while saving file: jupyter_notebooks/paper/2a.Temperature_globalmap.ipynb database is locked
[E 2022-06-14 15:21:36.109 ServerApp] {
      "Host": "localhost:8885",
      "Accept": "*/*",
      "Referer": "http://localhost:8885/lab/tree/jupyter_notebooks/paper/2a.Temperature_globalmap.ipynb",
      "User-Agent": "Mozilla/5.0 (Macintosh; Intel Mac OS X 10_15_7) AppleWebKit/537.36 (KHTML, like Gecko) Chrome/100.0.4896.79 Safari/537.36"
    }
[E 2022-06-14 15:21:36.109 ServerApp] 500 PUT /api/contents/jupyter_notebooks/paper/2a.Temperature_globalmap.ipynb?1655216485370 (::1) 10529.26ms referer=http://localhost:8885/lab/tree/jupyter_notebooks/paper/2a.Temperature_globalmap.ipynb
[I 2022-06-14 15:23:30.988 ServerApp] Saving file at /jupyter_notebooks/paper/2a.Temperature_globalmap.ipynb
[E 2022-06-14 15:23:36.071 ServerApp] Error while saving file: jupyter_notebooks/paper/2a.Temperature_globalmap.ipynb database is locked
    Traceback (most recent call last):
      File "/home/k/kimpson/bin/conda/envs/workhorse/lib/python3.7/site-packages/jupyter_server/services/contents/filemanager.py", line 427, in save
      File "/home/k/kimpson/bin/conda/envs/workhorse/lib/python3.7/site-packages/jupyter_server/services/contents/manager.py", line 644, in check_and_sign
      File "/home/k/kimpson/bin/conda/envs/workhorse/lib/python3.7/site-packages/nbformat/sign.py", line 482, in sign
      File "/home/k/kimpson/bin/conda/envs/workhorse/lib/python3.7/site-packages/nbformat/sign.py", line 224, in store_signature
      File "/home/k/kimpson/bin/conda/envs/workhorse/lib/python3.7/site-packages/nbformat/sign.py", line 255, in check_signature
    sqlite3.OperationalError: database is locked
[W 2022-06-14 15:23:36.088 ServerApp] 500 PUT /api/contents/jupyter_notebooks/paper/2a.Temperature_globalmap.ipynb?1655216605685 (::1): Unexpected error while saving file: jupyter_notebooks/paper/2a.Temperature_globalmap.ipynb database is locked
[W 2022-06-14 15:23:36.089 ServerApp] Unexpected error while saving file: jupyter_notebooks/paper/2a.Temperature_globalmap.ipynb database is locked
[E 2022-06-14 15:23:36.090 ServerApp] {
      "Host": "localhost:8885",
      "Accept": "*/*",
      "Referer": "http://localhost:8885/lab/tree/jupyter_notebooks/paper/2a.Temperature_globalmap.ipynb",
      "User-Agent": "Mozilla/5.0 (Macintosh; Intel Mac OS X 10_15_7) AppleWebKit/537.36 (KHTML, like Gecko) Chrome/100.0.4896.79 Safari/537.36"
    }
[E 2022-06-14 15:23:36.090 ServerApp] 500 PUT /api/contents/jupyter_notebooks/paper/2a.Temperature_globalmap.ipynb?1655216605685 (::1) 9971.60ms referer=http://localhost:8885/lab/tree/jupyter_notebooks/paper/2a.Temperature_globalmap.ipynb
[I 2022-06-14 15:25:30.734 ServerApp] Saving file at /jupyter_notebooks/paper/2a.Temperature_globalmap.ipynb
[E 2022-06-14 15:25:35.818 ServerApp] Error while saving file: jupyter_notebooks/paper/2a.Temperature_globalmap.ipynb database is locked
    Traceback (most recent call last):
      File "/home/k/kimpson/bin/conda/envs/workhorse/lib/python3.7/site-packages/jupyter_server/services/contents/filemanager.py", line 427, in save
      File "/home/k/kimpson/bin/conda/envs/workhorse/lib/python3.7/site-packages/jupyter_server/services/contents/manager.py", line 644, in check_and_sign
      File "/home/k/kimpson/bin/conda/envs/workhorse/lib/python3.7/site-packages/nbformat/sign.py", line 482, in sign
      File "/home/k/kimpson/bin/conda/envs/workhorse/lib/python3.7/site-packages/nbformat/sign.py", line 224, in store_signature
      File "/home/k/kimpson/bin/conda/envs/workhorse/lib/python3.7/site-packages/nbformat/sign.py", line 255, in check_signature
    sqlite3.OperationalError: database is locked
[W 2022-06-14 15:25:35.834 ServerApp] 500 PUT /api/contents/jupyter_notebooks/paper/2a.Temperature_globalmap.ipynb?1655216725761 (::1): Unexpected error while saving file: jupyter_notebooks/paper/2a.Temperature_globalmap.ipynb database is locked
[W 2022-06-14 15:25:35.834 ServerApp] Unexpected error while saving file: jupyter_notebooks/paper/2a.Temperature_globalmap.ipynb database is locked
[E 2022-06-14 15:25:35.835 ServerApp] {
      "Host": "localhost:8885",
      "Accept": "*/*",
      "Referer": "http://localhost:8885/lab/tree/jupyter_notebooks/paper/2a.Temperature_globalmap.ipynb",
      "User-Agent": "Mozilla/5.0 (Macintosh; Intel Mac OS X 10_15_7) AppleWebKit/537.36 (KHTML, like Gecko) Chrome/100.0.4896.79 Safari/537.36"
    }
[E 2022-06-14 15:25:35.836 ServerApp] 500 PUT /api/contents/jupyter_notebooks/paper/2a.Temperature_globalmap.ipynb?1655216725761 (::1) 9797.38ms referer=http://localhost:8885/lab/tree/jupyter_notebooks/paper/2a.Temperature_globalmap.ipynb
[I 2022-06-14 15:28:31.007 ServerApp] Saving file at /jupyter_notebooks/paper/2a.Temperature_globalmap.ipynb
[E 2022-06-14 15:28:36.093 ServerApp] Error while saving file: jupyter_notebooks/paper/2a.Temperature_globalmap.ipynb database is locked
    Traceback (most recent call last):
      File "/home/k/kimpson/bin/conda/envs/workhorse/lib/python3.7/site-packages/jupyter_server/services/contents/filemanager.py", line 427, in save
      File "/home/k/kimpson/bin/conda/envs/workhorse/lib/python3.7/site-packages/jupyter_server/services/contents/manager.py", line 644, in check_and_sign
      File "/home/k/kimpson/bin/conda/envs/workhorse/lib/python3.7/site-packages/nbformat/sign.py", line 482, in sign
      File "/home/k/kimpson/bin/conda/envs/workhorse/lib/python3.7/site-packages/nbformat/sign.py", line 224, in store_signature
      File "/home/k/kimpson/bin/conda/envs/workhorse/lib/python3.7/site-packages/nbformat/sign.py", line 255, in check_signature
    sqlite3.OperationalError: database is locked
[W 2022-06-14 15:28:36.109 ServerApp] 500 PUT /api/contents/jupyter_notebooks/paper/2a.Temperature_globalmap.ipynb?1655216906049 (::1): Unexpected error while saving file: jupyter_notebooks/paper/2a.Temperature_globalmap.ipynb database is locked
[W 2022-06-14 15:28:36.110 ServerApp] Unexpected error while saving file: jupyter_notebooks/paper/2a.Temperature_globalmap.ipynb database is locked
[E 2022-06-14 15:28:36.111 ServerApp] {
      "Host": "localhost:8885",
      "Accept": "*/*",
      "Referer": "http://localhost:8885/lab/tree/jupyter_notebooks/paper/2a.Temperature_globalmap.ipynb",
      "User-Agent": "Mozilla/5.0 (Macintosh; Intel Mac OS X 10_15_7) AppleWebKit/537.36 (KHTML, like Gecko) Chrome/100.0.4896.79 Safari/537.36"
    }
[E 2022-06-14 15:28:36.112 ServerApp] 500 PUT /api/contents/jupyter_notebooks/paper/2a.Temperature_globalmap.ipynb?1655216906049 (::1) 9813.77ms referer=http://localhost:8885/lab/tree/jupyter_notebooks/paper/2a.Temperature_globalmap.ipynb
[I 2022-06-14 15:30:32.437 ServerApp] Saving file at /jupyter_notebooks/paper/2a.Temperature_globalmap.ipynb
[E 2022-06-14 15:30:37.520 ServerApp] Error while saving file: jupyter_notebooks/paper/2a.Temperature_globalmap.ipynb database is locked
    Traceback (most recent call last):
      File "/home/k/kimpson/bin/conda/envs/workhorse/lib/python3.7/site-packages/jupyter_server/services/contents/filemanager.py", line 427, in save
      File "/home/k/kimpson/bin/conda/envs/workhorse/lib/python3.7/site-packages/jupyter_server/services/contents/manager.py", line 644, in check_and_sign
      File "/home/k/kimpson/bin/conda/envs/workhorse/lib/python3.7/site-packages/nbformat/sign.py", line 482, in sign
      File "/home/k/kimpson/bin/conda/envs/workhorse/lib/python3.7/site-packages/nbformat/sign.py", line 224, in store_signature
      File "/home/k/kimpson/bin/conda/envs/workhorse/lib/python3.7/site-packages/nbformat/sign.py", line 255, in check_signature
    sqlite3.OperationalError: database is locked
[W 2022-06-14 15:30:37.537 ServerApp] 500 PUT /api/contents/jupyter_notebooks/paper/2a.Temperature_globalmap.ipynb?1655217026845 (::1): Unexpected error while saving file: jupyter_notebooks/paper/2a.Temperature_globalmap.ipynb database is locked
[W 2022-06-14 15:30:37.537 ServerApp] Unexpected error while saving file: jupyter_notebooks/paper/2a.Temperature_globalmap.ipynb database is locked
[E 2022-06-14 15:30:37.538 ServerApp] {
      "Host": "localhost:8885",
      "Accept": "*/*",
      "Referer": "http://localhost:8885/lab/tree/jupyter_notebooks/paper/2a.Temperature_globalmap.ipynb",
      "User-Agent": "Mozilla/5.0 (Macintosh; Intel Mac OS X 10_15_7) AppleWebKit/537.36 (KHTML, like Gecko) Chrome/100.0.4896.79 Safari/537.36"
    }
[E 2022-06-14 15:30:37.539 ServerApp] 500 PUT /api/contents/jupyter_notebooks/paper/2a.Temperature_globalmap.ipynb?1655217026845 (::1) 10456.84ms referer=http://localhost:8885/lab/tree/jupyter_notebooks/paper/2a.Temperature_globalmap.ipynb
[I 2022-06-14 15:33:32.863 ServerApp] Saving file at /jupyter_notebooks/paper/2a.Temperature_globalmap.ipynb
[E 2022-06-14 15:33:37.955 ServerApp] Error while saving file: jupyter_notebooks/paper/2a.Temperature_globalmap.ipynb database is locked
    Traceback (most recent call last):
      File "/home/k/kimpson/bin/conda/envs/workhorse/lib/python3.7/site-packages/jupyter_server/services/contents/filemanager.py", line 427, in save
      File "/home/k/kimpson/bin/conda/envs/workhorse/lib/python3.7/site-packages/jupyter_server/services/contents/manager.py", line 644, in check_and_sign
      File "/home/k/kimpson/bin/conda/envs/workhorse/lib/python3.7/site-packages/nbformat/sign.py", line 482, in sign
      File "/home/k/kimpson/bin/conda/envs/workhorse/lib/python3.7/site-packages/nbformat/sign.py", line 224, in store_signature
      File "/home/k/kimpson/bin/conda/envs/workhorse/lib/python3.7/site-packages/nbformat/sign.py", line 255, in check_signature
    sqlite3.OperationalError: database is locked
[W 2022-06-14 15:33:37.970 ServerApp] 500 PUT /api/contents/jupyter_notebooks/paper/2a.Temperature_globalmap.ipynb?1655217206274 (::1): Unexpected error while saving file: jupyter_notebooks/paper/2a.Temperature_globalmap.ipynb database is locked
[W 2022-06-14 15:33:37.971 ServerApp] Unexpected error while saving file: jupyter_notebooks/paper/2a.Temperature_globalmap.ipynb database is locked
[E 2022-06-14 15:33:37.972 ServerApp] {
      "Host": "localhost:8885",
      "Accept": "*/*",
      "Referer": "http://localhost:8885/lab/tree/jupyter_notebooks/paper/2a.Temperature_globalmap.ipynb",
      "User-Agent": "Mozilla/5.0 (Macintosh; Intel Mac OS X 10_15_7) AppleWebKit/537.36 (KHTML, like Gecko) Chrome/100.0.4896.79 Safari/537.36"
    }
[E 2022-06-14 15:33:37.972 ServerApp] 500 PUT /api/contents/jupyter_notebooks/paper/2a.Temperature_globalmap.ipynb?1655217206274 (::1) 11531.69ms referer=http://localhost:8885/lab/tree/jupyter_notebooks/paper/2a.Temperature_globalmap.ipynb
[I 2022-06-14 15:35:33.051 ServerApp] Saving file at /jupyter_notebooks/paper/2a.Temperature_globalmap.ipynb
[E 2022-06-14 15:35:38.139 ServerApp] Error while saving file: jupyter_notebooks/paper/2a.Temperature_globalmap.ipynb database is locked
    Traceback (most recent call last):
      File "/home/k/kimpson/bin/conda/envs/workhorse/lib/python3.7/site-packages/jupyter_server/services/contents/filemanager.py", line 427, in save
      File "/home/k/kimpson/bin/conda/envs/workhorse/lib/python3.7/site-packages/jupyter_server/services/contents/manager.py", line 644, in check_and_sign
      File "/home/k/kimpson/bin/conda/envs/workhorse/lib/python3.7/site-packages/nbformat/sign.py", line 482, in sign
      File "/home/k/kimpson/bin/conda/envs/workhorse/lib/python3.7/site-packages/nbformat/sign.py", line 224, in store_signature
      File "/home/k/kimpson/bin/conda/envs/workhorse/lib/python3.7/site-packages/nbformat/sign.py", line 255, in check_signature
    sqlite3.OperationalError: database is locked
[W 2022-06-14 15:35:38.156 ServerApp] 500 PUT /api/contents/jupyter_notebooks/paper/2a.Temperature_globalmap.ipynb?1655217327461 (::1): Unexpected error while saving file: jupyter_notebooks/paper/2a.Temperature_globalmap.ipynb database is locked
[W 2022-06-14 15:35:38.157 ServerApp] Unexpected error while saving file: jupyter_notebooks/paper/2a.Temperature_globalmap.ipynb database is locked
[E 2022-06-14 15:35:38.158 ServerApp] {
      "Host": "localhost:8885",
      "Accept": "*/*",
      "Referer": "http://localhost:8885/lab/tree/jupyter_notebooks/paper/2a.Temperature_globalmap.ipynb",
      "User-Agent": "Mozilla/5.0 (Macintosh; Intel Mac OS X 10_15_7) AppleWebKit/537.36 (KHTML, like Gecko) Chrome/100.0.4896.79 Safari/537.36"
    }
[E 2022-06-14 15:35:38.159 ServerApp] 500 PUT /api/contents/jupyter_notebooks/paper/2a.Temperature_globalmap.ipynb?1655217327461 (::1) 10530.28ms referer=http://localhost:8885/lab/tree/jupyter_notebooks/paper/2a.Temperature_globalmap.ipynb
[I 2022-06-14 15:38:30.882 ServerApp] Saving file at /jupyter_notebooks/paper/2a.Temperature_globalmap.ipynb
[E 2022-06-14 15:38:35.972 ServerApp] Error while saving file: jupyter_notebooks/paper/2a.Temperature_globalmap.ipynb database is locked
    Traceback (most recent call last):
      File "/home/k/kimpson/bin/conda/envs/workhorse/lib/python3.7/site-packages/jupyter_server/services/contents/filemanager.py", line 427, in save
      File "/home/k/kimpson/bin/conda/envs/workhorse/lib/python3.7/site-packages/jupyter_server/services/contents/manager.py", line 644, in check_and_sign
      File "/home/k/kimpson/bin/conda/envs/workhorse/lib/python3.7/site-packages/nbformat/sign.py", line 482, in sign
      File "/home/k/kimpson/bin/conda/envs/workhorse/lib/python3.7/site-packages/nbformat/sign.py", line 224, in store_signature
      File "/home/k/kimpson/bin/conda/envs/workhorse/lib/python3.7/site-packages/nbformat/sign.py", line 255, in check_signature
    sqlite3.OperationalError: database is locked
[W 2022-06-14 15:38:35.988 ServerApp] 500 PUT /api/contents/jupyter_notebooks/paper/2a.Temperature_globalmap.ipynb?1655217505301 (::1): Unexpected error while saving file: jupyter_notebooks/paper/2a.Temperature_globalmap.ipynb database is locked
[W 2022-06-14 15:38:35.989 ServerApp] Unexpected error while saving file: jupyter_notebooks/paper/2a.Temperature_globalmap.ipynb database is locked
[E 2022-06-14 15:38:35.991 ServerApp] {
      "Host": "localhost:8885",
      "Accept": "*/*",
      "Referer": "http://localhost:8885/lab/tree/jupyter_notebooks/paper/2a.Temperature_globalmap.ipynb",
      "User-Agent": "Mozilla/5.0 (Macintosh; Intel Mac OS X 10_15_7) AppleWebKit/537.36 (KHTML, like Gecko) Chrome/100.0.4896.79 Safari/537.36"
    }
[E 2022-06-14 15:38:35.991 ServerApp] 500 PUT /api/contents/jupyter_notebooks/paper/2a.Temperature_globalmap.ipynb?1655217505301 (::1) 10512.19ms referer=http://localhost:8885/lab/tree/jupyter_notebooks/paper/2a.Temperature_globalmap.ipynb
[I 2022-06-14 15:40:32.426 ServerApp] Saving file at /jupyter_notebooks/paper/2a.Temperature_globalmap.ipynb
[E 2022-06-14 15:40:37.516 ServerApp] Error while saving file: jupyter_notebooks/paper/2a.Temperature_globalmap.ipynb database is locked
    Traceback (most recent call last):
      File "/home/k/kimpson/bin/conda/envs/workhorse/lib/python3.7/site-packages/jupyter_server/services/contents/filemanager.py", line 427, in save
      File "/home/k/kimpson/bin/conda/envs/workhorse/lib/python3.7/site-packages/jupyter_server/services/contents/manager.py", line 644, in check_and_sign
      File "/home/k/kimpson/bin/conda/envs/workhorse/lib/python3.7/site-packages/nbformat/sign.py", line 482, in sign
      File "/home/k/kimpson/bin/conda/envs/workhorse/lib/python3.7/site-packages/nbformat/sign.py", line 224, in store_signature
      File "/home/k/kimpson/bin/conda/envs/workhorse/lib/python3.7/site-packages/nbformat/sign.py", line 255, in check_signature
    sqlite3.OperationalError: database is locked
[W 2022-06-14 15:40:37.532 ServerApp] 500 PUT /api/contents/jupyter_notebooks/paper/2a.Temperature_globalmap.ipynb?1655217625695 (::1): Unexpected error while saving file: jupyter_notebooks/paper/2a.Temperature_globalmap.ipynb database is locked
[W 2022-06-14 15:40:37.533 ServerApp] Unexpected error while saving file: jupyter_notebooks/paper/2a.Temperature_globalmap.ipynb database is locked
[E 2022-06-14 15:40:37.535 ServerApp] {
      "Host": "localhost:8885",
      "Accept": "*/*",
      "Referer": "http://localhost:8885/lab/tree/jupyter_notebooks/paper/2a.Temperature_globalmap.ipynb",
      "User-Agent": "Mozilla/5.0 (Macintosh; Intel Mac OS X 10_15_7) AppleWebKit/537.36 (KHTML, like Gecko) Chrome/100.0.4896.79 Safari/537.36"
    }
[E 2022-06-14 15:40:37.535 ServerApp] 500 PUT /api/contents/jupyter_notebooks/paper/2a.Temperature_globalmap.ipynb?1655217625695 (::1) 11662.82ms referer=http://localhost:8885/lab/tree/jupyter_notebooks/paper/2a.Temperature_globalmap.ipynb
[I 2022-06-14 15:42:34.899 ServerApp] Saving file at /jupyter_notebooks/paper/2a.Temperature_globalmap.ipynb
[E 2022-06-14 15:42:39.990 ServerApp] Error while saving file: jupyter_notebooks/paper/2a.Temperature_globalmap.ipynb database is locked
    Traceback (most recent call last):
      File "/home/k/kimpson/bin/conda/envs/workhorse/lib/python3.7/site-packages/jupyter_server/services/contents/filemanager.py", line 427, in save
      File "/home/k/kimpson/bin/conda/envs/workhorse/lib/python3.7/site-packages/jupyter_server/services/contents/manager.py", line 644, in check_and_sign
      File "/home/k/kimpson/bin/conda/envs/workhorse/lib/python3.7/site-packages/nbformat/sign.py", line 482, in sign
      File "/home/k/kimpson/bin/conda/envs/workhorse/lib/python3.7/site-packages/nbformat/sign.py", line 224, in store_signature
      File "/home/k/kimpson/bin/conda/envs/workhorse/lib/python3.7/site-packages/nbformat/sign.py", line 255, in check_signature
    sqlite3.OperationalError: database is locked
[W 2022-06-14 15:42:40.006 ServerApp] 500 PUT /api/contents/jupyter_notebooks/paper/2a.Temperature_globalmap.ipynb?1655217748408 (::1): Unexpected error while saving file: jupyter_notebooks/paper/2a.Temperature_globalmap.ipynb database is locked
[W 2022-06-14 15:42:40.007 ServerApp] Unexpected error while saving file: jupyter_notebooks/paper/2a.Temperature_globalmap.ipynb database is locked
[E 2022-06-14 15:42:40.008 ServerApp] {
      "Host": "localhost:8885",
      "Accept": "*/*",
      "Referer": "http://localhost:8885/lab/tree/jupyter_notebooks/paper/2a.Temperature_globalmap.ipynb",
      "User-Agent": "Mozilla/5.0 (Macintosh; Intel Mac OS X 10_15_7) AppleWebKit/537.36 (KHTML, like Gecko) Chrome/100.0.4896.79 Safari/537.36"
    }
[E 2022-06-14 15:42:40.008 ServerApp] 500 PUT /api/contents/jupyter_notebooks/paper/2a.Temperature_globalmap.ipynb?1655217748408 (::1) 11436.14ms referer=http://localhost:8885/lab/tree/jupyter_notebooks/paper/2a.Temperature_globalmap.ipynb
[I 2022-06-14 15:44:35.340 ServerApp] Saving file at /jupyter_notebooks/paper/2a.Temperature_globalmap.ipynb
[E 2022-06-14 15:44:40.433 ServerApp] Error while saving file: jupyter_notebooks/paper/2a.Temperature_globalmap.ipynb database is locked
    Traceback (most recent call last):
      File "/home/k/kimpson/bin/conda/envs/workhorse/lib/python3.7/site-packages/jupyter_server/services/contents/filemanager.py", line 427, in save
      File "/home/k/kimpson/bin/conda/envs/workhorse/lib/python3.7/site-packages/jupyter_server/services/contents/manager.py", line 644, in check_and_sign
      File "/home/k/kimpson/bin/conda/envs/workhorse/lib/python3.7/site-packages/nbformat/sign.py", line 482, in sign
      File "/home/k/kimpson/bin/conda/envs/workhorse/lib/python3.7/site-packages/nbformat/sign.py", line 224, in store_signature
      File "/home/k/kimpson/bin/conda/envs/workhorse/lib/python3.7/site-packages/nbformat/sign.py", line 255, in check_signature
    sqlite3.OperationalError: database is locked
[W 2022-06-14 15:44:40.451 ServerApp] 500 PUT /api/contents/jupyter_notebooks/paper/2a.Temperature_globalmap.ipynb?1655217868773 (::1): Unexpected error while saving file: jupyter_notebooks/paper/2a.Temperature_globalmap.ipynb database is locked
[W 2022-06-14 15:44:40.452 ServerApp] Unexpected error while saving file: jupyter_notebooks/paper/2a.Temperature_globalmap.ipynb database is locked
[E 2022-06-14 15:44:40.455 ServerApp] {
      "Host": "localhost:8885",
      "Accept": "*/*",
      "Referer": "http://localhost:8885/lab/tree/jupyter_notebooks/paper/2a.Temperature_globalmap.ipynb",
      "User-Agent": "Mozilla/5.0 (Macintosh; Intel Mac OS X 10_15_7) AppleWebKit/537.36 (KHTML, like Gecko) Chrome/100.0.4896.79 Safari/537.36"
    }
[E 2022-06-14 15:44:40.455 ServerApp] 500 PUT /api/contents/jupyter_notebooks/paper/2a.Temperature_globalmap.ipynb?1655217868773 (::1) 11458.09ms referer=http://localhost:8885/lab/tree/jupyter_notebooks/paper/2a.Temperature_globalmap.ipynb
[I 2022-06-14 15:46:34.178 ServerApp] Saving file at /jupyter_notebooks/paper/2a.Temperature_globalmap.ipynb
[E 2022-06-14 15:46:39.266 ServerApp] Error while saving file: jupyter_notebooks/paper/2a.Temperature_globalmap.ipynb database is locked
    Traceback (most recent call last):
      File "/home/k/kimpson/bin/conda/envs/workhorse/lib/python3.7/site-packages/jupyter_server/services/contents/filemanager.py", line 427, in save
      File "/home/k/kimpson/bin/conda/envs/workhorse/lib/python3.7/site-packages/jupyter_server/services/contents/manager.py", line 644, in check_and_sign
      File "/home/k/kimpson/bin/conda/envs/workhorse/lib/python3.7/site-packages/nbformat/sign.py", line 482, in sign
      File "/home/k/kimpson/bin/conda/envs/workhorse/lib/python3.7/site-packages/nbformat/sign.py", line 224, in store_signature
      File "/home/k/kimpson/bin/conda/envs/workhorse/lib/python3.7/site-packages/nbformat/sign.py", line 255, in check_signature
    sqlite3.OperationalError: database is locked
[W 2022-06-14 15:46:39.283 ServerApp] 500 PUT /api/contents/jupyter_notebooks/paper/2a.Temperature_globalmap.ipynb?1655217989597 (::1): Unexpected error while saving file: jupyter_notebooks/paper/2a.Temperature_globalmap.ipynb database is locked
[W 2022-06-14 15:46:39.284 ServerApp] Unexpected error while saving file: jupyter_notebooks/paper/2a.Temperature_globalmap.ipynb database is locked
[E 2022-06-14 15:46:39.285 ServerApp] {
      "Host": "localhost:8885",
      "Accept": "*/*",
      "Referer": "http://localhost:8885/lab/tree/jupyter_notebooks/paper/2a.Temperature_globalmap.ipynb",
      "User-Agent": "Mozilla/5.0 (Macintosh; Intel Mac OS X 10_15_7) AppleWebKit/537.36 (KHTML, like Gecko) Chrome/100.0.4896.79 Safari/537.36"
    }
[E 2022-06-14 15:46:39.286 ServerApp] 500 PUT /api/contents/jupyter_notebooks/paper/2a.Temperature_globalmap.ipynb?1655217989597 (::1) 9530.87ms referer=http://localhost:8885/lab/tree/jupyter_notebooks/paper/2a.Temperature_globalmap.ipynb
[I 2022-06-14 15:48:35.326 ServerApp] Saving file at /jupyter_notebooks/paper/2a.Temperature_globalmap.ipynb
[E 2022-06-14 15:48:40.414 ServerApp] Error while saving file: jupyter_notebooks/paper/2a.Temperature_globalmap.ipynb database is locked
    Traceback (most recent call last):
      File "/home/k/kimpson/bin/conda/envs/workhorse/lib/python3.7/site-packages/jupyter_server/services/contents/filemanager.py", line 427, in save
      File "/home/k/kimpson/bin/conda/envs/workhorse/lib/python3.7/site-packages/jupyter_server/services/contents/manager.py", line 644, in check_and_sign
      File "/home/k/kimpson/bin/conda/envs/workhorse/lib/python3.7/site-packages/nbformat/sign.py", line 482, in sign
      File "/home/k/kimpson/bin/conda/envs/workhorse/lib/python3.7/site-packages/nbformat/sign.py", line 224, in store_signature
      File "/home/k/kimpson/bin/conda/envs/workhorse/lib/python3.7/site-packages/nbformat/sign.py", line 255, in check_signature
    sqlite3.OperationalError: database is locked
[W 2022-06-14 15:48:40.429 ServerApp] 500 PUT /api/contents/jupyter_notebooks/paper/2a.Temperature_globalmap.ipynb?1655218110815 (::1): Unexpected error while saving file: jupyter_notebooks/paper/2a.Temperature_globalmap.ipynb database is locked
[W 2022-06-14 15:48:40.430 ServerApp] Unexpected error while saving file: jupyter_notebooks/paper/2a.Temperature_globalmap.ipynb database is locked
[E 2022-06-14 15:48:40.431 ServerApp] {
      "Host": "localhost:8885",
      "Accept": "*/*",
      "Referer": "http://localhost:8885/lab/tree/jupyter_notebooks/paper/2a.Temperature_globalmap.ipynb",
      "User-Agent": "Mozilla/5.0 (Macintosh; Intel Mac OS X 10_15_7) AppleWebKit/537.36 (KHTML, like Gecko) Chrome/100.0.4896.79 Safari/537.36"
    }
[E 2022-06-14 15:48:40.432 ServerApp] 500 PUT /api/contents/jupyter_notebooks/paper/2a.Temperature_globalmap.ipynb?1655218110815 (::1) 9444.01ms referer=http://localhost:8885/lab/tree/jupyter_notebooks/paper/2a.Temperature_globalmap.ipynb
[I 2022-06-14 15:51:32.365 ServerApp] Saving file at /jupyter_notebooks/paper/2a.Temperature_globalmap.ipynb
[E 2022-06-14 15:51:37.447 ServerApp] Error while saving file: jupyter_notebooks/paper/2a.Temperature_globalmap.ipynb database is locked
    Traceback (most recent call last):
      File "/home/k/kimpson/bin/conda/envs/workhorse/lib/python3.7/site-packages/jupyter_server/services/contents/filemanager.py", line 427, in save
      File "/home/k/kimpson/bin/conda/envs/workhorse/lib/python3.7/site-packages/jupyter_server/services/contents/manager.py", line 644, in check_and_sign
      File "/home/k/kimpson/bin/conda/envs/workhorse/lib/python3.7/site-packages/nbformat/sign.py", line 482, in sign
      File "/home/k/kimpson/bin/conda/envs/workhorse/lib/python3.7/site-packages/nbformat/sign.py", line 224, in store_signature
      File "/home/k/kimpson/bin/conda/envs/workhorse/lib/python3.7/site-packages/nbformat/sign.py", line 255, in check_signature
    sqlite3.OperationalError: database is locked
[W 2022-06-14 15:51:37.464 ServerApp] 500 PUT /api/contents/jupyter_notebooks/paper/2a.Temperature_globalmap.ipynb?1655218287681 (::1): Unexpected error while saving file: jupyter_notebooks/paper/2a.Temperature_globalmap.ipynb database is locked
[W 2022-06-14 15:51:37.465 ServerApp] Unexpected error while saving file: jupyter_notebooks/paper/2a.Temperature_globalmap.ipynb database is locked
[E 2022-06-14 15:51:37.466 ServerApp] {
      "Host": "localhost:8885",
      "Accept": "*/*",
      "Referer": "http://localhost:8885/lab/tree/jupyter_notebooks/paper/2a.Temperature_globalmap.ipynb",
      "User-Agent": "Mozilla/5.0 (Macintosh; Intel Mac OS X 10_15_7) AppleWebKit/537.36 (KHTML, like Gecko) Chrome/100.0.4896.79 Safari/537.36"
    }
[E 2022-06-14 15:51:37.467 ServerApp] 500 PUT /api/contents/jupyter_notebooks/paper/2a.Temperature_globalmap.ipynb?1655218287681 (::1) 9434.15ms referer=http://localhost:8885/lab/tree/jupyter_notebooks/paper/2a.Temperature_globalmap.ipynb
[I 2022-06-14 15:53:33.079 ServerApp] Saving file at /jupyter_notebooks/paper/2a.Temperature_globalmap.ipynb
[E 2022-06-14 15:53:38.167 ServerApp] Error while saving file: jupyter_notebooks/paper/2a.Temperature_globalmap.ipynb database is locked
    Traceback (most recent call last):
      File "/home/k/kimpson/bin/conda/envs/workhorse/lib/python3.7/site-packages/jupyter_server/services/contents/filemanager.py", line 427, in save
      File "/home/k/kimpson/bin/conda/envs/workhorse/lib/python3.7/site-packages/jupyter_server/services/contents/manager.py", line 644, in check_and_sign
      File "/home/k/kimpson/bin/conda/envs/workhorse/lib/python3.7/site-packages/nbformat/sign.py", line 482, in sign
      File "/home/k/kimpson/bin/conda/envs/workhorse/lib/python3.7/site-packages/nbformat/sign.py", line 224, in store_signature
      File "/home/k/kimpson/bin/conda/envs/workhorse/lib/python3.7/site-packages/nbformat/sign.py", line 255, in check_signature
    sqlite3.OperationalError: database is locked
[W 2022-06-14 15:53:38.182 ServerApp] 500 PUT /api/contents/jupyter_notebooks/paper/2a.Temperature_globalmap.ipynb?1655218408589 (::1): Unexpected error while saving file: jupyter_notebooks/paper/2a.Temperature_globalmap.ipynb database is locked
[W 2022-06-14 15:53:38.183 ServerApp] Unexpected error while saving file: jupyter_notebooks/paper/2a.Temperature_globalmap.ipynb database is locked
[E 2022-06-14 15:53:38.185 ServerApp] {
      "Host": "localhost:8885",
      "Accept": "*/*",
      "Referer": "http://localhost:8885/lab/tree/jupyter_notebooks/paper/2a.Temperature_globalmap.ipynb",
      "User-Agent": "Mozilla/5.0 (Macintosh; Intel Mac OS X 10_15_7) AppleWebKit/537.36 (KHTML, like Gecko) Chrome/100.0.4896.79 Safari/537.36"
    }
[E 2022-06-14 15:53:38.185 ServerApp] 500 PUT /api/contents/jupyter_notebooks/paper/2a.Temperature_globalmap.ipynb?1655218408589 (::1) 9436.64ms referer=http://localhost:8885/lab/tree/jupyter_notebooks/paper/2a.Temperature_globalmap.ipynb
[I 2022-06-14 15:55:33.129 ServerApp] Saving file at /jupyter_notebooks/paper/2a.Temperature_globalmap.ipynb
[E 2022-06-14 15:55:38.216 ServerApp] Error while saving file: jupyter_notebooks/paper/2a.Temperature_globalmap.ipynb database is locked
    Traceback (most recent call last):
      File "/home/k/kimpson/bin/conda/envs/workhorse/lib/python3.7/site-packages/jupyter_server/services/contents/filemanager.py", line 427, in save
      File "/home/k/kimpson/bin/conda/envs/workhorse/lib/python3.7/site-packages/jupyter_server/services/contents/manager.py", line 644, in check_and_sign
      File "/home/k/kimpson/bin/conda/envs/workhorse/lib/python3.7/site-packages/nbformat/sign.py", line 482, in sign
      File "/home/k/kimpson/bin/conda/envs/workhorse/lib/python3.7/site-packages/nbformat/sign.py", line 224, in store_signature
      File "/home/k/kimpson/bin/conda/envs/workhorse/lib/python3.7/site-packages/nbformat/sign.py", line 255, in check_signature
    sqlite3.OperationalError: database is locked
[W 2022-06-14 15:55:38.232 ServerApp] 500 PUT /api/contents/jupyter_notebooks/paper/2a.Temperature_globalmap.ipynb?1655218528639 (::1): Unexpected error while saving file: jupyter_notebooks/paper/2a.Temperature_globalmap.ipynb database is locked
[W 2022-06-14 15:55:38.233 ServerApp] Unexpected error while saving file: jupyter_notebooks/paper/2a.Temperature_globalmap.ipynb database is locked
[E 2022-06-14 15:55:38.234 ServerApp] {
      "Host": "localhost:8885",
      "Accept": "*/*",
      "Referer": "http://localhost:8885/lab/tree/jupyter_notebooks/paper/2a.Temperature_globalmap.ipynb",
      "User-Agent": "Mozilla/5.0 (Macintosh; Intel Mac OS X 10_15_7) AppleWebKit/537.36 (KHTML, like Gecko) Chrome/100.0.4896.79 Safari/537.36"
    }
[E 2022-06-14 15:55:38.235 ServerApp] 500 PUT /api/contents/jupyter_notebooks/paper/2a.Temperature_globalmap.ipynb?1655218528639 (::1) 9475.40ms referer=http://localhost:8885/lab/tree/jupyter_notebooks/paper/2a.Temperature_globalmap.ipynb
[I 2022-06-14 15:57:33.900 ServerApp] Saving file at /jupyter_notebooks/paper/2a.Temperature_globalmap.ipynb
[E 2022-06-14 15:57:38.985 ServerApp] Error while saving file: jupyter_notebooks/paper/2a.Temperature_globalmap.ipynb database is locked
    Traceback (most recent call last):
      File "/home/k/kimpson/bin/conda/envs/workhorse/lib/python3.7/site-packages/jupyter_server/services/contents/filemanager.py", line 427, in save
      File "/home/k/kimpson/bin/conda/envs/workhorse/lib/python3.7/site-packages/jupyter_server/services/contents/manager.py", line 644, in check_and_sign
      File "/home/k/kimpson/bin/conda/envs/workhorse/lib/python3.7/site-packages/nbformat/sign.py", line 482, in sign
      File "/home/k/kimpson/bin/conda/envs/workhorse/lib/python3.7/site-packages/nbformat/sign.py", line 224, in store_signature
      File "/home/k/kimpson/bin/conda/envs/workhorse/lib/python3.7/site-packages/nbformat/sign.py", line 255, in check_signature
    sqlite3.OperationalError: database is locked
[W 2022-06-14 15:57:39.002 ServerApp] 500 PUT /api/contents/jupyter_notebooks/paper/2a.Temperature_globalmap.ipynb?1655218649402 (::1): Unexpected error while saving file: jupyter_notebooks/paper/2a.Temperature_globalmap.ipynb database is locked
[W 2022-06-14 15:57:39.003 ServerApp] Unexpected error while saving file: jupyter_notebooks/paper/2a.Temperature_globalmap.ipynb database is locked
[E 2022-06-14 15:57:39.004 ServerApp] {
      "Host": "localhost:8885",
      "Accept": "*/*",
      "Referer": "http://localhost:8885/lab/tree/jupyter_notebooks/paper/2a.Temperature_globalmap.ipynb",
      "User-Agent": "Mozilla/5.0 (Macintosh; Intel Mac OS X 10_15_7) AppleWebKit/537.36 (KHTML, like Gecko) Chrome/100.0.4896.79 Safari/537.36"
    }
[E 2022-06-14 15:57:39.004 ServerApp] 500 PUT /api/contents/jupyter_notebooks/paper/2a.Temperature_globalmap.ipynb?1655218649402 (::1) 9474.42ms referer=http://localhost:8885/lab/tree/jupyter_notebooks/paper/2a.Temperature_globalmap.ipynb
[I 2022-06-14 16:00:31.352 ServerApp] Saving file at /jupyter_notebooks/paper/2a.Temperature_globalmap.ipynb
[E 2022-06-14 16:00:36.437 ServerApp] Error while saving file: jupyter_notebooks/paper/2a.Temperature_globalmap.ipynb database is locked
    Traceback (most recent call last):
      File "/home/k/kimpson/bin/conda/envs/workhorse/lib/python3.7/site-packages/jupyter_server/services/contents/filemanager.py", line 427, in save
      File "/home/k/kimpson/bin/conda/envs/workhorse/lib/python3.7/site-packages/jupyter_server/services/contents/manager.py", line 644, in check_and_sign
      File "/home/k/kimpson/bin/conda/envs/workhorse/lib/python3.7/site-packages/nbformat/sign.py", line 482, in sign
      File "/home/k/kimpson/bin/conda/envs/workhorse/lib/python3.7/site-packages/nbformat/sign.py", line 224, in store_signature
      File "/home/k/kimpson/bin/conda/envs/workhorse/lib/python3.7/site-packages/nbformat/sign.py", line 255, in check_signature
    sqlite3.OperationalError: database is locked
[W 2022-06-14 16:00:36.454 ServerApp] 500 PUT /api/contents/jupyter_notebooks/paper/2a.Temperature_globalmap.ipynb?1655218826694 (::1): Unexpected error while saving file: jupyter_notebooks/paper/2a.Temperature_globalmap.ipynb database is locked
[W 2022-06-14 16:00:36.455 ServerApp] Unexpected error while saving file: jupyter_notebooks/paper/2a.Temperature_globalmap.ipynb database is locked
[E 2022-06-14 16:00:36.457 ServerApp] {
      "Host": "localhost:8885",
      "Accept": "*/*",
      "Referer": "http://localhost:8885/lab/tree/jupyter_notebooks/paper/2a.Temperature_globalmap.ipynb",
      "User-Agent": "Mozilla/5.0 (Macintosh; Intel Mac OS X 10_15_7) AppleWebKit/537.36 (KHTML, like Gecko) Chrome/100.0.4896.79 Safari/537.36"
    }
[E 2022-06-14 16:00:36.458 ServerApp] 500 PUT /api/contents/jupyter_notebooks/paper/2a.Temperature_globalmap.ipynb?1655218826694 (::1) 9445.93ms referer=http://localhost:8885/lab/tree/jupyter_notebooks/paper/2a.Temperature_globalmap.ipynb
[I 2022-06-14 16:03:29.991 ServerApp] Saving file at /jupyter_notebooks/paper/2a.Temperature_globalmap.ipynb
[E 2022-06-14 16:03:35.079 ServerApp] Error while saving file: jupyter_notebooks/paper/2a.Temperature_globalmap.ipynb database is locked
    Traceback (most recent call last):
      File "/home/k/kimpson/bin/conda/envs/workhorse/lib/python3.7/site-packages/jupyter_server/services/contents/filemanager.py", line 427, in save
      File "/home/k/kimpson/bin/conda/envs/workhorse/lib/python3.7/site-packages/jupyter_server/services/contents/manager.py", line 644, in check_and_sign
      File "/home/k/kimpson/bin/conda/envs/workhorse/lib/python3.7/site-packages/nbformat/sign.py", line 482, in sign
      File "/home/k/kimpson/bin/conda/envs/workhorse/lib/python3.7/site-packages/nbformat/sign.py", line 224, in store_signature
      File "/home/k/kimpson/bin/conda/envs/workhorse/lib/python3.7/site-packages/nbformat/sign.py", line 255, in check_signature
    sqlite3.OperationalError: database is locked
[W 2022-06-14 16:03:35.097 ServerApp] 500 PUT /api/contents/jupyter_notebooks/paper/2a.Temperature_globalmap.ipynb?1655219005429 (::1): Unexpected error while saving file: jupyter_notebooks/paper/2a.Temperature_globalmap.ipynb database is locked
[W 2022-06-14 16:03:35.097 ServerApp] Unexpected error while saving file: jupyter_notebooks/paper/2a.Temperature_globalmap.ipynb database is locked
[E 2022-06-14 16:03:35.099 ServerApp] {
      "Host": "localhost:8885",
      "Accept": "*/*",
      "Referer": "http://localhost:8885/lab/tree/jupyter_notebooks/paper/2a.Temperature_globalmap.ipynb",
      "User-Agent": "Mozilla/5.0 (Macintosh; Intel Mac OS X 10_15_7) AppleWebKit/537.36 (KHTML, like Gecko) Chrome/100.0.4896.79 Safari/537.36"
    }
[E 2022-06-14 16:03:35.100 ServerApp] 500 PUT /api/contents/jupyter_notebooks/paper/2a.Temperature_globalmap.ipynb?1655219005429 (::1) 9444.29ms referer=http://localhost:8885/lab/tree/jupyter_notebooks/paper/2a.Temperature_globalmap.ipynb
[I 2022-06-14 16:05:30.815 ServerApp] Saving file at /jupyter_notebooks/paper/2a.Temperature_globalmap.ipynb
[E 2022-06-14 16:05:35.903 ServerApp] Error while saving file: jupyter_notebooks/paper/2a.Temperature_globalmap.ipynb database is locked
    Traceback (most recent call last):
      File "/home/k/kimpson/bin/conda/envs/workhorse/lib/python3.7/site-packages/jupyter_server/services/contents/filemanager.py", line 427, in save
      File "/home/k/kimpson/bin/conda/envs/workhorse/lib/python3.7/site-packages/jupyter_server/services/contents/manager.py", line 644, in check_and_sign
      File "/home/k/kimpson/bin/conda/envs/workhorse/lib/python3.7/site-packages/nbformat/sign.py", line 482, in sign
      File "/home/k/kimpson/bin/conda/envs/workhorse/lib/python3.7/site-packages/nbformat/sign.py", line 224, in store_signature
      File "/home/k/kimpson/bin/conda/envs/workhorse/lib/python3.7/site-packages/nbformat/sign.py", line 255, in check_signature
    sqlite3.OperationalError: database is locked
[W 2022-06-14 16:05:35.918 ServerApp] 500 PUT /api/contents/jupyter_notebooks/paper/2a.Temperature_globalmap.ipynb?1655219126179 (::1): Unexpected error while saving file: jupyter_notebooks/paper/2a.Temperature_globalmap.ipynb database is locked
[W 2022-06-14 16:05:35.919 ServerApp] Unexpected error while saving file: jupyter_notebooks/paper/2a.Temperature_globalmap.ipynb database is locked
[E 2022-06-14 16:05:35.920 ServerApp] {
      "Host": "localhost:8885",
      "Accept": "*/*",
      "Referer": "http://localhost:8885/lab/tree/jupyter_notebooks/paper/2a.Temperature_globalmap.ipynb",
      "User-Agent": "Mozilla/5.0 (Macintosh; Intel Mac OS X 10_15_7) AppleWebKit/537.36 (KHTML, like Gecko) Chrome/100.0.4896.79 Safari/537.36"
    }
[E 2022-06-14 16:05:35.921 ServerApp] 500 PUT /api/contents/jupyter_notebooks/paper/2a.Temperature_globalmap.ipynb?1655219126179 (::1) 9564.91ms referer=http://localhost:8885/lab/tree/jupyter_notebooks/paper/2a.Temperature_globalmap.ipynb
[I 2022-06-14 16:07:30.850 ServerApp] Saving file at /jupyter_notebooks/paper/2a.Temperature_globalmap.ipynb
[E 2022-06-14 16:07:35.942 ServerApp] Error while saving file: jupyter_notebooks/paper/2a.Temperature_globalmap.ipynb database is locked
    Traceback (most recent call last):
      File "/home/k/kimpson/bin/conda/envs/workhorse/lib/python3.7/site-packages/jupyter_server/services/contents/filemanager.py", line 427, in save
      File "/home/k/kimpson/bin/conda/envs/workhorse/lib/python3.7/site-packages/jupyter_server/services/contents/manager.py", line 644, in check_and_sign
      File "/home/k/kimpson/bin/conda/envs/workhorse/lib/python3.7/site-packages/nbformat/sign.py", line 482, in sign
      File "/home/k/kimpson/bin/conda/envs/workhorse/lib/python3.7/site-packages/nbformat/sign.py", line 224, in store_signature
      File "/home/k/kimpson/bin/conda/envs/workhorse/lib/python3.7/site-packages/nbformat/sign.py", line 255, in check_signature
    sqlite3.OperationalError: database is locked
[W 2022-06-14 16:07:35.959 ServerApp] 500 PUT /api/contents/jupyter_notebooks/paper/2a.Temperature_globalmap.ipynb?1655219246136 (::1): Unexpected error while saving file: jupyter_notebooks/paper/2a.Temperature_globalmap.ipynb database is locked
[W 2022-06-14 16:07:35.960 ServerApp] Unexpected error while saving file: jupyter_notebooks/paper/2a.Temperature_globalmap.ipynb database is locked
[E 2022-06-14 16:07:35.961 ServerApp] {
      "Host": "localhost:8885",
      "Accept": "*/*",
      "Referer": "http://localhost:8885/lab/tree/jupyter_notebooks/paper/2a.Temperature_globalmap.ipynb",
      "User-Agent": "Mozilla/5.0 (Macintosh; Intel Mac OS X 10_15_7) AppleWebKit/537.36 (KHTML, like Gecko) Chrome/100.0.4896.79 Safari/537.36"
    }
[E 2022-06-14 16:07:35.962 ServerApp] 500 PUT /api/contents/jupyter_notebooks/paper/2a.Temperature_globalmap.ipynb?1655219246136 (::1) 9526.21ms referer=http://localhost:8885/lab/tree/jupyter_notebooks/paper/2a.Temperature_globalmap.ipynb
[I 2022-06-14 16:10:30.159 ServerApp] Saving file at /jupyter_notebooks/paper/2a.Temperature_globalmap.ipynb
[E 2022-06-14 16:10:35.241 ServerApp] Error while saving file: jupyter_notebooks/paper/2a.Temperature_globalmap.ipynb database is locked
    Traceback (most recent call last):
      File "/home/k/kimpson/bin/conda/envs/workhorse/lib/python3.7/site-packages/jupyter_server/services/contents/filemanager.py", line 427, in save
      File "/home/k/kimpson/bin/conda/envs/workhorse/lib/python3.7/site-packages/jupyter_server/services/contents/manager.py", line 644, in check_and_sign
      File "/home/k/kimpson/bin/conda/envs/workhorse/lib/python3.7/site-packages/nbformat/sign.py", line 482, in sign
      File "/home/k/kimpson/bin/conda/envs/workhorse/lib/python3.7/site-packages/nbformat/sign.py", line 224, in store_signature
      File "/home/k/kimpson/bin/conda/envs/workhorse/lib/python3.7/site-packages/nbformat/sign.py", line 255, in check_signature
    sqlite3.OperationalError: database is locked
[W 2022-06-14 16:10:35.257 ServerApp] 500 PUT /api/contents/jupyter_notebooks/paper/2a.Temperature_globalmap.ipynb?1655219425684 (::1): Unexpected error while saving file: jupyter_notebooks/paper/2a.Temperature_globalmap.ipynb database is locked
[W 2022-06-14 16:10:35.257 ServerApp] Unexpected error while saving file: jupyter_notebooks/paper/2a.Temperature_globalmap.ipynb database is locked
[E 2022-06-14 16:10:35.259 ServerApp] {
      "Host": "localhost:8885",
      "Accept": "*/*",
      "Referer": "http://localhost:8885/lab/tree/jupyter_notebooks/paper/2a.Temperature_globalmap.ipynb",
      "User-Agent": "Mozilla/5.0 (Macintosh; Intel Mac OS X 10_15_7) AppleWebKit/537.36 (KHTML, like Gecko) Chrome/100.0.4896.79 Safari/537.36"
    }
[E 2022-06-14 16:10:35.259 ServerApp] 500 PUT /api/contents/jupyter_notebooks/paper/2a.Temperature_globalmap.ipynb?1655219425684 (::1) 9436.46ms referer=http://localhost:8885/lab/tree/jupyter_notebooks/paper/2a.Temperature_globalmap.ipynb
[E 2022-06-14 16:10:41.103 ServerApp] Uncaught exception in write_error
    Traceback (most recent call last):
      File "/home/k/kimpson/bin/conda/envs/workhorse/lib/python3.7/site-packages/tornado/web.py", line 1704, in _execute
      File "/home/k/kimpson/bin/conda/envs/workhorse/lib/python3.7/site-packages/tornado/web.py", line 2576, in get
      File "/home/k/kimpson/bin/conda/envs/workhorse/lib/python3.7/site-packages/jupyter_server/base/handlers.py", line 872, in validate_absolute_path
      File "/home/k/kimpson/bin/conda/envs/workhorse/lib/python3.7/site-packages/tornado/web.py", line 2778, in validate_absolute_path
    tornado.web.HTTPError: HTTP 404: Not Found
    
    During handling of the above exception, another exception occurred:
    
    Traceback (most recent call last):
      File "/home/k/kimpson/bin/conda/envs/workhorse/lib/python3.7/site-packages/jupyter_server/base/handlers.py", line 595, in write_error
      File "/home/k/kimpson/bin/conda/envs/workhorse/lib/python3.7/site-packages/jupyter_server/base/handlers.py", line 525, in render_template
      File "/home/k/kimpson/bin/conda/envs/workhorse/lib/python3.7/site-packages/jupyter_server/base/handlers.py", line 521, in get_template
      File "/home/k/kimpson/bin/conda/envs/workhorse/lib/python3.7/site-packages/jinja2/environment.py", line 997, in get_template
      File "/home/k/kimpson/bin/conda/envs/workhorse/lib/python3.7/site-packages/jinja2/environment.py", line 958, in _load_template
      File "/home/k/kimpson/bin/conda/envs/workhorse/lib/python3.7/site-packages/jinja2/loaders.py", line 125, in load
      File "/home/k/kimpson/bin/conda/envs/workhorse/lib/python3.7/site-packages/jinja2/loaders.py", line 214, in get_source
    jinja2.exceptions.TemplateNotFound: 404.html
    
    During handling of the above exception, another exception occurred:
    
    Traceback (most recent call last):
      File "/home/k/kimpson/bin/conda/envs/workhorse/lib/python3.7/site-packages/tornado/web.py", line 1217, in send_error
      File "/home/k/kimpson/bin/conda/envs/workhorse/lib/python3.7/site-packages/jupyter_server/base/handlers.py", line 597, in write_error
      File "/home/k/kimpson/bin/conda/envs/workhorse/lib/python3.7/site-packages/jupyter_server/base/handlers.py", line 525, in render_template
      File "/home/k/kimpson/bin/conda/envs/workhorse/lib/python3.7/site-packages/jupyter_server/base/handlers.py", line 521, in get_template
      File "/home/k/kimpson/bin/conda/envs/workhorse/lib/python3.7/site-packages/jinja2/environment.py", line 997, in get_template
      File "/home/k/kimpson/bin/conda/envs/workhorse/lib/python3.7/site-packages/jinja2/environment.py", line 958, in _load_template
      File "/home/k/kimpson/bin/conda/envs/workhorse/lib/python3.7/site-packages/jinja2/loaders.py", line 125, in load
      File "/home/k/kimpson/bin/conda/envs/workhorse/lib/python3.7/site-packages/jinja2/loaders.py", line 214, in get_source
    jinja2.exceptions.TemplateNotFound: error.html
[W 2022-06-14 16:10:41.161 ServerApp] 404 GET /static/favicons/favicon.ico (::1) 73.92ms referer=http://localhost:8885/lab/tree/jupyter_notebooks/paper/2a.Temperature_globalmap.ipynb
[E 2022-06-14 16:10:47.786 ServerApp] Uncaught exception in write_error
    Traceback (most recent call last):
      File "/home/k/kimpson/bin/conda/envs/workhorse/lib/python3.7/site-packages/tornado/web.py", line 1704, in _execute
      File "/home/k/kimpson/bin/conda/envs/workhorse/lib/python3.7/site-packages/tornado/web.py", line 2576, in get
      File "/home/k/kimpson/bin/conda/envs/workhorse/lib/python3.7/site-packages/jupyter_server/base/handlers.py", line 872, in validate_absolute_path
      File "/home/k/kimpson/bin/conda/envs/workhorse/lib/python3.7/site-packages/tornado/web.py", line 2778, in validate_absolute_path
    tornado.web.HTTPError: HTTP 404: Not Found
    
    During handling of the above exception, another exception occurred:
    
    Traceback (most recent call last):
      File "/home/k/kimpson/bin/conda/envs/workhorse/lib/python3.7/site-packages/jupyter_server/base/handlers.py", line 595, in write_error
      File "/home/k/kimpson/bin/conda/envs/workhorse/lib/python3.7/site-packages/jupyter_server/base/handlers.py", line 525, in render_template
      File "/home/k/kimpson/bin/conda/envs/workhorse/lib/python3.7/site-packages/jupyter_server/base/handlers.py", line 521, in get_template
      File "/home/k/kimpson/bin/conda/envs/workhorse/lib/python3.7/site-packages/jinja2/environment.py", line 997, in get_template
      File "/home/k/kimpson/bin/conda/envs/workhorse/lib/python3.7/site-packages/jinja2/environment.py", line 958, in _load_template
      File "/home/k/kimpson/bin/conda/envs/workhorse/lib/python3.7/site-packages/jinja2/loaders.py", line 125, in load
      File "/home/k/kimpson/bin/conda/envs/workhorse/lib/python3.7/site-packages/jinja2/loaders.py", line 214, in get_source
    jinja2.exceptions.TemplateNotFound: 404.html
    
    During handling of the above exception, another exception occurred:
    
    Traceback (most recent call last):
      File "/home/k/kimpson/bin/conda/envs/workhorse/lib/python3.7/site-packages/tornado/web.py", line 1217, in send_error
      File "/home/k/kimpson/bin/conda/envs/workhorse/lib/python3.7/site-packages/jupyter_server/base/handlers.py", line 597, in write_error
      File "/home/k/kimpson/bin/conda/envs/workhorse/lib/python3.7/site-packages/jupyter_server/base/handlers.py", line 525, in render_template
      File "/home/k/kimpson/bin/conda/envs/workhorse/lib/python3.7/site-packages/jupyter_server/base/handlers.py", line 521, in get_template
      File "/home/k/kimpson/bin/conda/envs/workhorse/lib/python3.7/site-packages/jinja2/environment.py", line 997, in get_template
      File "/home/k/kimpson/bin/conda/envs/workhorse/lib/python3.7/site-packages/jinja2/environment.py", line 958, in _load_template
      File "/home/k/kimpson/bin/conda/envs/workhorse/lib/python3.7/site-packages/jinja2/loaders.py", line 125, in load
      File "/home/k/kimpson/bin/conda/envs/workhorse/lib/python3.7/site-packages/jinja2/loaders.py", line 214, in get_source
    jinja2.exceptions.TemplateNotFound: error.html
[W 2022-06-14 16:10:47.842 ServerApp] 404 GET /static/favicons/favicon-busy-1.ico (::1) 70.90ms referer=http://localhost:8885/lab/tree/jupyter_notebooks/paper/2a.Temperature_globalmap.ipynb
[E 2022-06-14 16:10:48.992 ServerApp] Uncaught exception in write_error
    Traceback (most recent call last):
      File "/home/k/kimpson/bin/conda/envs/workhorse/lib/python3.7/site-packages/tornado/web.py", line 1704, in _execute
      File "/home/k/kimpson/bin/conda/envs/workhorse/lib/python3.7/site-packages/tornado/web.py", line 2576, in get
      File "/home/k/kimpson/bin/conda/envs/workhorse/lib/python3.7/site-packages/jupyter_server/base/handlers.py", line 872, in validate_absolute_path
      File "/home/k/kimpson/bin/conda/envs/workhorse/lib/python3.7/site-packages/tornado/web.py", line 2778, in validate_absolute_path
    tornado.web.HTTPError: HTTP 404: Not Found
    
    During handling of the above exception, another exception occurred:
    
    Traceback (most recent call last):
      File "/home/k/kimpson/bin/conda/envs/workhorse/lib/python3.7/site-packages/jupyter_server/base/handlers.py", line 595, in write_error
      File "/home/k/kimpson/bin/conda/envs/workhorse/lib/python3.7/site-packages/jupyter_server/base/handlers.py", line 525, in render_template
      File "/home/k/kimpson/bin/conda/envs/workhorse/lib/python3.7/site-packages/jupyter_server/base/handlers.py", line 521, in get_template
      File "/home/k/kimpson/bin/conda/envs/workhorse/lib/python3.7/site-packages/jinja2/environment.py", line 997, in get_template
      File "/home/k/kimpson/bin/conda/envs/workhorse/lib/python3.7/site-packages/jinja2/environment.py", line 958, in _load_template
      File "/home/k/kimpson/bin/conda/envs/workhorse/lib/python3.7/site-packages/jinja2/loaders.py", line 125, in load
      File "/home/k/kimpson/bin/conda/envs/workhorse/lib/python3.7/site-packages/jinja2/loaders.py", line 214, in get_source
    jinja2.exceptions.TemplateNotFound: 404.html
    
    During handling of the above exception, another exception occurred:
    
    Traceback (most recent call last):
      File "/home/k/kimpson/bin/conda/envs/workhorse/lib/python3.7/site-packages/tornado/web.py", line 1217, in send_error
      File "/home/k/kimpson/bin/conda/envs/workhorse/lib/python3.7/site-packages/jupyter_server/base/handlers.py", line 597, in write_error
      File "/home/k/kimpson/bin/conda/envs/workhorse/lib/python3.7/site-packages/jupyter_server/base/handlers.py", line 525, in render_template
      File "/home/k/kimpson/bin/conda/envs/workhorse/lib/python3.7/site-packages/jupyter_server/base/handlers.py", line 521, in get_template
      File "/home/k/kimpson/bin/conda/envs/workhorse/lib/python3.7/site-packages/jinja2/environment.py", line 997, in get_template
      File "/home/k/kimpson/bin/conda/envs/workhorse/lib/python3.7/site-packages/jinja2/environment.py", line 958, in _load_template
      File "/home/k/kimpson/bin/conda/envs/workhorse/lib/python3.7/site-packages/jinja2/loaders.py", line 125, in load
      File "/home/k/kimpson/bin/conda/envs/workhorse/lib/python3.7/site-packages/jinja2/loaders.py", line 214, in get_source
    jinja2.exceptions.TemplateNotFound: error.html
[W 2022-06-14 16:10:49.047 ServerApp] 404 GET /static/favicons/favicon-busy-1.ico (::1) 68.69ms referer=http://localhost:8885/lab/tree/jupyter_notebooks/paper/2a.Temperature_globalmap.ipynb
[I 2022-06-14 16:12:30.001 ServerApp] Saving file at /jupyter_notebooks/paper/2a.Temperature_globalmap.ipynb
[E 2022-06-14 16:12:35.089 ServerApp] Error while saving file: jupyter_notebooks/paper/2a.Temperature_globalmap.ipynb database is locked
    Traceback (most recent call last):
      File "/home/k/kimpson/bin/conda/envs/workhorse/lib/python3.7/site-packages/jupyter_server/services/contents/filemanager.py", line 427, in save
      File "/home/k/kimpson/bin/conda/envs/workhorse/lib/python3.7/site-packages/jupyter_server/services/contents/manager.py", line 644, in check_and_sign
      File "/home/k/kimpson/bin/conda/envs/workhorse/lib/python3.7/site-packages/nbformat/sign.py", line 482, in sign
      File "/home/k/kimpson/bin/conda/envs/workhorse/lib/python3.7/site-packages/nbformat/sign.py", line 224, in store_signature
      File "/home/k/kimpson/bin/conda/envs/workhorse/lib/python3.7/site-packages/nbformat/sign.py", line 255, in check_signature
    sqlite3.OperationalError: database is locked
[W 2022-06-14 16:12:35.105 ServerApp] 500 PUT /api/contents/jupyter_notebooks/paper/2a.Temperature_globalmap.ipynb?1655219546319 (::1): Unexpected error while saving file: jupyter_notebooks/paper/2a.Temperature_globalmap.ipynb database is locked
[W 2022-06-14 16:12:35.106 ServerApp] Unexpected error while saving file: jupyter_notebooks/paper/2a.Temperature_globalmap.ipynb database is locked
[E 2022-06-14 16:12:35.107 ServerApp] {
      "Host": "localhost:8885",
      "Accept": "*/*",
      "Referer": "http://localhost:8885/lab/tree/jupyter_notebooks/paper/2a.Temperature_globalmap.ipynb",
      "User-Agent": "Mozilla/5.0 (Macintosh; Intel Mac OS X 10_15_7) AppleWebKit/537.36 (KHTML, like Gecko) Chrome/100.0.4896.79 Safari/537.36"
    }
[E 2022-06-14 16:12:35.107 ServerApp] 500 PUT /api/contents/jupyter_notebooks/paper/2a.Temperature_globalmap.ipynb?1655219546319 (::1) 8671.79ms referer=http://localhost:8885/lab/tree/jupyter_notebooks/paper/2a.Temperature_globalmap.ipynb
[I 2022-06-14 16:14:30.096 ServerApp] Saving file at /jupyter_notebooks/paper/2a.Temperature_globalmap.ipynb
[E 2022-06-14 16:14:35.180 ServerApp] Error while saving file: jupyter_notebooks/paper/2a.Temperature_globalmap.ipynb database is locked
    Traceback (most recent call last):
      File "/home/k/kimpson/bin/conda/envs/workhorse/lib/python3.7/site-packages/jupyter_server/services/contents/filemanager.py", line 427, in save
      File "/home/k/kimpson/bin/conda/envs/workhorse/lib/python3.7/site-packages/jupyter_server/services/contents/manager.py", line 644, in check_and_sign
      File "/home/k/kimpson/bin/conda/envs/workhorse/lib/python3.7/site-packages/nbformat/sign.py", line 482, in sign
      File "/home/k/kimpson/bin/conda/envs/workhorse/lib/python3.7/site-packages/nbformat/sign.py", line 224, in store_signature
      File "/home/k/kimpson/bin/conda/envs/workhorse/lib/python3.7/site-packages/nbformat/sign.py", line 255, in check_signature
    sqlite3.OperationalError: database is locked
[W 2022-06-14 16:14:35.197 ServerApp] 500 PUT /api/contents/jupyter_notebooks/paper/2a.Temperature_globalmap.ipynb?1655219666630 (::1): Unexpected error while saving file: jupyter_notebooks/paper/2a.Temperature_globalmap.ipynb database is locked
[W 2022-06-14 16:14:35.198 ServerApp] Unexpected error while saving file: jupyter_notebooks/paper/2a.Temperature_globalmap.ipynb database is locked
[E 2022-06-14 16:14:35.200 ServerApp] {
      "Host": "localhost:8885",
      "Accept": "*/*",
      "Referer": "http://localhost:8885/lab/tree/jupyter_notebooks/paper/2a.Temperature_globalmap.ipynb",
      "User-Agent": "Mozilla/5.0 (Macintosh; Intel Mac OS X 10_15_7) AppleWebKit/537.36 (KHTML, like Gecko) Chrome/100.0.4896.79 Safari/537.36"
    }
[E 2022-06-14 16:14:35.201 ServerApp] 500 PUT /api/contents/jupyter_notebooks/paper/2a.Temperature_globalmap.ipynb?1655219666630 (::1) 8280.39ms referer=http://localhost:8885/lab/tree/jupyter_notebooks/paper/2a.Temperature_globalmap.ipynb
[I 2022-06-14 16:16:30.790 ServerApp] Saving file at /jupyter_notebooks/paper/2a.Temperature_globalmap.ipynb
[E 2022-06-14 16:16:35.873 ServerApp] Error while saving file: jupyter_notebooks/paper/2a.Temperature_globalmap.ipynb database is locked
    Traceback (most recent call last):
      File "/home/k/kimpson/bin/conda/envs/workhorse/lib/python3.7/site-packages/jupyter_server/services/contents/filemanager.py", line 427, in save
      File "/home/k/kimpson/bin/conda/envs/workhorse/lib/python3.7/site-packages/jupyter_server/services/contents/manager.py", line 644, in check_and_sign
      File "/home/k/kimpson/bin/conda/envs/workhorse/lib/python3.7/site-packages/nbformat/sign.py", line 482, in sign
      File "/home/k/kimpson/bin/conda/envs/workhorse/lib/python3.7/site-packages/nbformat/sign.py", line 224, in store_signature
      File "/home/k/kimpson/bin/conda/envs/workhorse/lib/python3.7/site-packages/nbformat/sign.py", line 255, in check_signature
    sqlite3.OperationalError: database is locked
[W 2022-06-14 16:16:35.889 ServerApp] 500 PUT /api/contents/jupyter_notebooks/paper/2a.Temperature_globalmap.ipynb?1655219787493 (::1): Unexpected error while saving file: jupyter_notebooks/paper/2a.Temperature_globalmap.ipynb database is locked
[W 2022-06-14 16:16:35.890 ServerApp] Unexpected error while saving file: jupyter_notebooks/paper/2a.Temperature_globalmap.ipynb database is locked
[E 2022-06-14 16:16:35.891 ServerApp] {
      "Host": "localhost:8885",
      "Accept": "*/*",
      "Referer": "http://localhost:8885/lab/tree/jupyter_notebooks/paper/2a.Temperature_globalmap.ipynb",
      "User-Agent": "Mozilla/5.0 (Macintosh; Intel Mac OS X 10_15_7) AppleWebKit/537.36 (KHTML, like Gecko) Chrome/100.0.4896.79 Safari/537.36"
    }
[E 2022-06-14 16:16:35.892 ServerApp] 500 PUT /api/contents/jupyter_notebooks/paper/2a.Temperature_globalmap.ipynb?1655219787493 (::1) 8278.36ms referer=http://localhost:8885/lab/tree/jupyter_notebooks/paper/2a.Temperature_globalmap.ipynb
[I 2022-06-14 16:19:28.606 ServerApp] Saving file at /jupyter_notebooks/paper/2a.Temperature_globalmap.ipynb
[E 2022-06-14 16:19:33.690 ServerApp] Error while saving file: jupyter_notebooks/paper/2a.Temperature_globalmap.ipynb database is locked
    Traceback (most recent call last):
      File "/home/k/kimpson/bin/conda/envs/workhorse/lib/python3.7/site-packages/jupyter_server/services/contents/filemanager.py", line 427, in save
      File "/home/k/kimpson/bin/conda/envs/workhorse/lib/python3.7/site-packages/jupyter_server/services/contents/manager.py", line 644, in check_and_sign
      File "/home/k/kimpson/bin/conda/envs/workhorse/lib/python3.7/site-packages/nbformat/sign.py", line 482, in sign
      File "/home/k/kimpson/bin/conda/envs/workhorse/lib/python3.7/site-packages/nbformat/sign.py", line 224, in store_signature
      File "/home/k/kimpson/bin/conda/envs/workhorse/lib/python3.7/site-packages/nbformat/sign.py", line 255, in check_signature
    sqlite3.OperationalError: database is locked
[W 2022-06-14 16:19:33.706 ServerApp] 500 PUT /api/contents/jupyter_notebooks/paper/2a.Temperature_globalmap.ipynb?1655219965313 (::1): Unexpected error while saving file: jupyter_notebooks/paper/2a.Temperature_globalmap.ipynb database is locked
[W 2022-06-14 16:19:33.707 ServerApp] Unexpected error while saving file: jupyter_notebooks/paper/2a.Temperature_globalmap.ipynb database is locked
[E 2022-06-14 16:19:33.709 ServerApp] {
      "Host": "localhost:8885",
      "Accept": "*/*",
      "Referer": "http://localhost:8885/lab/tree/jupyter_notebooks/paper/2a.Temperature_globalmap.ipynb",
      "User-Agent": "Mozilla/5.0 (Macintosh; Intel Mac OS X 10_15_7) AppleWebKit/537.36 (KHTML, like Gecko) Chrome/100.0.4896.79 Safari/537.36"
    }
[E 2022-06-14 16:19:33.710 ServerApp] 500 PUT /api/contents/jupyter_notebooks/paper/2a.Temperature_globalmap.ipynb?1655219965313 (::1) 8279.02ms referer=http://localhost:8885/lab/tree/jupyter_notebooks/paper/2a.Temperature_globalmap.ipynb
[I 2022-06-14 16:21:28.631 ServerApp] Saving file at /jupyter_notebooks/paper/2a.Temperature_globalmap.ipynb
[E 2022-06-14 16:21:33.711 ServerApp] Error while saving file: jupyter_notebooks/paper/2a.Temperature_globalmap.ipynb database is locked
    Traceback (most recent call last):
      File "/home/k/kimpson/bin/conda/envs/workhorse/lib/python3.7/site-packages/jupyter_server/services/contents/filemanager.py", line 427, in save
      File "/home/k/kimpson/bin/conda/envs/workhorse/lib/python3.7/site-packages/jupyter_server/services/contents/manager.py", line 644, in check_and_sign
      File "/home/k/kimpson/bin/conda/envs/workhorse/lib/python3.7/site-packages/nbformat/sign.py", line 482, in sign
      File "/home/k/kimpson/bin/conda/envs/workhorse/lib/python3.7/site-packages/nbformat/sign.py", line 224, in store_signature
      File "/home/k/kimpson/bin/conda/envs/workhorse/lib/python3.7/site-packages/nbformat/sign.py", line 255, in check_signature
    sqlite3.OperationalError: database is locked
[W 2022-06-14 16:21:33.727 ServerApp] 500 PUT /api/contents/jupyter_notebooks/paper/2a.Temperature_globalmap.ipynb?1655220085340 (::1): Unexpected error while saving file: jupyter_notebooks/paper/2a.Temperature_globalmap.ipynb database is locked
[W 2022-06-14 16:21:33.728 ServerApp] Unexpected error while saving file: jupyter_notebooks/paper/2a.Temperature_globalmap.ipynb database is locked
[E 2022-06-14 16:21:33.729 ServerApp] {
      "Host": "localhost:8885",
      "Accept": "*/*",
      "Referer": "http://localhost:8885/lab/tree/jupyter_notebooks/paper/2a.Temperature_globalmap.ipynb",
      "User-Agent": "Mozilla/5.0 (Macintosh; Intel Mac OS X 10_15_7) AppleWebKit/537.36 (KHTML, like Gecko) Chrome/100.0.4896.79 Safari/537.36"
    }
[E 2022-06-14 16:21:33.729 ServerApp] 500 PUT /api/contents/jupyter_notebooks/paper/2a.Temperature_globalmap.ipynb?1655220085340 (::1) 8311.19ms referer=http://localhost:8885/lab/tree/jupyter_notebooks/paper/2a.Temperature_globalmap.ipynb
[I 2022-06-14 16:24:28.606 ServerApp] Saving file at /jupyter_notebooks/paper/2a.Temperature_globalmap.ipynb
[E 2022-06-14 16:24:33.682 ServerApp] Error while saving file: jupyter_notebooks/paper/2a.Temperature_globalmap.ipynb database is locked
    Traceback (most recent call last):
      File "/home/k/kimpson/bin/conda/envs/workhorse/lib/python3.7/site-packages/jupyter_server/services/contents/filemanager.py", line 427, in save
      File "/home/k/kimpson/bin/conda/envs/workhorse/lib/python3.7/site-packages/jupyter_server/services/contents/manager.py", line 644, in check_and_sign
      File "/home/k/kimpson/bin/conda/envs/workhorse/lib/python3.7/site-packages/nbformat/sign.py", line 482, in sign
      File "/home/k/kimpson/bin/conda/envs/workhorse/lib/python3.7/site-packages/nbformat/sign.py", line 224, in store_signature
      File "/home/k/kimpson/bin/conda/envs/workhorse/lib/python3.7/site-packages/nbformat/sign.py", line 255, in check_signature
    sqlite3.OperationalError: database is locked
[W 2022-06-14 16:24:33.698 ServerApp] 500 PUT /api/contents/jupyter_notebooks/paper/2a.Temperature_globalmap.ipynb?1655220265321 (::1): Unexpected error while saving file: jupyter_notebooks/paper/2a.Temperature_globalmap.ipynb database is locked
[W 2022-06-14 16:24:33.699 ServerApp] Unexpected error while saving file: jupyter_notebooks/paper/2a.Temperature_globalmap.ipynb database is locked
[E 2022-06-14 16:24:33.700 ServerApp] {
      "Host": "localhost:8885",
      "Accept": "*/*",
      "Referer": "http://localhost:8885/lab/tree/jupyter_notebooks/paper/2a.Temperature_globalmap.ipynb",
      "User-Agent": "Mozilla/5.0 (Macintosh; Intel Mac OS X 10_15_7) AppleWebKit/537.36 (KHTML, like Gecko) Chrome/100.0.4896.79 Safari/537.36"
    }
[E 2022-06-14 16:24:33.700 ServerApp] 500 PUT /api/contents/jupyter_notebooks/paper/2a.Temperature_globalmap.ipynb?1655220265321 (::1) 8270.76ms referer=http://localhost:8885/lab/tree/jupyter_notebooks/paper/2a.Temperature_globalmap.ipynb
[I 2022-06-14 16:26:28.634 ServerApp] Saving file at /jupyter_notebooks/paper/2a.Temperature_globalmap.ipynb
[E 2022-06-14 16:26:33.710 ServerApp] Error while saving file: jupyter_notebooks/paper/2a.Temperature_globalmap.ipynb database is locked
    Traceback (most recent call last):
      File "/home/k/kimpson/bin/conda/envs/workhorse/lib/python3.7/site-packages/jupyter_server/services/contents/filemanager.py", line 427, in save
      File "/home/k/kimpson/bin/conda/envs/workhorse/lib/python3.7/site-packages/jupyter_server/services/contents/manager.py", line 644, in check_and_sign
      File "/home/k/kimpson/bin/conda/envs/workhorse/lib/python3.7/site-packages/nbformat/sign.py", line 482, in sign
      File "/home/k/kimpson/bin/conda/envs/workhorse/lib/python3.7/site-packages/nbformat/sign.py", line 224, in store_signature
      File "/home/k/kimpson/bin/conda/envs/workhorse/lib/python3.7/site-packages/nbformat/sign.py", line 255, in check_signature
    sqlite3.OperationalError: database is locked
[W 2022-06-14 16:26:33.726 ServerApp] 500 PUT /api/contents/jupyter_notebooks/paper/2a.Temperature_globalmap.ipynb?1655220385347 (::1): Unexpected error while saving file: jupyter_notebooks/paper/2a.Temperature_globalmap.ipynb database is locked
[W 2022-06-14 16:26:33.727 ServerApp] Unexpected error while saving file: jupyter_notebooks/paper/2a.Temperature_globalmap.ipynb database is locked
[E 2022-06-14 16:26:33.728 ServerApp] {
      "Host": "localhost:8885",
      "Accept": "*/*",
      "Referer": "http://localhost:8885/lab/tree/jupyter_notebooks/paper/2a.Temperature_globalmap.ipynb",
      "User-Agent": "Mozilla/5.0 (Macintosh; Intel Mac OS X 10_15_7) AppleWebKit/537.36 (KHTML, like Gecko) Chrome/100.0.4896.79 Safari/537.36"
    }
[E 2022-06-14 16:26:33.728 ServerApp] 500 PUT /api/contents/jupyter_notebooks/paper/2a.Temperature_globalmap.ipynb?1655220385347 (::1) 8308.59ms referer=http://localhost:8885/lab/tree/jupyter_notebooks/paper/2a.Temperature_globalmap.ipynb
[I 2022-06-14 16:29:29.526 ServerApp] Saving file at /jupyter_notebooks/paper/2a.Temperature_globalmap.ipynb
[E 2022-06-14 16:29:34.608 ServerApp] Error while saving file: jupyter_notebooks/paper/2a.Temperature_globalmap.ipynb database is locked
    Traceback (most recent call last):
      File "/home/k/kimpson/bin/conda/envs/workhorse/lib/python3.7/site-packages/jupyter_server/services/contents/filemanager.py", line 427, in save
      File "/home/k/kimpson/bin/conda/envs/workhorse/lib/python3.7/site-packages/jupyter_server/services/contents/manager.py", line 644, in check_and_sign
      File "/home/k/kimpson/bin/conda/envs/workhorse/lib/python3.7/site-packages/nbformat/sign.py", line 482, in sign
      File "/home/k/kimpson/bin/conda/envs/workhorse/lib/python3.7/site-packages/nbformat/sign.py", line 224, in store_signature
      File "/home/k/kimpson/bin/conda/envs/workhorse/lib/python3.7/site-packages/nbformat/sign.py", line 255, in check_signature
    sqlite3.OperationalError: database is locked
[W 2022-06-14 16:29:34.624 ServerApp] 500 PUT /api/contents/jupyter_notebooks/paper/2a.Temperature_globalmap.ipynb?1655220566237 (::1): Unexpected error while saving file: jupyter_notebooks/paper/2a.Temperature_globalmap.ipynb database is locked
[W 2022-06-14 16:29:34.624 ServerApp] Unexpected error while saving file: jupyter_notebooks/paper/2a.Temperature_globalmap.ipynb database is locked
[E 2022-06-14 16:29:34.626 ServerApp] {
      "Host": "localhost:8885",
      "Accept": "*/*",
      "Referer": "http://localhost:8885/lab/tree/jupyter_notebooks/paper/2a.Temperature_globalmap.ipynb",
      "User-Agent": "Mozilla/5.0 (Macintosh; Intel Mac OS X 10_15_7) AppleWebKit/537.36 (KHTML, like Gecko) Chrome/100.0.4896.79 Safari/537.36"
    }
[E 2022-06-14 16:29:34.626 ServerApp] 500 PUT /api/contents/jupyter_notebooks/paper/2a.Temperature_globalmap.ipynb?1655220566237 (::1) 8278.20ms referer=http://localhost:8885/lab/tree/jupyter_notebooks/paper/2a.Temperature_globalmap.ipynb
[I 2022-06-14 16:32:28.719 ServerApp] Saving file at /jupyter_notebooks/paper/2a.Temperature_globalmap.ipynb
[E 2022-06-14 16:32:33.807 ServerApp] Error while saving file: jupyter_notebooks/paper/2a.Temperature_globalmap.ipynb database is locked
    Traceback (most recent call last):
      File "/home/k/kimpson/bin/conda/envs/workhorse/lib/python3.7/site-packages/jupyter_server/services/contents/filemanager.py", line 427, in save
      File "/home/k/kimpson/bin/conda/envs/workhorse/lib/python3.7/site-packages/jupyter_server/services/contents/manager.py", line 644, in check_and_sign
      File "/home/k/kimpson/bin/conda/envs/workhorse/lib/python3.7/site-packages/nbformat/sign.py", line 482, in sign
      File "/home/k/kimpson/bin/conda/envs/workhorse/lib/python3.7/site-packages/nbformat/sign.py", line 224, in store_signature
      File "/home/k/kimpson/bin/conda/envs/workhorse/lib/python3.7/site-packages/nbformat/sign.py", line 255, in check_signature
    sqlite3.OperationalError: database is locked
[W 2022-06-14 16:32:33.824 ServerApp] 500 PUT /api/contents/jupyter_notebooks/paper/2a.Temperature_globalmap.ipynb?1655220745390 (::1): Unexpected error while saving file: jupyter_notebooks/paper/2a.Temperature_globalmap.ipynb database is locked
[W 2022-06-14 16:32:33.825 ServerApp] Unexpected error while saving file: jupyter_notebooks/paper/2a.Temperature_globalmap.ipynb database is locked
[E 2022-06-14 16:32:33.827 ServerApp] {
      "Host": "localhost:8885",
      "Accept": "*/*",
      "Referer": "http://localhost:8885/lab/tree/jupyter_notebooks/paper/2a.Temperature_globalmap.ipynb",
      "User-Agent": "Mozilla/5.0 (Macintosh; Intel Mac OS X 10_15_7) AppleWebKit/537.36 (KHTML, like Gecko) Chrome/100.0.4896.79 Safari/537.36"
    }
[E 2022-06-14 16:32:33.828 ServerApp] 500 PUT /api/contents/jupyter_notebooks/paper/2a.Temperature_globalmap.ipynb?1655220745390 (::1) 8365.59ms referer=http://localhost:8885/lab/tree/jupyter_notebooks/paper/2a.Temperature_globalmap.ipynb
[I 2022-06-14 16:34:28.726 ServerApp] Saving file at /jupyter_notebooks/paper/2a.Temperature_globalmap.ipynb
[E 2022-06-14 16:34:33.806 ServerApp] Error while saving file: jupyter_notebooks/paper/2a.Temperature_globalmap.ipynb database is locked
    Traceback (most recent call last):
      File "/home/k/kimpson/bin/conda/envs/workhorse/lib/python3.7/site-packages/jupyter_server/services/contents/filemanager.py", line 427, in save
      File "/home/k/kimpson/bin/conda/envs/workhorse/lib/python3.7/site-packages/jupyter_server/services/contents/manager.py", line 644, in check_and_sign
      File "/home/k/kimpson/bin/conda/envs/workhorse/lib/python3.7/site-packages/nbformat/sign.py", line 482, in sign
      File "/home/k/kimpson/bin/conda/envs/workhorse/lib/python3.7/site-packages/nbformat/sign.py", line 224, in store_signature
      File "/home/k/kimpson/bin/conda/envs/workhorse/lib/python3.7/site-packages/nbformat/sign.py", line 255, in check_signature
    sqlite3.OperationalError: database is locked
[W 2022-06-14 16:34:33.823 ServerApp] 500 PUT /api/contents/jupyter_notebooks/paper/2a.Temperature_globalmap.ipynb?1655220865366 (::1): Unexpected error while saving file: jupyter_notebooks/paper/2a.Temperature_globalmap.ipynb database is locked
[W 2022-06-14 16:34:33.824 ServerApp] Unexpected error while saving file: jupyter_notebooks/paper/2a.Temperature_globalmap.ipynb database is locked
[E 2022-06-14 16:34:33.825 ServerApp] {
      "Host": "localhost:8885",
      "Accept": "*/*",
      "Referer": "http://localhost:8885/lab/tree/jupyter_notebooks/paper/2a.Temperature_globalmap.ipynb",
      "User-Agent": "Mozilla/5.0 (Macintosh; Intel Mac OS X 10_15_7) AppleWebKit/537.36 (KHTML, like Gecko) Chrome/100.0.4896.79 Safari/537.36"
    }
[E 2022-06-14 16:34:33.825 ServerApp] 500 PUT /api/contents/jupyter_notebooks/paper/2a.Temperature_globalmap.ipynb?1655220865366 (::1) 8277.98ms referer=http://localhost:8885/lab/tree/jupyter_notebooks/paper/2a.Temperature_globalmap.ipynb
[I 2022-06-14 16:37:28.647 ServerApp] Saving file at /jupyter_notebooks/paper/2a.Temperature_globalmap.ipynb
[E 2022-06-14 16:37:33.724 ServerApp] Error while saving file: jupyter_notebooks/paper/2a.Temperature_globalmap.ipynb database is locked
    Traceback (most recent call last):
      File "/home/k/kimpson/bin/conda/envs/workhorse/lib/python3.7/site-packages/jupyter_server/services/contents/filemanager.py", line 427, in save
      File "/home/k/kimpson/bin/conda/envs/workhorse/lib/python3.7/site-packages/jupyter_server/services/contents/manager.py", line 644, in check_and_sign
      File "/home/k/kimpson/bin/conda/envs/workhorse/lib/python3.7/site-packages/nbformat/sign.py", line 482, in sign
      File "/home/k/kimpson/bin/conda/envs/workhorse/lib/python3.7/site-packages/nbformat/sign.py", line 224, in store_signature
      File "/home/k/kimpson/bin/conda/envs/workhorse/lib/python3.7/site-packages/nbformat/sign.py", line 255, in check_signature
    sqlite3.OperationalError: database is locked
[W 2022-06-14 16:37:33.741 ServerApp] 500 PUT /api/contents/jupyter_notebooks/paper/2a.Temperature_globalmap.ipynb?1655221045286 (::1): Unexpected error while saving file: jupyter_notebooks/paper/2a.Temperature_globalmap.ipynb database is locked
[W 2022-06-14 16:37:33.741 ServerApp] Unexpected error while saving file: jupyter_notebooks/paper/2a.Temperature_globalmap.ipynb database is locked
[E 2022-06-14 16:37:33.742 ServerApp] {
      "Host": "localhost:8885",
      "Accept": "*/*",
      "Referer": "http://localhost:8885/lab/tree/jupyter_notebooks/paper/2a.Temperature_globalmap.ipynb",
      "User-Agent": "Mozilla/5.0 (Macintosh; Intel Mac OS X 10_15_7) AppleWebKit/537.36 (KHTML, like Gecko) Chrome/100.0.4896.79 Safari/537.36"
    }
[E 2022-06-14 16:37:33.743 ServerApp] 500 PUT /api/contents/jupyter_notebooks/paper/2a.Temperature_globalmap.ipynb?1655221045286 (::1) 8268.88ms referer=http://localhost:8885/lab/tree/jupyter_notebooks/paper/2a.Temperature_globalmap.ipynb
[I 2022-06-14 16:39:28.657 ServerApp] Saving file at /jupyter_notebooks/paper/2a.Temperature_globalmap.ipynb
[E 2022-06-14 16:39:33.735 ServerApp] Error while saving file: jupyter_notebooks/paper/2a.Temperature_globalmap.ipynb database is locked
    Traceback (most recent call last):
      File "/home/k/kimpson/bin/conda/envs/workhorse/lib/python3.7/site-packages/jupyter_server/services/contents/filemanager.py", line 427, in save
      File "/home/k/kimpson/bin/conda/envs/workhorse/lib/python3.7/site-packages/jupyter_server/services/contents/manager.py", line 644, in check_and_sign
      File "/home/k/kimpson/bin/conda/envs/workhorse/lib/python3.7/site-packages/nbformat/sign.py", line 482, in sign
      File "/home/k/kimpson/bin/conda/envs/workhorse/lib/python3.7/site-packages/nbformat/sign.py", line 224, in store_signature
      File "/home/k/kimpson/bin/conda/envs/workhorse/lib/python3.7/site-packages/nbformat/sign.py", line 255, in check_signature
    sqlite3.OperationalError: database is locked
[W 2022-06-14 16:39:33.751 ServerApp] 500 PUT /api/contents/jupyter_notebooks/paper/2a.Temperature_globalmap.ipynb?1655221165260 (::1): Unexpected error while saving file: jupyter_notebooks/paper/2a.Temperature_globalmap.ipynb database is locked
[W 2022-06-14 16:39:33.752 ServerApp] Unexpected error while saving file: jupyter_notebooks/paper/2a.Temperature_globalmap.ipynb database is locked
[E 2022-06-14 16:39:33.753 ServerApp] {
      "Host": "localhost:8885",
      "Accept": "*/*",
      "Referer": "http://localhost:8885/lab/tree/jupyter_notebooks/paper/2a.Temperature_globalmap.ipynb",
      "User-Agent": "Mozilla/5.0 (Macintosh; Intel Mac OS X 10_15_7) AppleWebKit/537.36 (KHTML, like Gecko) Chrome/100.0.4896.79 Safari/537.36"
    }
[E 2022-06-14 16:39:33.753 ServerApp] 500 PUT /api/contents/jupyter_notebooks/paper/2a.Temperature_globalmap.ipynb?1655221165260 (::1) 8272.02ms referer=http://localhost:8885/lab/tree/jupyter_notebooks/paper/2a.Temperature_globalmap.ipynb
[I 2022-06-14 16:42:28.868 ServerApp] Saving file at /jupyter_notebooks/paper/2a.Temperature_globalmap.ipynb
[E 2022-06-14 16:42:33.948 ServerApp] Error while saving file: jupyter_notebooks/paper/2a.Temperature_globalmap.ipynb database is locked
    Traceback (most recent call last):
      File "/home/k/kimpson/bin/conda/envs/workhorse/lib/python3.7/site-packages/jupyter_server/services/contents/filemanager.py", line 427, in save
      File "/home/k/kimpson/bin/conda/envs/workhorse/lib/python3.7/site-packages/jupyter_server/services/contents/manager.py", line 644, in check_and_sign
      File "/home/k/kimpson/bin/conda/envs/workhorse/lib/python3.7/site-packages/nbformat/sign.py", line 482, in sign
      File "/home/k/kimpson/bin/conda/envs/workhorse/lib/python3.7/site-packages/nbformat/sign.py", line 224, in store_signature
      File "/home/k/kimpson/bin/conda/envs/workhorse/lib/python3.7/site-packages/nbformat/sign.py", line 255, in check_signature
    sqlite3.OperationalError: database is locked
[W 2022-06-14 16:42:33.964 ServerApp] 500 PUT /api/contents/jupyter_notebooks/paper/2a.Temperature_globalmap.ipynb?1655221345287 (::1): Unexpected error while saving file: jupyter_notebooks/paper/2a.Temperature_globalmap.ipynb database is locked
[W 2022-06-14 16:42:33.965 ServerApp] Unexpected error while saving file: jupyter_notebooks/paper/2a.Temperature_globalmap.ipynb database is locked
[E 2022-06-14 16:42:33.966 ServerApp] {
      "Host": "localhost:8885",
      "Accept": "*/*",
      "Referer": "http://localhost:8885/lab/tree/jupyter_notebooks/paper/2a.Temperature_globalmap.ipynb",
      "User-Agent": "Mozilla/5.0 (Macintosh; Intel Mac OS X 10_15_7) AppleWebKit/537.36 (KHTML, like Gecko) Chrome/100.0.4896.79 Safari/537.36"
    }
[E 2022-06-14 16:42:33.966 ServerApp] 500 PUT /api/contents/jupyter_notebooks/paper/2a.Temperature_globalmap.ipynb?1655221345287 (::1) 8279.50ms referer=http://localhost:8885/lab/tree/jupyter_notebooks/paper/2a.Temperature_globalmap.ipynb
[I 2022-06-14 16:44:28.715 ServerApp] Saving file at /jupyter_notebooks/paper/2a.Temperature_globalmap.ipynb
[E 2022-06-14 16:44:33.796 ServerApp] Error while saving file: jupyter_notebooks/paper/2a.Temperature_globalmap.ipynb database is locked
    Traceback (most recent call last):
      File "/home/k/kimpson/bin/conda/envs/workhorse/lib/python3.7/site-packages/jupyter_server/services/contents/filemanager.py", line 427, in save
      File "/home/k/kimpson/bin/conda/envs/workhorse/lib/python3.7/site-packages/jupyter_server/services/contents/manager.py", line 644, in check_and_sign
      File "/home/k/kimpson/bin/conda/envs/workhorse/lib/python3.7/site-packages/nbformat/sign.py", line 482, in sign
      File "/home/k/kimpson/bin/conda/envs/workhorse/lib/python3.7/site-packages/nbformat/sign.py", line 224, in store_signature
      File "/home/k/kimpson/bin/conda/envs/workhorse/lib/python3.7/site-packages/nbformat/sign.py", line 255, in check_signature
    sqlite3.OperationalError: database is locked
[W 2022-06-14 16:44:33.812 ServerApp] 500 PUT /api/contents/jupyter_notebooks/paper/2a.Temperature_globalmap.ipynb?1655221465275 (::1): Unexpected error while saving file: jupyter_notebooks/paper/2a.Temperature_globalmap.ipynb database is locked
[W 2022-06-14 16:44:33.813 ServerApp] Unexpected error while saving file: jupyter_notebooks/paper/2a.Temperature_globalmap.ipynb database is locked
[E 2022-06-14 16:44:33.814 ServerApp] {
      "Host": "localhost:8885",
      "Accept": "*/*",
      "Referer": "http://localhost:8885/lab/tree/jupyter_notebooks/paper/2a.Temperature_globalmap.ipynb",
      "User-Agent": "Mozilla/5.0 (Macintosh; Intel Mac OS X 10_15_7) AppleWebKit/537.36 (KHTML, like Gecko) Chrome/100.0.4896.79 Safari/537.36"
    }
[E 2022-06-14 16:44:33.814 ServerApp] 500 PUT /api/contents/jupyter_notebooks/paper/2a.Temperature_globalmap.ipynb?1655221465275 (::1) 8332.51ms referer=http://localhost:8885/lab/tree/jupyter_notebooks/paper/2a.Temperature_globalmap.ipynb
[I 2022-06-14 16:46:36.854 ServerApp] Saving file at /jupyter_notebooks/paper/2a.Temperature_globalmap.ipynb
[E 2022-06-14 16:46:41.935 ServerApp] Error while saving file: jupyter_notebooks/paper/2a.Temperature_globalmap.ipynb database is locked
    Traceback (most recent call last):
      File "/home/k/kimpson/bin/conda/envs/workhorse/lib/python3.7/site-packages/jupyter_server/services/contents/filemanager.py", line 427, in save
      File "/home/k/kimpson/bin/conda/envs/workhorse/lib/python3.7/site-packages/jupyter_server/services/contents/manager.py", line 644, in check_and_sign
      File "/home/k/kimpson/bin/conda/envs/workhorse/lib/python3.7/site-packages/nbformat/sign.py", line 482, in sign
      File "/home/k/kimpson/bin/conda/envs/workhorse/lib/python3.7/site-packages/nbformat/sign.py", line 224, in store_signature
      File "/home/k/kimpson/bin/conda/envs/workhorse/lib/python3.7/site-packages/nbformat/sign.py", line 255, in check_signature
    sqlite3.OperationalError: database is locked
[W 2022-06-14 16:46:41.951 ServerApp] 500 PUT /api/contents/jupyter_notebooks/paper/2a.Temperature_globalmap.ipynb?1655221593487 (::1): Unexpected error while saving file: jupyter_notebooks/paper/2a.Temperature_globalmap.ipynb database is locked
[W 2022-06-14 16:46:41.951 ServerApp] Unexpected error while saving file: jupyter_notebooks/paper/2a.Temperature_globalmap.ipynb database is locked
[E 2022-06-14 16:46:41.953 ServerApp] {
      "Host": "localhost:8885",
      "Accept": "*/*",
      "Referer": "http://localhost:8885/lab/tree/jupyter_notebooks/paper/2a.Temperature_globalmap.ipynb",
      "User-Agent": "Mozilla/5.0 (Macintosh; Intel Mac OS X 10_15_7) AppleWebKit/537.36 (KHTML, like Gecko) Chrome/100.0.4896.79 Safari/537.36"
    }
[E 2022-06-14 16:46:41.954 ServerApp] 500 PUT /api/contents/jupyter_notebooks/paper/2a.Temperature_globalmap.ipynb?1655221593487 (::1) 8274.33ms referer=http://localhost:8885/lab/tree/jupyter_notebooks/paper/2a.Temperature_globalmap.ipynb
[I 2022-06-14 16:49:39.466 ServerApp] Saving file at /jupyter_notebooks/paper/2a.Temperature_globalmap.ipynb
[E 2022-06-14 16:49:44.546 ServerApp] Error while saving file: jupyter_notebooks/paper/2a.Temperature_globalmap.ipynb database is locked
    Traceback (most recent call last):
      File "/home/k/kimpson/bin/conda/envs/workhorse/lib/python3.7/site-packages/jupyter_server/services/contents/filemanager.py", line 427, in save
      File "/home/k/kimpson/bin/conda/envs/workhorse/lib/python3.7/site-packages/jupyter_server/services/contents/manager.py", line 644, in check_and_sign
      File "/home/k/kimpson/bin/conda/envs/workhorse/lib/python3.7/site-packages/nbformat/sign.py", line 482, in sign
      File "/home/k/kimpson/bin/conda/envs/workhorse/lib/python3.7/site-packages/nbformat/sign.py", line 224, in store_signature
      File "/home/k/kimpson/bin/conda/envs/workhorse/lib/python3.7/site-packages/nbformat/sign.py", line 255, in check_signature
    sqlite3.OperationalError: database is locked
[W 2022-06-14 16:49:44.562 ServerApp] 500 PUT /api/contents/jupyter_notebooks/paper/2a.Temperature_globalmap.ipynb?1655221776091 (::1): Unexpected error while saving file: jupyter_notebooks/paper/2a.Temperature_globalmap.ipynb database is locked
[W 2022-06-14 16:49:44.563 ServerApp] Unexpected error while saving file: jupyter_notebooks/paper/2a.Temperature_globalmap.ipynb database is locked
[E 2022-06-14 16:49:44.564 ServerApp] {
      "Host": "localhost:8885",
      "Accept": "*/*",
      "Referer": "http://localhost:8885/lab/tree/jupyter_notebooks/paper/2a.Temperature_globalmap.ipynb",
      "User-Agent": "Mozilla/5.0 (Macintosh; Intel Mac OS X 10_15_7) AppleWebKit/537.36 (KHTML, like Gecko) Chrome/100.0.4896.79 Safari/537.36"
    }
[E 2022-06-14 16:49:44.565 ServerApp] 500 PUT /api/contents/jupyter_notebooks/paper/2a.Temperature_globalmap.ipynb?1655221776091 (::1) 8274.91ms referer=http://localhost:8885/lab/tree/jupyter_notebooks/paper/2a.Temperature_globalmap.ipynb
[I 2022-06-14 16:52:30.892 ServerApp] Saving file at /jupyter_notebooks/paper/2a.Temperature_globalmap.ipynb
[E 2022-06-14 16:52:35.968 ServerApp] Error while saving file: jupyter_notebooks/paper/2a.Temperature_globalmap.ipynb database is locked
    Traceback (most recent call last):
      File "/home/k/kimpson/bin/conda/envs/workhorse/lib/python3.7/site-packages/jupyter_server/services/contents/filemanager.py", line 427, in save
      File "/home/k/kimpson/bin/conda/envs/workhorse/lib/python3.7/site-packages/jupyter_server/services/contents/manager.py", line 644, in check_and_sign
      File "/home/k/kimpson/bin/conda/envs/workhorse/lib/python3.7/site-packages/nbformat/sign.py", line 482, in sign
      File "/home/k/kimpson/bin/conda/envs/workhorse/lib/python3.7/site-packages/nbformat/sign.py", line 224, in store_signature
      File "/home/k/kimpson/bin/conda/envs/workhorse/lib/python3.7/site-packages/nbformat/sign.py", line 255, in check_signature
    sqlite3.OperationalError: database is locked
[W 2022-06-14 16:52:35.984 ServerApp] 500 PUT /api/contents/jupyter_notebooks/paper/2a.Temperature_globalmap.ipynb?1655221947510 (::1): Unexpected error while saving file: jupyter_notebooks/paper/2a.Temperature_globalmap.ipynb database is locked
[W 2022-06-14 16:52:35.985 ServerApp] Unexpected error while saving file: jupyter_notebooks/paper/2a.Temperature_globalmap.ipynb database is locked
[E 2022-06-14 16:52:35.986 ServerApp] {
      "Host": "localhost:8885",
      "Accept": "*/*",
      "Referer": "http://localhost:8885/lab/tree/jupyter_notebooks/paper/2a.Temperature_globalmap.ipynb",
      "User-Agent": "Mozilla/5.0 (Macintosh; Intel Mac OS X 10_15_7) AppleWebKit/537.36 (KHTML, like Gecko) Chrome/100.0.4896.79 Safari/537.36"
    }
[E 2022-06-14 16:52:35.986 ServerApp] 500 PUT /api/contents/jupyter_notebooks/paper/2a.Temperature_globalmap.ipynb?1655221947510 (::1) 8316.26ms referer=http://localhost:8885/lab/tree/jupyter_notebooks/paper/2a.Temperature_globalmap.ipynb
[I 2022-06-14 16:54:44.188 ServerApp] Saving file at /jupyter_notebooks/paper/2a.Temperature_globalmap.ipynb
[E 2022-06-14 16:54:49.267 ServerApp] Error while saving file: jupyter_notebooks/paper/2a.Temperature_globalmap.ipynb database is locked
    Traceback (most recent call last):
      File "/home/k/kimpson/bin/conda/envs/workhorse/lib/python3.7/site-packages/jupyter_server/services/contents/filemanager.py", line 427, in save
      File "/home/k/kimpson/bin/conda/envs/workhorse/lib/python3.7/site-packages/jupyter_server/services/contents/manager.py", line 644, in check_and_sign
      File "/home/k/kimpson/bin/conda/envs/workhorse/lib/python3.7/site-packages/nbformat/sign.py", line 482, in sign
      File "/home/k/kimpson/bin/conda/envs/workhorse/lib/python3.7/site-packages/nbformat/sign.py", line 224, in store_signature
      File "/home/k/kimpson/bin/conda/envs/workhorse/lib/python3.7/site-packages/nbformat/sign.py", line 255, in check_signature
    sqlite3.OperationalError: database is locked
[W 2022-06-14 16:54:49.284 ServerApp] 500 PUT /api/contents/jupyter_notebooks/paper/2a.Temperature_globalmap.ipynb?1655222078960 (::1): Unexpected error while saving file: jupyter_notebooks/paper/2a.Temperature_globalmap.ipynb database is locked
[W 2022-06-14 16:54:49.285 ServerApp] Unexpected error while saving file: jupyter_notebooks/paper/2a.Temperature_globalmap.ipynb database is locked
[E 2022-06-14 16:54:49.286 ServerApp] {
      "Host": "localhost:8885",
      "Accept": "*/*",
      "Referer": "http://localhost:8885/lab/tree/jupyter_notebooks/paper/2a.Temperature_globalmap.ipynb",
      "User-Agent": "Mozilla/5.0 (Macintosh; Intel Mac OS X 10_15_7) AppleWebKit/537.36 (KHTML, like Gecko) Chrome/100.0.4896.79 Safari/537.36"
    }
[E 2022-06-14 16:54:49.286 ServerApp] 500 PUT /api/contents/jupyter_notebooks/paper/2a.Temperature_globalmap.ipynb?1655222078960 (::1) 9161.14ms referer=http://localhost:8885/lab/tree/jupyter_notebooks/paper/2a.Temperature_globalmap.ipynb
[I 2022-06-14 16:56:51.447 ServerApp] Saving file at /jupyter_notebooks/paper/2a.Temperature_globalmap.ipynb
[E 2022-06-14 16:56:56.525 ServerApp] Error while saving file: jupyter_notebooks/paper/2a.Temperature_globalmap.ipynb database is locked
    Traceback (most recent call last):
      File "/home/k/kimpson/bin/conda/envs/workhorse/lib/python3.7/site-packages/jupyter_server/services/contents/filemanager.py", line 427, in save
      File "/home/k/kimpson/bin/conda/envs/workhorse/lib/python3.7/site-packages/jupyter_server/services/contents/manager.py", line 644, in check_and_sign
      File "/home/k/kimpson/bin/conda/envs/workhorse/lib/python3.7/site-packages/nbformat/sign.py", line 482, in sign
      File "/home/k/kimpson/bin/conda/envs/workhorse/lib/python3.7/site-packages/nbformat/sign.py", line 224, in store_signature
      File "/home/k/kimpson/bin/conda/envs/workhorse/lib/python3.7/site-packages/nbformat/sign.py", line 255, in check_signature
    sqlite3.OperationalError: database is locked
[W 2022-06-14 16:56:56.541 ServerApp] 500 PUT /api/contents/jupyter_notebooks/paper/2a.Temperature_globalmap.ipynb?1655222207697 (::1): Unexpected error while saving file: jupyter_notebooks/paper/2a.Temperature_globalmap.ipynb database is locked
[W 2022-06-14 16:56:56.542 ServerApp] Unexpected error while saving file: jupyter_notebooks/paper/2a.Temperature_globalmap.ipynb database is locked
[E 2022-06-14 16:56:56.543 ServerApp] {
      "Host": "localhost:8885",
      "Accept": "*/*",
      "Referer": "http://localhost:8885/lab/tree/jupyter_notebooks/paper/2a.Temperature_globalmap.ipynb",
      "User-Agent": "Mozilla/5.0 (Macintosh; Intel Mac OS X 10_15_7) AppleWebKit/537.36 (KHTML, like Gecko) Chrome/100.0.4896.79 Safari/537.36"
    }
[E 2022-06-14 16:56:56.544 ServerApp] 500 PUT /api/contents/jupyter_notebooks/paper/2a.Temperature_globalmap.ipynb?1655222207697 (::1) 8683.85ms referer=http://localhost:8885/lab/tree/jupyter_notebooks/paper/2a.Temperature_globalmap.ipynb
[I 2022-06-14 16:59:37.325 ServerApp] Saving file at /jupyter_notebooks/paper/2a.Temperature_globalmap.ipynb
[E 2022-06-14 16:59:42.410 ServerApp] Error while saving file: jupyter_notebooks/paper/2a.Temperature_globalmap.ipynb database is locked
    Traceback (most recent call last):
      File "/home/k/kimpson/bin/conda/envs/workhorse/lib/python3.7/site-packages/jupyter_server/services/contents/filemanager.py", line 427, in save
      File "/home/k/kimpson/bin/conda/envs/workhorse/lib/python3.7/site-packages/jupyter_server/services/contents/manager.py", line 644, in check_and_sign
      File "/home/k/kimpson/bin/conda/envs/workhorse/lib/python3.7/site-packages/nbformat/sign.py", line 482, in sign
      File "/home/k/kimpson/bin/conda/envs/workhorse/lib/python3.7/site-packages/nbformat/sign.py", line 224, in store_signature
      File "/home/k/kimpson/bin/conda/envs/workhorse/lib/python3.7/site-packages/nbformat/sign.py", line 255, in check_signature
    sqlite3.OperationalError: database is locked
[W 2022-06-14 16:59:42.427 ServerApp] 500 PUT /api/contents/jupyter_notebooks/paper/2a.Temperature_globalmap.ipynb?1655222373211 (::1): Unexpected error while saving file: jupyter_notebooks/paper/2a.Temperature_globalmap.ipynb database is locked
[W 2022-06-14 16:59:42.428 ServerApp] Unexpected error while saving file: jupyter_notebooks/paper/2a.Temperature_globalmap.ipynb database is locked
[E 2022-06-14 16:59:42.430 ServerApp] {
      "Host": "localhost:8885",
      "Accept": "*/*",
      "Referer": "http://localhost:8885/lab/tree/jupyter_notebooks/paper/2a.Temperature_globalmap.ipynb",
      "User-Agent": "Mozilla/5.0 (Macintosh; Intel Mac OS X 10_15_7) AppleWebKit/537.36 (KHTML, like Gecko) Chrome/100.0.4896.79 Safari/537.36"
    }
[E 2022-06-14 16:59:42.430 ServerApp] 500 PUT /api/contents/jupyter_notebooks/paper/2a.Temperature_globalmap.ipynb?1655222373211 (::1) 9017.98ms referer=http://localhost:8885/lab/tree/jupyter_notebooks/paper/2a.Temperature_globalmap.ipynb
[I 2022-06-14 17:01:42.173 ServerApp] Saving file at /jupyter_notebooks/paper/2a.Temperature_globalmap.ipynb
[E 2022-06-14 17:01:47.256 ServerApp] Error while saving file: jupyter_notebooks/paper/2a.Temperature_globalmap.ipynb database is locked
    Traceback (most recent call last):
      File "/home/k/kimpson/bin/conda/envs/workhorse/lib/python3.7/site-packages/jupyter_server/services/contents/filemanager.py", line 427, in save
      File "/home/k/kimpson/bin/conda/envs/workhorse/lib/python3.7/site-packages/jupyter_server/services/contents/manager.py", line 644, in check_and_sign
      File "/home/k/kimpson/bin/conda/envs/workhorse/lib/python3.7/site-packages/nbformat/sign.py", line 482, in sign
      File "/home/k/kimpson/bin/conda/envs/workhorse/lib/python3.7/site-packages/nbformat/sign.py", line 224, in store_signature
      File "/home/k/kimpson/bin/conda/envs/workhorse/lib/python3.7/site-packages/nbformat/sign.py", line 255, in check_signature
    sqlite3.OperationalError: database is locked
[W 2022-06-14 17:01:47.272 ServerApp] 500 PUT /api/contents/jupyter_notebooks/paper/2a.Temperature_globalmap.ipynb?1655222498199 (::1): Unexpected error while saving file: jupyter_notebooks/paper/2a.Temperature_globalmap.ipynb database is locked
[W 2022-06-14 17:01:47.273 ServerApp] Unexpected error while saving file: jupyter_notebooks/paper/2a.Temperature_globalmap.ipynb database is locked
[E 2022-06-14 17:01:47.274 ServerApp] {
      "Host": "localhost:8885",
      "Accept": "*/*",
      "Referer": "http://localhost:8885/lab/tree/jupyter_notebooks/paper/2a.Temperature_globalmap.ipynb",
      "User-Agent": "Mozilla/5.0 (Macintosh; Intel Mac OS X 10_15_7) AppleWebKit/537.36 (KHTML, like Gecko) Chrome/100.0.4896.79 Safari/537.36"
    }
[E 2022-06-14 17:01:47.274 ServerApp] 500 PUT /api/contents/jupyter_notebooks/paper/2a.Temperature_globalmap.ipynb?1655222498199 (::1) 8908.03ms referer=http://localhost:8885/lab/tree/jupyter_notebooks/paper/2a.Temperature_globalmap.ipynb
[I 2022-06-14 17:03:49.043 ServerApp] Saving file at /jupyter_notebooks/paper/2a.Temperature_globalmap.ipynb
[E 2022-06-14 17:03:54.121 ServerApp] Error while saving file: jupyter_notebooks/paper/2a.Temperature_globalmap.ipynb database is locked
    Traceback (most recent call last):
      File "/home/k/kimpson/bin/conda/envs/workhorse/lib/python3.7/site-packages/jupyter_server/services/contents/filemanager.py", line 427, in save
      File "/home/k/kimpson/bin/conda/envs/workhorse/lib/python3.7/site-packages/jupyter_server/services/contents/manager.py", line 644, in check_and_sign
      File "/home/k/kimpson/bin/conda/envs/workhorse/lib/python3.7/site-packages/nbformat/sign.py", line 482, in sign
      File "/home/k/kimpson/bin/conda/envs/workhorse/lib/python3.7/site-packages/nbformat/sign.py", line 224, in store_signature
      File "/home/k/kimpson/bin/conda/envs/workhorse/lib/python3.7/site-packages/nbformat/sign.py", line 255, in check_signature
    sqlite3.OperationalError: database is locked
[W 2022-06-14 17:03:54.135 ServerApp] 500 PUT /api/contents/jupyter_notebooks/paper/2a.Temperature_globalmap.ipynb?1655222625610 (::1): Unexpected error while saving file: jupyter_notebooks/paper/2a.Temperature_globalmap.ipynb database is locked
[W 2022-06-14 17:03:54.136 ServerApp] Unexpected error while saving file: jupyter_notebooks/paper/2a.Temperature_globalmap.ipynb database is locked
[E 2022-06-14 17:03:54.137 ServerApp] {
      "Host": "localhost:8885",
      "Accept": "*/*",
      "Referer": "http://localhost:8885/lab/tree/jupyter_notebooks/paper/2a.Temperature_globalmap.ipynb",
      "User-Agent": "Mozilla/5.0 (Macintosh; Intel Mac OS X 10_15_7) AppleWebKit/537.36 (KHTML, like Gecko) Chrome/100.0.4896.79 Safari/537.36"
    }
[E 2022-06-14 17:03:54.138 ServerApp] 500 PUT /api/contents/jupyter_notebooks/paper/2a.Temperature_globalmap.ipynb?1655222625610 (::1) 8323.45ms referer=http://localhost:8885/lab/tree/jupyter_notebooks/paper/2a.Temperature_globalmap.ipynb
[I 2022-06-14 17:06:48.638 ServerApp] Saving file at /jupyter_notebooks/paper/2a.Temperature_globalmap.ipynb
[E 2022-06-14 17:06:53.717 ServerApp] Error while saving file: jupyter_notebooks/paper/2a.Temperature_globalmap.ipynb database is locked
    Traceback (most recent call last):
      File "/home/k/kimpson/bin/conda/envs/workhorse/lib/python3.7/site-packages/jupyter_server/services/contents/filemanager.py", line 427, in save
      File "/home/k/kimpson/bin/conda/envs/workhorse/lib/python3.7/site-packages/jupyter_server/services/contents/manager.py", line 644, in check_and_sign
      File "/home/k/kimpson/bin/conda/envs/workhorse/lib/python3.7/site-packages/nbformat/sign.py", line 482, in sign
      File "/home/k/kimpson/bin/conda/envs/workhorse/lib/python3.7/site-packages/nbformat/sign.py", line 224, in store_signature
      File "/home/k/kimpson/bin/conda/envs/workhorse/lib/python3.7/site-packages/nbformat/sign.py", line 255, in check_signature
    sqlite3.OperationalError: database is locked
[W 2022-06-14 17:06:53.726 ServerApp] 500 PUT /api/contents/jupyter_notebooks/paper/2a.Temperature_globalmap.ipynb?1655222805024 (::1): Unexpected error while saving file: jupyter_notebooks/paper/2a.Temperature_globalmap.ipynb database is locked
[W 2022-06-14 17:06:53.727 ServerApp] Unexpected error while saving file: jupyter_notebooks/paper/2a.Temperature_globalmap.ipynb database is locked
[E 2022-06-14 17:06:53.728 ServerApp] {
      "Host": "localhost:8885",
      "Accept": "*/*",
      "Referer": "http://localhost:8885/lab/tree/jupyter_notebooks/paper/2a.Temperature_globalmap.ipynb",
      "User-Agent": "Mozilla/5.0 (Macintosh; Intel Mac OS X 10_15_7) AppleWebKit/537.36 (KHTML, like Gecko) Chrome/100.0.4896.79 Safari/537.36"
    }
[E 2022-06-14 17:06:53.729 ServerApp] 500 PUT /api/contents/jupyter_notebooks/paper/2a.Temperature_globalmap.ipynb?1655222805024 (::1) 8388.86ms referer=http://localhost:8885/lab/tree/jupyter_notebooks/paper/2a.Temperature_globalmap.ipynb
[I 2022-06-14 17:08:48.528 ServerApp] Saving file at /jupyter_notebooks/paper/2a.Temperature_globalmap.ipynb
[E 2022-06-14 17:08:53.612 ServerApp] Error while saving file: jupyter_notebooks/paper/2a.Temperature_globalmap.ipynb database is locked
    Traceback (most recent call last):
      File "/home/k/kimpson/bin/conda/envs/workhorse/lib/python3.7/site-packages/jupyter_server/services/contents/filemanager.py", line 427, in save
      File "/home/k/kimpson/bin/conda/envs/workhorse/lib/python3.7/site-packages/jupyter_server/services/contents/manager.py", line 644, in check_and_sign
      File "/home/k/kimpson/bin/conda/envs/workhorse/lib/python3.7/site-packages/nbformat/sign.py", line 482, in sign
      File "/home/k/kimpson/bin/conda/envs/workhorse/lib/python3.7/site-packages/nbformat/sign.py", line 224, in store_signature
      File "/home/k/kimpson/bin/conda/envs/workhorse/lib/python3.7/site-packages/nbformat/sign.py", line 255, in check_signature
    sqlite3.OperationalError: database is locked
[W 2022-06-14 17:08:53.622 ServerApp] 500 PUT /api/contents/jupyter_notebooks/paper/2a.Temperature_globalmap.ipynb?1655222925000 (::1): Unexpected error while saving file: jupyter_notebooks/paper/2a.Temperature_globalmap.ipynb database is locked
[W 2022-06-14 17:08:53.622 ServerApp] Unexpected error while saving file: jupyter_notebooks/paper/2a.Temperature_globalmap.ipynb database is locked
[E 2022-06-14 17:08:53.623 ServerApp] {
      "Host": "localhost:8885",
      "Accept": "*/*",
      "Referer": "http://localhost:8885/lab/tree/jupyter_notebooks/paper/2a.Temperature_globalmap.ipynb",
      "User-Agent": "Mozilla/5.0 (Macintosh; Intel Mac OS X 10_15_7) AppleWebKit/537.36 (KHTML, like Gecko) Chrome/100.0.4896.79 Safari/537.36"
    }
[E 2022-06-14 17:08:53.624 ServerApp] 500 PUT /api/contents/jupyter_notebooks/paper/2a.Temperature_globalmap.ipynb?1655222925000 (::1) 8370.70ms referer=http://localhost:8885/lab/tree/jupyter_notebooks/paper/2a.Temperature_globalmap.ipynb
[I 2022-06-14 17:10:48.609 ServerApp] Saving file at /jupyter_notebooks/paper/2a.Temperature_globalmap.ipynb
[E 2022-06-14 17:10:53.686 ServerApp] Error while saving file: jupyter_notebooks/paper/2a.Temperature_globalmap.ipynb database is locked
    Traceback (most recent call last):
      File "/home/k/kimpson/bin/conda/envs/workhorse/lib/python3.7/site-packages/jupyter_server/services/contents/filemanager.py", line 427, in save
      File "/home/k/kimpson/bin/conda/envs/workhorse/lib/python3.7/site-packages/jupyter_server/services/contents/manager.py", line 644, in check_and_sign
      File "/home/k/kimpson/bin/conda/envs/workhorse/lib/python3.7/site-packages/nbformat/sign.py", line 482, in sign
      File "/home/k/kimpson/bin/conda/envs/workhorse/lib/python3.7/site-packages/nbformat/sign.py", line 224, in store_signature
      File "/home/k/kimpson/bin/conda/envs/workhorse/lib/python3.7/site-packages/nbformat/sign.py", line 255, in check_signature
    sqlite3.OperationalError: database is locked
[W 2022-06-14 17:10:53.695 ServerApp] 500 PUT /api/contents/jupyter_notebooks/paper/2a.Temperature_globalmap.ipynb?1655223045004 (::1): Unexpected error while saving file: jupyter_notebooks/paper/2a.Temperature_globalmap.ipynb database is locked
[W 2022-06-14 17:10:53.695 ServerApp] Unexpected error while saving file: jupyter_notebooks/paper/2a.Temperature_globalmap.ipynb database is locked
[E 2022-06-14 17:10:53.696 ServerApp] {
      "Host": "localhost:8885",
      "Accept": "*/*",
      "Referer": "http://localhost:8885/lab/tree/jupyter_notebooks/paper/2a.Temperature_globalmap.ipynb",
      "User-Agent": "Mozilla/5.0 (Macintosh; Intel Mac OS X 10_15_7) AppleWebKit/537.36 (KHTML, like Gecko) Chrome/100.0.4896.79 Safari/537.36"
    }
[E 2022-06-14 17:10:53.697 ServerApp] 500 PUT /api/contents/jupyter_notebooks/paper/2a.Temperature_globalmap.ipynb?1655223045004 (::1) 8520.44ms referer=http://localhost:8885/lab/tree/jupyter_notebooks/paper/2a.Temperature_globalmap.ipynb
[E 2022-06-14 17:11:38.509 ServerApp] Uncaught exception GET /lab/tree/jupyter_notebooks/paper/2a.Temperature_globalmap.ipynb (::1)
    HTTPServerRequest(protocol='http', host='localhost:8885', method='GET', uri='/lab/tree/jupyter_notebooks/paper/2a.Temperature_globalmap.ipynb', version='HTTP/1.1', remote_ip='::1')
    Traceback (most recent call last):
      File "/home/k/kimpson/bin/conda/envs/workhorse/lib/python3.7/site-packages/jupyter_server/extension/handler.py", line 15, in get_template
      File "/home/k/kimpson/bin/conda/envs/workhorse/lib/python3.7/site-packages/jinja2/environment.py", line 997, in get_template
      File "/home/k/kimpson/bin/conda/envs/workhorse/lib/python3.7/site-packages/jinja2/environment.py", line 958, in _load_template
      File "/home/k/kimpson/bin/conda/envs/workhorse/lib/python3.7/site-packages/jinja2/loaders.py", line 125, in load
      File "/home/k/kimpson/bin/conda/envs/workhorse/lib/python3.7/site-packages/jinja2/loaders.py", line 214, in get_source
    jinja2.exceptions.TemplateNotFound: index.html
    
    During handling of the above exception, another exception occurred:
    
    Traceback (most recent call last):
      File "/home/k/kimpson/bin/conda/envs/workhorse/lib/python3.7/site-packages/tornado/web.py", line 1702, in _execute
      File "/home/k/kimpson/bin/conda/envs/workhorse/lib/python3.7/site-packages/tornado/web.py", line 3173, in wrapper
      File "/home/k/kimpson/bin/conda/envs/workhorse/lib/python3.7/site-packages/tornado/web.py", line 1878, in wrapper
      File "/home/k/kimpson/bin/conda/envs/workhorse/lib/python3.7/site-packages/jupyterlab_server/handlers.py", line 158, in get
      File "/home/k/kimpson/bin/conda/envs/workhorse/lib/python3.7/site-packages/jupyter_server/base/handlers.py", line 525, in render_template
      File "/home/k/kimpson/bin/conda/envs/workhorse/lib/python3.7/site-packages/jupyter_server/extension/handler.py", line 17, in get_template
      File "/home/k/kimpson/bin/conda/envs/workhorse/lib/python3.7/site-packages/jupyter_server/base/handlers.py", line 521, in get_template
      File "/home/k/kimpson/bin/conda/envs/workhorse/lib/python3.7/site-packages/jinja2/environment.py", line 997, in get_template
      File "/home/k/kimpson/bin/conda/envs/workhorse/lib/python3.7/site-packages/jinja2/environment.py", line 958, in _load_template
      File "/home/k/kimpson/bin/conda/envs/workhorse/lib/python3.7/site-packages/jinja2/loaders.py", line 125, in load
      File "/home/k/kimpson/bin/conda/envs/workhorse/lib/python3.7/site-packages/jinja2/loaders.py", line 214, in get_source
    jinja2.exceptions.TemplateNotFound: index.html
[E 2022-06-14 17:11:38.540 ServerApp] Uncaught exception in write_error
    Traceback (most recent call last):
      File "/home/k/kimpson/bin/conda/envs/workhorse/lib/python3.7/site-packages/jupyter_server/extension/handler.py", line 15, in get_template
      File "/home/k/kimpson/bin/conda/envs/workhorse/lib/python3.7/site-packages/jinja2/environment.py", line 997, in get_template
      File "/home/k/kimpson/bin/conda/envs/workhorse/lib/python3.7/site-packages/jinja2/environment.py", line 958, in _load_template
      File "/home/k/kimpson/bin/conda/envs/workhorse/lib/python3.7/site-packages/jinja2/loaders.py", line 125, in load
      File "/home/k/kimpson/bin/conda/envs/workhorse/lib/python3.7/site-packages/jinja2/loaders.py", line 214, in get_source
    jinja2.exceptions.TemplateNotFound: index.html
    
    During handling of the above exception, another exception occurred:
    
    Traceback (most recent call last):
      File "/home/k/kimpson/bin/conda/envs/workhorse/lib/python3.7/site-packages/tornado/web.py", line 1702, in _execute
      File "/home/k/kimpson/bin/conda/envs/workhorse/lib/python3.7/site-packages/tornado/web.py", line 3173, in wrapper
      File "/home/k/kimpson/bin/conda/envs/workhorse/lib/python3.7/site-packages/tornado/web.py", line 1878, in wrapper
      File "/home/k/kimpson/bin/conda/envs/workhorse/lib/python3.7/site-packages/jupyterlab_server/handlers.py", line 158, in get
      File "/home/k/kimpson/bin/conda/envs/workhorse/lib/python3.7/site-packages/jupyter_server/base/handlers.py", line 525, in render_template
      File "/home/k/kimpson/bin/conda/envs/workhorse/lib/python3.7/site-packages/jupyter_server/extension/handler.py", line 17, in get_template
      File "/home/k/kimpson/bin/conda/envs/workhorse/lib/python3.7/site-packages/jupyter_server/base/handlers.py", line 521, in get_template
      File "/home/k/kimpson/bin/conda/envs/workhorse/lib/python3.7/site-packages/jinja2/environment.py", line 997, in get_template
      File "/home/k/kimpson/bin/conda/envs/workhorse/lib/python3.7/site-packages/jinja2/environment.py", line 958, in _load_template
      File "/home/k/kimpson/bin/conda/envs/workhorse/lib/python3.7/site-packages/jinja2/loaders.py", line 125, in load
      File "/home/k/kimpson/bin/conda/envs/workhorse/lib/python3.7/site-packages/jinja2/loaders.py", line 214, in get_source
    jinja2.exceptions.TemplateNotFound: index.html
    
    During handling of the above exception, another exception occurred:
    
    Traceback (most recent call last):
      File "/home/k/kimpson/bin/conda/envs/workhorse/lib/python3.7/site-packages/jupyter_server/extension/handler.py", line 15, in get_template
      File "/home/k/kimpson/bin/conda/envs/workhorse/lib/python3.7/site-packages/jinja2/environment.py", line 997, in get_template
      File "/home/k/kimpson/bin/conda/envs/workhorse/lib/python3.7/site-packages/jinja2/environment.py", line 958, in _load_template
      File "/home/k/kimpson/bin/conda/envs/workhorse/lib/python3.7/site-packages/jinja2/loaders.py", line 125, in load
      File "/home/k/kimpson/bin/conda/envs/workhorse/lib/python3.7/site-packages/jinja2/loaders.py", line 214, in get_source
    jinja2.exceptions.TemplateNotFound: 500.html
    
    During handling of the above exception, another exception occurred:
    
    Traceback (most recent call last):
      File "/home/k/kimpson/bin/conda/envs/workhorse/lib/python3.7/site-packages/jupyter_server/base/handlers.py", line 595, in write_error
      File "/home/k/kimpson/bin/conda/envs/workhorse/lib/python3.7/site-packages/jupyter_server/base/handlers.py", line 525, in render_template
      File "/home/k/kimpson/bin/conda/envs/workhorse/lib/python3.7/site-packages/jupyter_server/extension/handler.py", line 17, in get_template
      File "/home/k/kimpson/bin/conda/envs/workhorse/lib/python3.7/site-packages/jupyter_server/base/handlers.py", line 521, in get_template
      File "/home/k/kimpson/bin/conda/envs/workhorse/lib/python3.7/site-packages/jinja2/environment.py", line 997, in get_template
      File "/home/k/kimpson/bin/conda/envs/workhorse/lib/python3.7/site-packages/jinja2/environment.py", line 958, in _load_template
      File "/home/k/kimpson/bin/conda/envs/workhorse/lib/python3.7/site-packages/jinja2/loaders.py", line 125, in load
      File "/home/k/kimpson/bin/conda/envs/workhorse/lib/python3.7/site-packages/jinja2/loaders.py", line 214, in get_source
    jinja2.exceptions.TemplateNotFound: 500.html
    
    During handling of the above exception, another exception occurred:
    
    Traceback (most recent call last):
      File "/home/k/kimpson/bin/conda/envs/workhorse/lib/python3.7/site-packages/jupyter_server/extension/handler.py", line 15, in get_template
      File "/home/k/kimpson/bin/conda/envs/workhorse/lib/python3.7/site-packages/jinja2/environment.py", line 997, in get_template
      File "/home/k/kimpson/bin/conda/envs/workhorse/lib/python3.7/site-packages/jinja2/environment.py", line 958, in _load_template
      File "/home/k/kimpson/bin/conda/envs/workhorse/lib/python3.7/site-packages/jinja2/loaders.py", line 125, in load
      File "/home/k/kimpson/bin/conda/envs/workhorse/lib/python3.7/site-packages/jinja2/loaders.py", line 214, in get_source
    jinja2.exceptions.TemplateNotFound: error.html
    
    During handling of the above exception, another exception occurred:
    
    Traceback (most recent call last):
      File "/home/k/kimpson/bin/conda/envs/workhorse/lib/python3.7/site-packages/tornado/web.py", line 1217, in send_error
      File "/home/k/kimpson/bin/conda/envs/workhorse/lib/python3.7/site-packages/jupyter_server/base/handlers.py", line 597, in write_error
      File "/home/k/kimpson/bin/conda/envs/workhorse/lib/python3.7/site-packages/jupyter_server/base/handlers.py", line 525, in render_template
      File "/home/k/kimpson/bin/conda/envs/workhorse/lib/python3.7/site-packages/jupyter_server/extension/handler.py", line 17, in get_template
      File "/home/k/kimpson/bin/conda/envs/workhorse/lib/python3.7/site-packages/jupyter_server/base/handlers.py", line 521, in get_template
      File "/home/k/kimpson/bin/conda/envs/workhorse/lib/python3.7/site-packages/jinja2/environment.py", line 997, in get_template
      File "/home/k/kimpson/bin/conda/envs/workhorse/lib/python3.7/site-packages/jinja2/environment.py", line 958, in _load_template
      File "/home/k/kimpson/bin/conda/envs/workhorse/lib/python3.7/site-packages/jinja2/loaders.py", line 125, in load
      File "/home/k/kimpson/bin/conda/envs/workhorse/lib/python3.7/site-packages/jinja2/loaders.py", line 214, in get_source
    jinja2.exceptions.TemplateNotFound: error.html
[E 2022-06-14 17:11:38.605 LabApp] {
      "Host": "localhost:8885",
      "Accept": "text/html,application/xhtml+xml,application/xml;q=0.9,image/avif,image/webp,image/apng,*/*;q=0.8,application/signed-exchange;v=b3;q=0.9",
      "User-Agent": "Mozilla/5.0 (Macintosh; Intel Mac OS X 10_15_7) AppleWebKit/537.36 (KHTML, like Gecko) Chrome/100.0.4896.79 Safari/537.36"
    }
[E 2022-06-14 17:11:38.606 LabApp] 500 GET /lab/tree/jupyter_notebooks/paper/2a.Temperature_globalmap.ipynb (::1) 122.52ms referer=None
[I 2022-06-14 17:11:38.903 ServerApp] Starting buffering for 9d5c4c84-d95d-45be-9c9f-212a7cc53f5a:da1ec78e-eeff-4a40-bc29-36755d9c92a8
[I 2022-06-14 17:11:38.905 ServerApp] Starting buffering for 9aac199e-45ec-4a45-9eb8-e3bf34a8a587:d9da9fba-c10f-4acb-bfb6-a6f22257d58e
[I 2022-06-14 17:11:38.907 ServerApp] Starting buffering for 406b89bf-6704-4f5c-81a6-a49361f6aafd:be700d45-81d7-453a-b9cd-00f1aa531701
[I 2022-06-14 17:11:38.908 ServerApp] Starting buffering for 6d665d7c-f556-4438-a1f9-d614a2533813:03ff7ca9-6bd7-4de1-91e4-fcaef10e8eb8
[I 2022-06-14 17:11:38.909 ServerApp] Starting buffering for f6d2ed52-7440-4378-9ed5-d917f03e7f9b:ccb2dae3-311d-4691-bb7a-175e3f014c21
[I 2022-06-14 17:11:38.911 ServerApp] Starting buffering for 4dc1853a-044e-4c3a-a63f-0c24d583e060:cba1a7a1-db9a-429f-8d68-3f1cda627a9c
[I 2022-06-14 17:12:05.125 ServerApp] 302 GET / (::1) 2.45ms
[I 2022-06-14 17:12:15.416 LabApp] Build is up to date
[I 2022-06-14 17:16:07.449 ServerApp] Saving file at /jupyter_notebooks/paper/2a.Temperature_globalmap.ipynb
[I 2022-06-14 17:20:12.001 ServerApp] Saving file at /jupyter_notebooks/paper/2a.Temperature_globalmap.ipynb
[I 2022-06-14 17:22:14.603 ServerApp] Saving file at /jupyter_notebooks/paper/2a.Temperature_globalmap.ipynb
[I 2022-06-14 17:22:40.802 ServerApp] Saving file at /jupyter_notebooks/paper/2a.Temperature_globalmap.ipynb
[I 2022-06-14 17:22:47.140 ServerApp] Copying jupyter_notebooks/paper/2a.Temperature_globalmap.ipynb to /jupyter_notebooks/paper
[I 2022-06-14 17:23:10.775 ServerApp] Kernel started: 0e60fa2d-c1b2-43f3-848f-589e858bad64
[I 2022-06-14 17:23:14.710 ServerApp] Saving file at /jupyter_notebooks/paper/2a.Temperature_globalmap.ipynb
[I 2022-06-14 17:28:49.827 ServerApp] Saving file at /jupyter_notebooks/paper/2b.Precipitation_globalmap.ipynb
[I 2022-06-14 17:30:52.524 ServerApp] Saving file at /jupyter_notebooks/paper/2b.Precipitation_globalmap.ipynb
[I 2022-06-14 17:32:55.210 ServerApp] Saving file at /jupyter_notebooks/paper/2b.Precipitation_globalmap.ipynb
[I 2022-06-14 17:34:59.390 ServerApp] Saving file at /jupyter_notebooks/paper/2b.Precipitation_globalmap.ipynb
[I 2022-06-14 17:43:02.571 ServerApp] Saving file at /jupyter_notebooks/paper/2b.Precipitation_globalmap.ipynb
[I 2022-06-14 17:45:03.464 ServerApp] Saving file at /jupyter_notebooks/paper/2b.Precipitation_globalmap.ipynb
[I 2022-06-14 17:59:38.729 ServerApp] Saving file at /jupyter_notebooks/paper/2b.Precipitation_globalmap.ipynb
[I 2022-06-14 18:27:44.910 ServerApp] Saving file at /jupyter_notebooks/paper/2b.Precipitation_globalmap.ipynb
[I 2022-06-14 18:57:45.837 ServerApp] Saving file at /jupyter_notebooks/paper/2b.Precipitation_globalmap.ipynb
[I 2022-06-14 19:25:46.260 ServerApp] Saving file at /jupyter_notebooks/paper/2b.Precipitation_globalmap.ipynb
[I 2022-06-15 08:23:50.669 ServerApp] Saving file at /jupyter_notebooks/paper/2b.Precipitation_globalmap.ipynb
[I 2022-06-15 08:25:54.728 ServerApp] Saving file at /jupyter_notebooks/paper/2b.Precipitation_globalmap.ipynb
[I 2022-06-15 08:27:58.801 ServerApp] Saving file at /jupyter_notebooks/paper/2b.Precipitation_globalmap.ipynb
[I 2022-06-15 09:32:04.236 ServerApp] Saving file at /jupyter_notebooks/paper/2b.Precipitation_globalmap.ipynb
[I 2022-06-15 09:34:09.507 ServerApp] Saving file at /jupyter_notebooks/paper/2b.Precipitation_globalmap.ipynb
[I 2022-06-15 09:36:14.255 ServerApp] Saving file at /jupyter_notebooks/paper/2b.Precipitation_globalmap.ipynb
[I 2022-06-15 09:38:19.123 ServerApp] Saving file at /jupyter_notebooks/paper/2b.Precipitation_globalmap.ipynb
[I 2022-06-15 09:39:24.325 ServerApp] Saving file at /jupyter_notebooks/paper/2b.Precipitation_globalmap.ipynb
[I 2022-06-15 09:41:28.340 ServerApp] Saving file at /jupyter_notebooks/paper/2b.Precipitation_globalmap.ipynb
[I 2022-06-15 09:43:32.648 ServerApp] Saving file at /jupyter_notebooks/paper/2b.Precipitation_globalmap.ipynb
[I 2022-06-15 09:44:56.805 ServerApp] Saving file at /jupyter_notebooks/paper/2b.Precipitation_globalmap.ipynb
[I 2022-06-15 09:45:00.009 ServerApp] Saving file at /jupyter_notebooks/paper/2b.Precipitation_globalmap.ipynb
[I 2022-06-15 10:00:01.500 ServerApp] Kernel started: 3ba76382-4e4c-4cb7-8b24-b339af6dbd50
[I 2022-06-15 10:02:02.045 ServerApp] Saving file at /jupyter_notebooks/5.Timeseries_MixedPrecision.ipynb
[I 2022-06-15 10:06:03.537 ServerApp] Saving file at /jupyter_notebooks/5.Timeseries_MixedPrecision.ipynb
[I 2022-06-15 10:08:04.916 ServerApp] Saving file at /jupyter_notebooks/5.Timeseries_MixedPrecision.ipynb
[I 2022-06-15 10:10:06.364 ServerApp] Saving file at /jupyter_notebooks/5.Timeseries_MixedPrecision.ipynb
[I 2022-06-15 11:24:30.554 ServerApp] Saving file at /jupyter_notebooks/paper/2b.Precipitation_globalmap.ipynb
[I 2022-06-15 11:26:35.825 ServerApp] Saving file at /jupyter_notebooks/paper/2b.Precipitation_globalmap.ipynb
[I 2022-06-15 11:28:40.318 ServerApp] Saving file at /jupyter_notebooks/paper/2b.Precipitation_globalmap.ipynb
[I 2022-06-15 11:30:45.357 ServerApp] Saving file at /jupyter_notebooks/paper/2b.Precipitation_globalmap.ipynb
